Workbook

Sheet Legends
A1: VARIABLE | B1: LEGEND
A2: TREND___QLT___(M3_S)___RISER_OUTLET | B2: Liquid at Outlet
A3: TREND___UL___(M_S)___RISER_OUTLET | B3: Liquid Velocity
A4: TREND___UG___(M_S)___RISER_OUTLET | B4: Gas Velocity

Sheet 10MMSCFD
A1: h | B1: h | C1: h | E1: (M3/S) | F1: (M/S) | G1: (M/S)
A2: TIME1 | B2: TIME2 | C2: TIME3 | E2: =Legends!B2 -> Liquid at Outlet | F2: =Legends!B3 -> Liquid Velocity | G2: =Legends!B4 -> Gas Velocity | I2: Report-2031_Oil_4500bopd_Liquid_4773blpd_10MMSCFD_GL_TD_Only_OP2.genkey
A3: =MIN($A$11:$A$299) -> 0 | B3: =MIN($B$11:$B$299) -> 0 | C3: =MIN($C$11:$C$299) -> 0 | D3: Min | E3: =MIN($E$11:$E$299) -> 0.0084849074 | F3: =MIN($F$11:$F$299) -> 4.6832271 | G3: =MIN($G$11:$G$299) -> 9.744174
A4: =MEDIAN($A$11:$A$299) -> 36.000168 | B4: =MEDIAN($B$11:$B$299) -> 36.000168 | C4: =MEDIAN($C$11:$C$299) -> 36.000168 | D4: P50 | E4: =MEDIAN($E$11:$E$299) -> 0.0098378537 | F4: =MEDIAN($F$11:$F$299) -> 4.8133931 | G4: =MEDIAN($G$11:$G$299) -> 9.7442694
A5: =MAX($A$11:$A$299) -> 72.000275 | B5: =MAX($B$11:$B$299) -> 72.000275 | C5: =MAX($C$11:$C$299) -> 72.000275 | D5: Max | E5: =MAX($E$11:$E$299) -> 0.01899014 | F5: =MAX($F$11:$F$299) -> 7.1813378 | G5: =MAX($G$11:$G$299) -> 13.0239
A6: =$A5-$A3 -> 72.000275 | B6: =$B5-$B3 -> 72.000275 | C6: =$C5-$C3 -> 72.000275 | D6: Delta | E6: =$E5-$E3 -> 0.010505233 | F6: =$F5-$F3 -> 2.4981108 | G6: =$G5-$G3 -> 3.279726
A7: h | B7: h | C7: h | E7: (M3/S) | F7: (M/S) | G7: (M/S)
A8: 0 | B8: 0 | C8: 0 | D8: Offset | E8: 0 | F8: 0 | G8: 0
A9: 1 | B9: 1 | C9: 1 | D9: Scale | E9: 1 | F9: 1 | G9: 1
A10: TIME1 | B10: TIME2 | C10: TIME3 | E10: =Legends!B2 -> Liquid at Outlet | F10: =Legends!B3 -> Liquid Velocity | G10: =Legends!B4 -> Gas Velocity
A11: =A$9 * (0 -A$8) -> 0 | B11: =B$9 * (0 -B$8) -> 0 | C11: =C$9 * (0 -C$8) -> 0 | E11: =E$9 * (0.0189901404082775 -E$8) -> 0.01899014 | F11: =F$9 * (6.97602319717407 -F$8) -> 6.9760232 | G11: =G$9 * (9.87746524810791 -G$8) -> 9.8774652 | I11: =E11*3600 -> 68.364505 | J11: =F11*3600 -> 25113.684 | K11: =G11*3600 -> 35558.875
A12: =A$9 * (0.250451177358627 -A$8) -> 0.25045118 | B12: =B$9 * (0.250451177358627 -B$8) -> 0.25045118 | C12: =C$9 * (0.250451177358627 -C$8) -> 0.25045118 | E12: =E$9 * (0.0123529797419905 -E$8) -> 0.01235298 | F12: =F$9 * (7.18133783340454 -F$8) -> 7.1813378 | G12: =G$9 * (13.0239000320434 -G$8) -> 13.0239 | I12: =E12*3600 -> 44.470727 | J12: =F12*3600 -> 25852.816 | K12: =G12*3600 -> 46886.04
A13: =A$9 * (0.500372529029846 -A$8) -> 0.50037253 | B13: =B$9 * (0.500372529029846 -B$8) -> 0.50037253 | C13: =C$9 * (0.500372529029846 -C$8) -> 0.50037253 | E13: =E$9 * (0.00876795127987861 -E$8) -> 0.0087679513 | F13: =F$9 * (5.20924806594848 -F$8) -> 5.2092481 | G13: =G$9 * (11.3920698165893 -G$8) -> 11.39207 | I13: =E13*3600 -> 31.564625 | J13: =F13*3600 -> 18753.293 | K13: =G13*3600 -> 41011.451
A14: =A$9 * (0.750264465808868 -A$8) -> 0.75026447 | B14: =B$9 * (0.750264465808868 -B$8) -> 0.75026447 | C14: =C$9 * (0.750264465808868 -C$8) -> 0.75026447 | E14: =E$9 * (0.0113582797348499 -E$8) -> 0.01135828 | F14: =F$9 * (5.98395109176635 -F$8) -> 5.9839511 | G14: =G$9 * (11.1697397232055 -G$8) -> 11.16974 | I14: =E14*3600 -> 40.889807 | J14: =F14*3600 -> 21542.224 | K14: =G14*3600 -> 40211.063
A15: =A$9 * (1.00022971630096 -A$8) -> 1.0002297 | B15: =B$9 * (1.00022971630096 -B$8) -> 1.0002297 | C15: =C$9 * (1.00022971630096 -C$8) -> 1.0002297 | E15: =E$9 * (0.00939853675663471 -E$8) -> 0.0093985368 | F15: =F$9 * (5.2784719467163 -F$8) -> 5.2784719 | G15: =G$9 * (11.0152196884155 -G$8) -> 11.01522 | I15: =E15*3600 -> 33.834732 | J15: =F15*3600 -> 19002.499 | K15: =G15*3600 -> 39654.791
A16: =A$9 * (1.25001311302185 -A$8) -> 1.2500131 | B16: =B$9 * (1.25001311302185 -B$8) -> 1.2500131 | C16: =C$9 * (1.25001311302185 -C$8) -> 1.2500131 | E16: =E$9 * (0.0106283100321888 -E$8) -> 0.01062831 | F16: =F$9 * (5.14639520645141 -F$8) -> 5.1463952 | G16: =G$9 * (9.85121631622314 -G$8) -> 9.8512163 | I16: =E16*3600 -> 38.261916 | J16: =F16*3600 -> 18527.023 | K16: =G16*3600 -> 35464.379
A17: =A$9 * (1.50012111663818 -A$8) -> 1.5001211 | B17: =B$9 * (1.50012111663818 -B$8) -> 1.5001211 | C17: =C$9 * (1.50012111663818 -C$8) -> 1.5001211 | E17: =E$9 * (0.00895081739872694 -E$8) -> 0.0089508174 | F17: =F$9 * (5.00681018829345 -F$8) -> 5.0068102 | G17: =G$9 * (10.7459001541137 -G$8) -> 10.7459 | I17: =E17*3600 -> 32.222943 | J17: =F17*3600 -> 18024.517 | K17: =G17*3600 -> 38685.241
A18: =A$9 * (1.75032866001129 -A$8) -> 1.7503287 | B18: =B$9 * (1.75032866001129 -B$8) -> 1.7503287 | C18: =C$9 * (1.75032866001129 -C$8) -> 1.7503287 | E18: =E$9 * (0.00883944518864154 -E$8) -> 0.0088394452 | F18: =F$9 * (4.73760318756103 -F$8) -> 4.7376032 | G18: =G$9 * (10.1899499893188 -G$8) -> 10.18995 | I18: =E18*3600 -> 31.822003 | J18: =F18*3600 -> 17055.371 | K18: =G18*3600 -> 36683.82
A19: =A$9 * (2.000328540802 -A$8) -> 2.0003285 | B19: =B$9 * (2.000328540802 -B$8) -> 2.0003285 | C19: =C$9 * (2.000328540802 -C$8) -> 2.0003285 | E19: =E$9 * (0.0100758504122495 -E$8) -> 0.01007585 | F19: =F$9 * (5.1983528137207 -F$8) -> 5.1983528 | G19: =G$9 * (10.3284101486206 -G$8) -> 10.32841 | I19: =E19*3600 -> 36.273061 | J19: =F19*3600 -> 18714.07 | K19: =G19*3600 -> 37182.277
A20: =A$9 * (2.2502760887146 -A$8) -> 2.2502761 | B20: =B$9 * (2.2502760887146 -B$8) -> 2.2502761 | C20: =C$9 * (2.2502760887146 -C$8) -> 2.2502761 | E20: =E$9 * (0.00848490744829177 -E$8) -> 0.0084849074 | F20: =F$9 * (4.68322706222534 -F$8) -> 4.6832271 | G20: =G$9 * (10.3659601211547 -G$8) -> 10.36596 | I20: =E20*3600 -> 30.545667 | J20: =F20*3600 -> 16859.617 | K20: =G20*3600 -> 37317.456
A21: =A$9 * (2.50030422210693 -A$8) -> 2.5003042 | B21: =B$9 * (2.50030422210693 -B$8) -> 2.5003042 | C21: =C$9 * (2.50030422210693 -C$8) -> 2.5003042 | E21: =E$9 * (0.0101656904444098 -E$8) -> 0.01016569 | F21: =F$9 * (5.07038497924804 -F$8) -> 5.070385 | G21: =G$9 * (9.99437522888183 -G$8) -> 9.9943752 | I21: =E21*3600 -> 36.596486 | J21: =F21*3600 -> 18253.386 | K21: =G21*3600 -> 35979.751
A22: =A$9 * (2.7503318786621 -A$8) -> 2.7503319 | B22: =B$9 * (2.7503318786621 -B$8) -> 2.7503319 | C22: =C$9 * (2.7503318786621 -C$8) -> 2.7503319 | E22: =E$9 * (0.00920781027525663 -E$8) -> 0.0092078103 | F22: =F$9 * (4.88818502426147 -F$8) -> 4.888185 | G22: =G$9 * (10.2712097167968 -G$8) -> 10.27121 | I22: =E22*3600 -> 33.148117 | J22: =F22*3600 -> 17597.466 | K22: =G22*3600 -> 36976.355
A23: =A$9 * (3.00036120414733 -A$8) -> 3.0003612 | B23: =B$9 * (3.00036120414733 -B$8) -> 3.0003612 | C23: =C$9 * (3.00036120414733 -C$8) -> 3.0003612 | E23: =E$9 * (0.00929384026676416 -E$8) -> 0.0092938403 | F23: =F$9 * (4.81830883026123 -F$8) -> 4.8183088 | G23: =G$9 * (10.0455598831176 -G$8) -> 10.04556 | I23: =E23*3600 -> 33.457825 | J23: =F23*3600 -> 17345.912 | K23: =G23*3600 -> 36164.016
A24: =A$9 * (3.25038886070251 -A$8) -> 3.2503889 | B24: =B$9 * (3.25038886070251 -B$8) -> 3.2503889 | C24: =C$9 * (3.25038886070251 -C$8) -> 3.2503889 | E24: =E$9 * (0.00979326572269201 -E$8) -> 0.0097932657 | F24: =F$9 * (5.0300588607788 -F$8) -> 5.0300589 | G24: =G$9 * (10.1696901321411 -G$8) -> 10.16969 | I24: =E24*3600 -> 35.255757 | J24: =F24*3600 -> 18108.212 | K24: =G24*3600 -> 36610.884
A25: =A$9 * (3.50002789497375 -A$8) -> 3.5000279 | B25: =B$9 * (3.50002789497375 -B$8) -> 3.5000279 | C25: =C$9 * (3.50002789497375 -C$8) -> 3.5000279 | E25: =E$9 * (0.00959334895014762 -E$8) -> 0.009593349 | F25: =F$9 * (4.94578790664672 -F$8) -> 4.9457879 | G25: =G$9 * (10.1256504058837 -G$8) -> 10.12565 | I25: =E25*3600 -> 34.536056 | J25: =F25*3600 -> 17804.836 | K25: =G25*3600 -> 36452.341
A26: =A$9 * (3.75005555152893 -A$8) -> 3.7500556 | B26: =B$9 * (3.75005555152893 -B$8) -> 3.7500556 | C26: =C$9 * (3.75005555152893 -C$8) -> 3.7500556 | E26: =E$9 * (0.00992781855165958 -E$8) -> 0.0099278186 | F26: =F$9 * (4.99578619003295 -F$8) -> 4.9957862 | G26: =G$9 * (10.0093803405761 -G$8) -> 10.00938 | I26: =E26*3600 -> 35.740147 | J26: =F26*3600 -> 17984.83 | K26: =G26*3600 -> 36033.769
A27: =A$9 * (4.00008344650268 -A$8) -> 4.0000834 | B27: =B$9 * (4.00008344650268 -B$8) -> 4.0000834 | C27: =C$9 * (4.00008344650268 -C$8) -> 4.0000834 | E27: =E$9 * (0.00974597781896591 -E$8) -> 0.0097459778 | F27: =F$9 * (4.98752689361572 -F$8) -> 4.9875269 | G27: =G$9 * (10.1346597671508 -G$8) -> 10.13466 | I27: =E27*3600 -> 35.08552 | J27: =F27*3600 -> 17955.097 | K27: =G27*3600 -> 36484.775
A28: =A$9 * (4.25011110305786 -A$8) -> 4.2501111 | B28: =B$9 * (4.25011110305786 -B$8) -> 4.2501111 | C28: =C$9 * (4.25011110305786 -C$8) -> 4.2501111 | E28: =E$9 * (0.00961970072239637 -E$8) -> 0.0096197007 | F28: =F$9 * (4.89806985855102 -F$8) -> 4.8980699 | G28: =G$9 * (10.0399599075317 -G$8) -> 10.03996 | I28: =E28*3600 -> 34.630923 | J28: =F28*3600 -> 17633.051 | K28: =G28*3600 -> 36143.856
A29: =A$9 * (4.50013875961303 -A$8) -> 4.5001388 | B29: =B$9 * (4.50013875961303 -B$8) -> 4.5001388 | C29: =C$9 * (4.50013875961303 -C$8) -> 4.5001388 | E29: =E$9 * (0.00981390196830034 -E$8) -> 0.009813902 | F29: =F$9 * (4.94573879241943 -F$8) -> 4.9457388 | G29: =G$9 * (10.0161895751953 -G$8) -> 10.01619 | I29: =E29*3600 -> 35.330047 | J29: =F29*3600 -> 17804.66 | K29: =G29*3600 -> 36058.282
A30: =A$9 * (4.75016689300537 -A$8) -> 4.7501669 | B30: =B$9 * (4.75016689300537 -B$8) -> 4.7501669 | C30: =C$9 * (4.75016689300537 -C$8) -> 4.7501669 | E30: =E$9 * (0.00963316019624471 -E$8) -> 0.0096331602 | F30: =F$9 * (4.90886497497558 -F$8) -> 4.908865 | G30: =G$9 * (10.062720298767 -G$8) -> 10.06272 | I30: =E30*3600 -> 34.679377 | J30: =F30*3600 -> 17671.914 | K30: =G30*3600 -> 36225.793
A31: =A$9 * (5.00019454956054 -A$8) -> 5.0001945 | B31: =B$9 * (5.00019454956054 -B$8) -> 5.0001945 | C31: =C$9 * (5.00019454956054 -C$8) -> 5.0001945 | E31: =E$9 * (0.0097122099250555 -E$8) -> 0.0097122099 | F31: =F$9 * (4.89602088928222 -F$8) -> 4.8960209 | G31: =G$9 * (9.98069858551025 -G$8) -> 9.9806986 | I31: =E31*3600 -> 34.963956 | J31: =F31*3600 -> 17625.675 | K31: =G31*3600 -> 35930.515
A32: =A$9 * (5.25022220611572 -A$8) -> 5.2502222 | B32: =B$9 * (5.25022220611572 -B$8) -> 5.2502222 | C32: =C$9 * (5.25022220611572 -C$8) -> 5.2502222 | E32: =E$9 * (0.00976879429072141 -E$8) -> 0.0097687943 | F32: =F$9 * (4.92498683929443 -F$8) -> 4.9249868 | G32: =G$9 * (10.0071496963501 -G$8) -> 10.00715 | I32: =E32*3600 -> 35.167659 | J32: =F32*3600 -> 17729.953 | K32: =G32*3600 -> 36025.739
A33: =A$9 * (5.50024986267089 -A$8) -> 5.5002499 | B33: =B$9 * (5.50024986267089 -B$8) -> 5.5002499 | C33: =C$9 * (5.50024986267089 -C$8) -> 5.5002499 | E33: =E$9 * (0.00966216530650854 -E$8) -> 0.0096621653 | F33: =F$9 * (4.88580703735351 -F$8) -> 4.885807 | G33: =G$9 * (9.99595642089843 -G$8) -> 9.9959564 | I33: =E33*3600 -> 34.783795 | J33: =F33*3600 -> 17588.905 | K33: =G33*3600 -> 35985.443
A34: =A$9 * (5.75027799606323 -A$8) -> 5.750278 | B34: =B$9 * (5.75027799606323 -B$8) -> 5.750278 | C34: =C$9 * (5.75027799606323 -C$8) -> 5.750278 | E34: =E$9 * (0.00977160595357418 -E$8) -> 0.009771606 | F34: =F$9 * (4.89839506149292 -F$8) -> 4.8983951 | G34: =G$9 * (9.94957542419433 -G$8) -> 9.9495754 | I34: =E34*3600 -> 35.177781 | J34: =F34*3600 -> 17634.222 | K34: =G34*3600 -> 35818.472
A35: =A$9 * (6.0003056526184 -A$8) -> 6.0003057 | B35: =B$9 * (6.0003056526184 -B$8) -> 6.0003057 | C35: =C$9 * (6.0003056526184 -C$8) -> 6.0003057 | E35: =E$9 * (0.00973766762763261 -E$8) -> 0.0097376676 | F35: =F$9 * (4.89893198013305 -F$8) -> 4.898932 | G35: =G$9 * (9.97559642791748 -G$8) -> 9.9755964 | I35: =E35*3600 -> 35.055603 | J35: =F35*3600 -> 17636.155 | K35: =G35*3600 -> 35912.147
A36: =A$9 * (6.25033330917358 -A$8) -> 6.2503333 | B36: =B$9 * (6.25033330917358 -B$8) -> 6.2503333 | C36: =C$9 * (6.25033330917358 -C$8) -> 6.2503333 | E36: =E$9 * (0.00971522741019725 -E$8) -> 0.0097152274 | F36: =F$9 * (4.87566423416137 -F$8) -> 4.8756642 | G36: =G$9 * (9.94116878509521 -G$8) -> 9.9411688 | I36: =E36*3600 -> 34.974819 | J36: =F36*3600 -> 17552.391 | K36: =G36*3600 -> 35788.208
A37: =A$9 * (6.50036096572876 -A$8) -> 6.500361 | B37: =B$9 * (6.50036096572876 -B$8) -> 6.500361 | C37: =C$9 * (6.50036096572876 -C$8) -> 6.500361 | E37: =E$9 * (0.00978646706789732 -E$8) -> 0.0097864671 | F37: =F$9 * (4.89117288589477 -F$8) -> 4.8911729 | G37: =G$9 * (9.92794132232666 -G$8) -> 9.9279413 | I37: =E37*3600 -> 35.231281 | J37: =F37*3600 -> 17608.222 | K37: =G37*3600 -> 35740.589
A38: =A$9 * (6.75 -A$8) -> 6.75 | B38: =B$9 * (6.75 -B$8) -> 6.75 | C38: =C$9 * (6.75 -C$8) -> 6.75 | E38: =E$9 * (0.0097345532849431 -E$8) -> 0.0097345533 | F38: =F$9 * (4.87769317626953 -F$8) -> 4.8776932 | G38: =G$9 * (9.93509006500244 -G$8) -> 9.9350901 | I38: =E38*3600 -> 35.044392 | J38: =F38*3600 -> 17559.695 | K38: =G38*3600 -> 35766.324
A39: =A$9 * (7.00002765655517 -A$8) -> 7.0000277 | B39: =B$9 * (7.00002765655517 -B$8) -> 7.0000277 | C39: =C$9 * (7.00002765655517 -C$8) -> 7.0000277 | E39: =E$9 * (0.00976091064512729 -E$8) -> 0.0097609106 | F39: =F$9 * (4.87051105499267 -F$8) -> 4.8705111 | G39: =G$9 * (9.90246295928955 -G$8) -> 9.902463 | I39: =E39*3600 -> 35.139278 | J39: =F39*3600 -> 17533.84 | K39: =G39*3600 -> 35648.867
A40: =A$9 * (7.25005578994751 -A$8) -> 7.2500558 | B40: =B$9 * (7.25005578994751 -B$8) -> 7.2500558 | C40: =C$9 * (7.25005578994751 -C$8) -> 7.2500558 | E40: =E$9 * (0.00978302303701639 -E$8) -> 0.009783023 | F40: =F$9 * (4.87788295745849 -F$8) -> 4.877883 | G40: =G$9 * (9.90485095977783 -G$8) -> 9.904851 | I40: =E40*3600 -> 35.218883 | J40: =F40*3600 -> 17560.379 | K40: =G40*3600 -> 35657.463
...

Sheet SIM2
A1: h | B1: h | C1: h | E1: (M3/S) | F1: (M/S) | G1: (M/S)
A2: TIME1 | B2: TIME2 | C2: TIME3 | E2: =Legends!B2 -> Liquid at Outlet | F2: =Legends!B3 -> Liquid Velocity | G2: =Legends!B4 -> Gas Velocity | I2: Report-2031_Oil_4500bopd_Liquid_4773blpd_5MMSCFD_GL_TD_Only_OP2.genkey
A3: =MIN($A$11:$A$299) -> 0 | B3: =MIN($B$11:$B$299) -> 0 | C3: =MIN($C$11:$C$299) -> 0 | D3: Min | E3: =MIN($E$11:$E$299) -> -0.0048303208 | F3: =MIN($F$11:$F$299) -> -4.692595 | G3: =MIN($G$11:$G$299) -> -2.975482
A4: =MEDIAN($A$11:$A$299) -> 36.000084 | B4: =MEDIAN($B$11:$B$299) -> 36.000084 | C4: =MEDIAN($C$11:$C$299) -> 36.000084 | D4: P50 | E4: =MEDIAN($E$11:$E$299) -> 0.0044169072 | F4: =MEDIAN($F$11:$F$299) -> 0.7049734 | G4: =MEDIAN($G$11:$G$299) -> 6.4099312
A5: =MAX($A$11:$A$299) -> 72.000336 | B5: =MAX($B$11:$B$299) -> 72.000336 | C5: =MAX($C$11:$C$299) -> 72.000336 | D5: Max | E5: =MAX($E$11:$E$299) -> 0.2286936 | F5: =MAX($F$11:$F$299) -> 22.42683 | G5: =MAX($G$11:$G$299) -> 41.738869
A6: =$A5-$A3 -> 72.000336 | B6: =$B5-$B3 -> 72.000336 | C6: =$C5-$C3 -> 72.000336 | D6: Delta | E6: =$E5-$E3 -> 0.23352393 | F6: =$F5-$F3 -> 27.119425 | G6: =$G5-$G3 -> 44.714351
A7: h | B7: h | C7: h | E7: (M3/S) | F7: (M/S) | G7: (M/S)
A8: 0 | B8: 0 | C8: 0 | D8: Offset | E8: 0 | F8: 0 | G8: 0
A9: 1 | B9: 1 | C9: 1 | D9: Scale | E9: 1 | F9: 1 | G9: 1
A10: TIME1 | B10: TIME2 | C10: TIME3 | E10: =Legends!B2 -> Liquid at Outlet | F10: =Legends!B3 -> Liquid Velocity | G10: =Legends!B4 -> Gas Velocity
A11: =A$9 * (0 -A$8) -> 0 | B11: =B$9 * (0 -B$8) -> 0 | C11: =C$9 * (0 -C$8) -> 0 | E11: =E$9 * (0.0189901404082775 -E$8) -> 0.01899014 | F11: =F$9 * (6.97602319717407 -F$8) -> 6.9760232 | G11: =G$9 * (9.87746524810791 -G$8) -> 9.8774652
A12: =A$9 * (0.250237703323364 -A$8) -> 0.2502377 | B12: =B$9 * (0.250237703323364 -B$8) -> 0.2502377 | C12: =C$9 * (0.250237703323364 -C$8) -> 0.2502377 | E12: =E$9 * (0.0132571095600724 -E$8) -> 0.01325711 | F12: =F$9 * (6.13306379318237 -F$8) -> 6.1330638 | G12: =G$9 * (10.4192600250244 -G$8) -> 10.41926
A13: =A$9 * (0.500134468078613 -A$8) -> 0.50013447 | B13: =B$9 * (0.500134468078613 -B$8) -> 0.50013447 | C13: =C$9 * (0.500134468078613 -C$8) -> 0.50013447 | E13: =E$9 * (0.00954968109726905 -E$8) -> 0.0095496811 | F13: =F$9 * (4.36546611785888 -F$8) -> 4.3654661 | G13: =G$9 * (8.80455207824707 -G$8) -> 8.8045521
A14: =A$9 * (0.750216662883758 -A$8) -> 0.75021666 | B14: =B$9 * (0.750216662883758 -B$8) -> 0.75021666 | C14: =C$9 * (0.750216662883758 -C$8) -> 0.75021666 | E14: =E$9 * (0.0131569001823663 -E$8) -> 0.0131569 | F14: =F$9 * (5.03891992568969 -F$8) -> 5.0389199 | G14: =G$9 * (8.42787075042724 -G$8) -> 8.4278708
A15: =A$9 * (1.00029695034027 -A$8) -> 1.000297 | B15: =B$9 * (1.00029695034027 -B$8) -> 1.000297 | C15: =C$9 * (1.00029695034027 -C$8) -> 1.000297 | E15: =E$9 * (0.00936556793749332 -E$8) -> 0.0093655679 | F15: =F$9 * (4.04002714157104 -F$8) -> 4.0400271 | G15: =G$9 * (8.20789813995361 -G$8) -> 8.2078981
A16: =A$9 * (1.25007057189941 -A$8) -> 1.2500706 | B16: =B$9 * (1.25007057189941 -B$8) -> 1.2500706 | C16: =C$9 * (1.25007057189941 -C$8) -> 1.2500706 | E16: =E$9 * (0.00831956975162029 -E$8) -> 0.0083195698 | F16: =F$9 * (3.14157104492187 -F$8) -> 3.141571 | G16: =G$9 * (6.77331686019897 -G$8) -> 6.7733169
A17: =A$9 * (1.50002884864807 -A$8) -> 1.5000288 | B17: =B$9 * (1.50002884864807 -B$8) -> 1.5000288 | C17: =C$9 * (1.50002884864807 -C$8) -> 1.5000288 | E17: =E$9 * (0.00925261620432138 -E$8) -> 0.0092526162 | F17: =F$9 * (4.24377298355102 -F$8) -> 4.243773 | G17: =G$9 * (8.72288799285888 -G$8) -> 8.722888
A18: =A$9 * (1.75000774860382 -A$8) -> 1.7500077 | B18: =B$9 * (1.75000774860382 -B$8) -> 1.7500077 | C18: =C$9 * (1.75000774860382 -C$8) -> 1.7500077 | E18: =E$9 * (0.00869770627468824 -E$8) -> 0.0086977063 | F18: =F$9 * (3.68141603469848 -F$8) -> 3.681416 | G18: =G$9 * (7.79507112503051 -G$8) -> 7.7950711
A19: =A$9 * (2.00033164024353 -A$8) -> 2.0003316 | B19: =B$9 * (2.00033164024353 -B$8) -> 2.0003316 | C19: =C$9 * (2.00033164024353 -C$8) -> 2.0003316 | E19: =E$9 * (0.0115617401897907 -E$8) -> 0.01156174 | F19: =F$9 * (3.94794201850891 -F$8) -> 3.947942 | G19: =G$9 * (6.99443387985229 -G$8) -> 6.9944339
A20: =A$9 * (2.25025415420532 -A$8) -> 2.2502542 | B20: =B$9 * (2.25025415420532 -B$8) -> 2.2502542 | C20: =C$9 * (2.25025415420532 -C$8) -> 2.2502542 | E20: =E$9 * (0.00820710603147745 -E$8) -> 0.008207106 | F20: =F$9 * (3.78051590919494 -F$8) -> 3.7805159 | G20: =G$9 * (8.35314655303955 -G$8) -> 8.3531466
A21: =A$9 * (2.50017666816711 -A$8) -> 2.5001767 | B21: =B$9 * (2.50017666816711 -B$8) -> 2.5001767 | C21: =C$9 * (2.50017666816711 -C$8) -> 2.5001767 | E21: =E$9 * (0.00849279016256332 -E$8) -> 0.0084927902 | F21: =F$9 * (3.24290704727172 -F$8) -> 3.242907 | G21: =G$9 * (6.91018676757812 -G$8) -> 6.9101868
A22: =A$9 * (2.7500991821289 -A$8) -> 2.7500992 | B22: =B$9 * (2.7500991821289 -B$8) -> 2.7500992 | C22: =C$9 * (2.7500991821289 -C$8) -> 2.7500992 | E22: =E$9 * (0.0104625895619392 -E$8) -> 0.01046259 | F22: =F$9 * (4.54508781433105 -F$8) -> 4.5450878 | G22: =G$9 * (8.67212104797363 -G$8) -> 8.672121
A23: =A$9 * (3.00002217292785 -A$8) -> 3.0000222 | B23: =B$9 * (3.00002217292785 -B$8) -> 3.0000222 | C23: =C$9 * (3.00002217292785 -C$8) -> 3.0000222 | E23: =E$9 * (0.00839243736118078 -E$8) -> 0.0083924374 | F23: =F$9 * (3.62110209465026 -F$8) -> 3.6211021 | G23: =G$9 * (7.86094522476196 -G$8) -> 7.8609452
A24: =A$9 * (3.2503445148468 -A$8) -> 3.2503445 | B24: =B$9 * (3.2503445148468 -B$8) -> 3.2503445 | C24: =C$9 * (3.2503445148468 -C$8) -> 3.2503445 | E24: =E$9 * (0.011512080207467 -E$8) -> 0.01151208 | F24: =F$9 * (3.50437188148498 -F$8) -> 3.5043719 | G24: =G$9 * (6.19303321838378 -G$8) -> 6.1930332
A25: =A$9 * (3.50026941299438 -A$8) -> 3.5002694 | B25: =B$9 * (3.50026941299438 -B$8) -> 3.5002694 | C25: =C$9 * (3.50026941299438 -C$8) -> 3.5002694 | E25: =E$9 * (0.0084743658080697 -E$8) -> 0.0084743658 | F25: =F$9 * (3.88349795341491 -F$8) -> 3.883498 | G25: =G$9 * (8.45409107208252 -G$8) -> 8.4540911
A26: =A$9 * (3.75019168853759 -A$8) -> 3.7501917 | B26: =B$9 * (3.75019168853759 -B$8) -> 3.7501917 | C26: =C$9 * (3.75019168853759 -C$8) -> 3.7501917 | E26: =E$9 * (0.00751087395474314 -E$8) -> 0.007510874 | F26: =F$9 * (2.90160489082336 -F$8) -> 2.9016049 | G26: =G$9 * (6.72075605392456 -G$8) -> 6.7207561
A27: =A$9 * (4.00011396408081 -A$8) -> 4.000114 | B27: =B$9 * (4.00011396408081 -B$8) -> 4.000114 | C27: =C$9 * (4.00011396408081 -C$8) -> 4.000114 | E27: =E$9 * (0.0117009095847606 -E$8) -> 0.01170091 | F27: =F$9 * (5.22205686569213 -F$8) -> 5.2220569 | G27: =G$9 * (9.44923400878906 -G$8) -> 9.449234
A28: =A$9 * (4.25003623962402 -A$8) -> 4.2500362 | B28: =B$9 * (4.25003623962402 -B$8) -> 4.2500362 | C28: =C$9 * (4.25003623962402 -C$8) -> 4.2500362 | E28: =E$9 * (0.00826132483780384 -E$8) -> 0.0082613248 | F28: =F$9 * (3.66607999801635 -F$8) -> 3.66608 | G28: =G$9 * (8.09494113922119 -G$8) -> 8.0949411
A29: =A$9 * (4.50035810470581 -A$8) -> 4.5003581 | B29: =B$9 * (4.50035810470581 -B$8) -> 4.5003581 | C29: =C$9 * (4.50035810470581 -C$8) -> 4.5003581 | E29: =E$9 * (0.00948974024504423 -E$8) -> 0.0094897402 | F29: =F$9 * (2.19545102119445 -F$8) -> 2.195451 | G29: =G$9 * (4.28318309783935 -G$8) -> 4.2831831
A30: =A$9 * (4.7503056526184 -A$8) -> 4.7503057 | B30: =B$9 * (4.7503056526184 -B$8) -> 4.7503057 | C30: =C$9 * (4.7503056526184 -C$8) -> 4.7503057 | E30: =E$9 * (0.00719790207222104 -E$8) -> 0.0071979021 | F30: =F$9 * (3.68671798706054 -F$8) -> 3.686718 | G30: =G$9 * (9.03808116912841 -G$8) -> 9.0380812
A31: =A$9 * (5.00006103515625 -A$8) -> 5.000061 | B31: =B$9 * (5.00006103515625 -B$8) -> 5.000061 | C31: =C$9 * (5.00006103515625 -C$8) -> 5.000061 | E31: =E$9 * (0.00537472777068615 -E$8) -> 0.0053747278 | F31: =F$9 * (1.76637995243072 -F$8) -> 1.76638 | G31: =G$9 * (5.10724401473999 -G$8) -> 5.107244
A32: =A$9 * (5.2504858970642 -A$8) -> 5.2504859 | B32: =B$9 * (5.2504858970642 -B$8) -> 5.2504859 | C32: =C$9 * (5.2504858970642 -C$8) -> 5.2504859 | E32: =E$9 * (-0.00242825597524642 -E$8) -> -0.002428256 | F32: =F$9 * (-2.11496305465698 -F$8) -> -2.1149631 | G32: =G$9 * (0.512343406677246 -G$8) -> 0.51234341
A33: =A$9 * (5.50045824050903 -A$8) -> 5.5004582 | B33: =B$9 * (5.50045824050903 -B$8) -> 5.5004582 | C33: =C$9 * (5.50045824050903 -C$8) -> 5.5004582 | E33: =E$9 * (0.00206511793658137 -E$8) -> 0.0020651179 | F33: =F$9 * (-0.362122386693954 -F$8) -> -0.36212239 | G33: =G$9 * (2.05952191352844 -G$8) -> 2.0595219
A34: =A$9 * (5.75071668624877 -A$8) -> 5.7507167 | B34: =B$9 * (5.75071668624877 -B$8) -> 5.7507167 | C34: =C$9 * (5.75071668624877 -C$8) -> 5.7507167 | E34: =E$9 * (0.0022369660437107 -E$8) -> 0.002236966 | F34: =F$9 * (-2.56807303428649 -F$8) -> -2.568073 | G34: =G$9 * (1.2446060180664 -G$8) -> 1.244606
A35: =A$9 * (6.00056409835815 -A$8) -> 6.0005641 | B35: =B$9 * (6.00056409835815 -B$8) -> 6.0005641 | C35: =C$9 * (6.00056409835815 -C$8) -> 6.0005641 | E35: =E$9 * (0.00327861402183771 -E$8) -> 0.003278614 | F35: =F$9 * (-0.0803271904587745 -F$8) -> -0.08032719 | G35: =G$9 * (7.30388879776001 -G$8) -> 7.3038888
A36: =A$9 * (6.25060272216796 -A$8) -> 6.2506027 | B36: =B$9 * (6.25060272216796 -B$8) -> 6.2506027 | C36: =C$9 * (6.25060272216796 -C$8) -> 6.2506027 | E36: =E$9 * (0.0254045501351356 -E$8) -> 0.02540455 | F36: =F$9 * (2.69052910804748 -F$8) -> 2.6905291 | G36: =G$9 * (3.07029700279235 -G$8) -> 3.070297
A37: =A$9 * (6.50015258789062 -A$8) -> 6.5001526 | B37: =B$9 * (6.50015258789062 -B$8) -> 6.5001526 | C37: =C$9 * (6.50015258789062 -C$8) -> 6.5001526 | E37: =E$9 * (0.0104373395442962 -E$8) -> 0.01043734 | F37: =F$9 * (5.5378189086914 -F$8) -> 5.5378189 | G37: =G$9 * (10.9554300308227 -G$8) -> 10.95543
A38: =A$9 * (6.75020265579223 -A$8) -> 6.7502027 | B38: =B$9 * (6.75020265579223 -B$8) -> 6.7502027 | C38: =C$9 * (6.75020265579223 -C$8) -> 6.7502027 | E38: =E$9 * (0.0191051494330167 -E$8) -> 0.019105149 | F38: =F$9 * (7.10554504394531 -F$8) -> 7.105545 | G38: =G$9 * (10.1106395721435 -G$8) -> 10.11064
A39: =A$9 * (7.00038909912109 -A$8) -> 7.0003891 | B39: =B$9 * (7.00038909912109 -B$8) -> 7.0003891 | C39: =C$9 * (7.00038909912109 -C$8) -> 7.0003891 | E39: =E$9 * (0.00704096816480159 -E$8) -> 0.0070409682 | F39: =F$9 * (3.70105290412902 -F$8) -> 3.7010529 | G39: =G$9 * (9.2607946395874 -G$8) -> 9.2607946
A40: =A$9 * (7.25005578994751 -A$8) -> 7.2500558 | B40: =B$9 * (7.25005578994751 -B$8) -> 7.2500558 | C40: =C$9 * (7.25005578994751 -C$8) -> 7.2500558 | E40: =E$9 * (0.00424628378823399 -E$8) -> 0.0042462838 | F40: =F$9 * (1.36589300632476 -F$8) -> 1.365893 | G40: =G$9 * (4.74028778076171 -G$8) -> 4.7402878
...

Sheet SIM3
A1: h | B1: h | C1: h | E1: (M3/S) | F1: (M/S) | G1: (M/S)
A2: TIME1 | B2: TIME2 | C2: TIME3 | E2: =Legends!B2 -> Liquid at Outlet | F2: =Legends!B3 -> Liquid Velocity | G2: =Legends!B4 -> Gas Velocity | I2: Report-2031_Oil_4500bopd_Liquid_4773blpd_No_GL_TD_Only_OP2.genkey
A3: =MIN($A$11:$A$299) -> 0 | B3: =MIN($B$11:$B$299) -> 0 | C3: =MIN($C$11:$C$299) -> 0 | D3: Min | E3: =MIN($E$11:$E$299) -> 0 | F3: =MIN($F$11:$F$299) -> 0 | G3: =MIN($G$11:$G$299) -> 0
A4: =MEDIAN($A$11:$A$299) -> 36.0005 | B4: =MEDIAN($B$11:$B$299) -> 36.0005 | C4: =MEDIAN($C$11:$C$299) -> 36.0005 | D4: P50 | E4: =MEDIAN($E$11:$E$299) -> 4.6656648e+08 | F4: =MEDIAN($F$11:$F$299) -> 4.6656648e+08 | G4: =MEDIAN($G$11:$G$299) -> 4.6656648e+08
A5: =MAX($A$11:$A$299) -> 72.000359 | B5: =MAX($B$11:$B$299) -> 72.000359 | C5: =MAX($C$11:$C$299) -> 72.000359 | D5: Max | E5: =MAX($E$11:$E$299) -> 9.3312465e+08 | F5: =MAX($F$11:$F$299) -> 9.3312465e+08 | G5: =MAX($G$11:$G$299) -> 9.3312465e+08
A6: =$A5-$A3 -> 72.000359 | B6: =$B5-$B3 -> 72.000359 | C6: =$C5-$C3 -> 72.000359 | D6: Delta | E6: =$E5-$E3 -> 9.3312465e+08 | F6: =$F5-$F3 -> 9.3312465e+08 | G6: =$G5-$G3 -> 9.3312465e+08
A7: h | B7: h | C7: h | E7: (M3/S) | F7: (M/S) | G7: (M/S)
A8: 0 | B8: 0 | C8: 0 | D8: Offset | E8: 0 | F8: 0 | G8: 0
A9: 1 | B9: 1 | C9: 1 | D9: Scale | E9: 1 | F9: 1 | G9: 1
A10: TIME1 | B10: TIME2 | C10: TIME3 | E10: =Legends!B2 -> Liquid at Outlet | F10: =Legends!B3 -> Liquid Velocity | G10: =Legends!B4 -> Gas Velocity
A11: =A$9 * (0 -A$8) -> 0 | B11: =B$9 * (0 -B$8) -> 0 | C11: =C$9 * (0 -C$8) -> 0 | E11: 0 | F11: 0 | G11: 0
A12: =A$9 * (0.25001123547554 -A$8) -> 0.25001124 | B12: =B$9 * (0.25001123547554 -B$8) -> 0.25001124 | C12: =C$9 * (0.25001123547554 -C$8) -> 0.25001124 | E12: 3240145.6 | F12: 3240145.6 | G12: 3240145.6
A13: =A$9 * (0.500121116638183 -A$8) -> 0.50012112 | B13: =B$9 * (0.500121116638183 -B$8) -> 0.50012112 | C13: =C$9 * (0.500121116638183 -C$8) -> 0.50012112 | E13: 6481569.7 | F13: 6481569.7 | G13: 6481569.7
A14: =A$9 * (0.750061094760894 -A$8) -> 0.75006109 | B14: =B$9 * (0.750061094760894 -B$8) -> 0.75006109 | C14: =C$9 * (0.750061094760894 -C$8) -> 0.75006109 | E14: 9720791.8 | F14: 9720791.8 | G14: 9720791.8
A15: =A$9 * (1.00013864040374 -A$8) -> 1.0001386 | B15: =B$9 * (1.00013864040374 -B$8) -> 1.0001386 | C15: =C$9 * (1.00013864040374 -C$8) -> 1.0001386 | E15: 12961797 | F15: 12961797 | G15: 12961797
A16: =A$9 * (1.25046443939209 -A$8) -> 1.2504644 | B16: =B$9 * (1.25046443939209 -B$8) -> 1.2504644 | C16: =C$9 * (1.25046443939209 -C$8) -> 1.2504644 | E16: 16206019 | F16: 16206019 | G16: 16206019
A17: =A$9 * (1.50049471855163 -A$8) -> 1.5004947 | B17: =B$9 * (1.50049471855163 -B$8) -> 1.5004947 | C17: =C$9 * (1.50049471855163 -C$8) -> 1.5004947 | E17: 19446412 | F17: 19446412 | G17: 19446412
A18: =A$9 * (1.75000417232513 -A$8) -> 1.7500042 | B18: =B$9 * (1.75000417232513 -B$8) -> 1.7500042 | C18: =C$9 * (1.75000417232513 -C$8) -> 1.7500042 | E18: 22680054 | F18: 22680054 | G18: 22680054
A19: =A$9 * (2.00042057037353 -A$8) -> 2.0004206 | B19: =B$9 * (2.00042057037353 -B$8) -> 2.0004206 | C19: =C$9 * (2.00042057037353 -C$8) -> 2.0004206 | E19: 25925451 | F19: 25925451 | G19: 25925451
A20: =A$9 * (2.25022411346435 -A$8) -> 2.2502241 | B20: =B$9 * (2.25022411346435 -B$8) -> 2.2502241 | C20: =C$9 * (2.25022411346435 -C$8) -> 2.2502241 | E20: 29162905 | F20: 29162905 | G20: 29162905
A21: =A$9 * (2.50036907196044 -A$8) -> 2.5003691 | B21: =B$9 * (2.50036907196044 -B$8) -> 2.5003691 | C21: =C$9 * (2.50036907196044 -C$8) -> 2.5003691 | E21: 32404783 | F21: 32404783 | G21: 32404783
A22: =A$9 * (2.75002408027648 -A$8) -> 2.7500241 | B22: =B$9 * (2.75002408027648 -B$8) -> 2.7500241 | C22: =C$9 * (2.75002408027648 -C$8) -> 2.7500241 | E22: 35640312 | F22: 35640312 | G22: 35640312
A23: =A$9 * (3.00020837783813 -A$8) -> 3.0002084 | B23: =B$9 * (3.00020837783813 -B$8) -> 3.0002084 | C23: =C$9 * (3.00020837783813 -C$8) -> 3.0002084 | E23: 38882701 | F23: 38882701 | G23: 38882701
A24: =A$9 * (3.25011396408081 -A$8) -> 3.250114 | B24: =B$9 * (3.25011396408081 -B$8) -> 3.250114 | C24: =C$9 * (3.25011396408081 -C$8) -> 3.250114 | E24: 42121477 | F24: 42121477 | G24: 42121477
A25: =A$9 * (3.50045275688171 -A$8) -> 3.5004528 | B25: =B$9 * (3.50045275688171 -B$8) -> 3.5004528 | C25: =C$9 * (3.50045275688171 -C$8) -> 3.5004528 | E25: 45365868 | F25: 45365868 | G25: 45365868
A26: =A$9 * (3.75038337707519 -A$8) -> 3.7503834 | B26: =B$9 * (3.75038337707519 -B$8) -> 3.7503834 | C26: =C$9 * (3.75038337707519 -C$8) -> 3.7503834 | E26: 48604969 | F26: 48604969 | G26: 48604969
A27: =A$9 * (4.00034427642822 -A$8) -> 4.0003443 | B27: =B$9 * (4.00034427642822 -B$8) -> 4.0003443 | C27: =C$9 * (4.00034427642822 -C$8) -> 4.0003443 | E27: 51844462 | F27: 51844462 | G27: 51844462
A28: =A$9 * (4.25049448013305 -A$8) -> 4.2504945 | B28: =B$9 * (4.25049448013305 -B$8) -> 4.2504945 | C28: =C$9 * (4.25049448013305 -C$8) -> 4.2504945 | E28: 55086408 | F28: 55086408 | G28: 55086408
A29: =A$9 * (4.50046110153198 -A$8) -> 4.5004611 | B29: =B$9 * (4.50046110153198 -B$8) -> 4.5004611 | C29: =C$9 * (4.50046110153198 -C$8) -> 4.5004611 | E29: 58325976 | F29: 58325976 | G29: 58325976
A30: =A$9 * (4.75026369094848 -A$8) -> 4.7502637 | B30: =B$9 * (4.75026369094848 -B$8) -> 4.7502637 | C30: =C$9 * (4.75026369094848 -C$8) -> 4.7502637 | E30: 61563417 | F30: 61563417 | G30: 61563417
A31: =A$9 * (5.00053071975708 -A$8) -> 5.0005307 | B31: =B$9 * (5.00053071975708 -B$8) -> 5.0005307 | C31: =C$9 * (5.00053071975708 -C$8) -> 5.0005307 | E31: 64806878 | F31: 64806878 | G31: 64806878
A32: =A$9 * (5.25008344650268 -A$8) -> 5.2500834 | B32: =B$9 * (5.25008344650268 -B$8) -> 5.2500834 | C32: =C$9 * (5.25008344650268 -C$8) -> 5.2500834 | E32: 68041081 | F32: 68041081 | G32: 68041081
A33: =A$9 * (5.50014162063598 -A$8) -> 5.5001416 | B33: =B$9 * (5.50014162063598 -B$8) -> 5.5001416 | C33: =C$9 * (5.50014162063598 -C$8) -> 5.5001416 | E33: 71281835 | F33: 71281835 | G33: 71281835
A34: =A$9 * (5.75021648406982 -A$8) -> 5.7502165 | B34: =B$9 * (5.75021648406982 -B$8) -> 5.7502165 | C34: =C$9 * (5.75021648406982 -C$8) -> 5.7502165 | E34: 74522806 | F34: 74522806 | G34: 74522806
A35: =A$9 * (6.0005497932434 -A$8) -> 6.0005498 | B35: =B$9 * (6.0005497932434 -B$8) -> 6.0005498 | C35: =C$9 * (6.0005497932434 -C$8) -> 6.0005498 | E35: 77767125 | F35: 77767125 | G35: 77767125
A36: =A$9 * (6.25009155273437 -A$8) -> 6.2500916 | B36: =B$9 * (6.25009155273437 -B$8) -> 6.2500916 | C36: =C$9 * (6.25009155273437 -C$8) -> 6.2500916 | E36: 81001187 | F36: 81001187 | G36: 81001187
A37: =A$9 * (6.50034189224243 -A$8) -> 6.5003419 | B37: =B$9 * (6.50034189224243 -B$8) -> 6.5003419 | C37: =C$9 * (6.50034189224243 -C$8) -> 6.5003419 | E37: 84244431 | F37: 84244431 | G37: 84244431
A38: =A$9 * (6.75011682510376 -A$8) -> 6.7501168 | B38: =B$9 * (6.75011682510376 -B$8) -> 6.7501168 | C38: =C$9 * (6.75011682510376 -C$8) -> 6.7501168 | E38: 87481514 | F38: 87481514 | G38: 87481514
A39: =A$9 * (7.00020551681518 -A$8) -> 7.0002055 | B39: =B$9 * (7.00020551681518 -B$8) -> 7.0002055 | C39: =C$9 * (7.00020551681518 -C$8) -> 7.0002055 | E39: 90722663 | F39: 90722663 | G39: 90722663
A40: =A$9 * (7.25024461746215 -A$8) -> 7.2502446 | B40: =B$9 * (7.25024461746215 -B$8) -> 7.2502446 | C40: =C$9 * (7.25024461746215 -C$8) -> 7.2502446 | E40: 93963170 | F40: 93963170 | G40: 93963170
...

Sheet SIM4
A1: h | B1: h | C1: h | E1: (M3/S) | F1: (M/S) | G1: (M/S)
A2: TIME1 | B2: TIME2 | C2: TIME3 | E2: =Legends!B2 -> Liquid at Outlet | F2: =Legends!B3 -> Liquid Velocity | G2: =Legends!B4 -> Gas Velocity | I2: Report-2031_Oil_4500bopd_Liquid_4773blpd_No_GL_TD_Only_OP2_TCV_10pc.genkey
A3: =MIN($A$11:$A$299) -> 0 | B3: =MIN($B$11:$B$299) -> 0 | C3: =MIN($C$11:$C$299) -> 0 | D3: Min | E3: =MIN($E$11:$E$299) -> -13.830509 | F3: =MIN($F$11:$F$299) -> -17865.467 | G3: =MIN($G$11:$G$299) -> -6023.7072
A4: =MEDIAN($A$11:$A$299) -> 36.000278 | B4: =MEDIAN($B$11:$B$299) -> 36.000278 | C4: =MEDIAN($C$11:$C$299) -> 36.000278 | D4: P50 | E4: =MEDIAN($E$11:$E$299) -> 19.690254 | F4: =MEDIAN($F$11:$F$299) -> 3241.2747 | G4: =MEDIAN($G$11:$G$299) -> 11824.69
A5: =MAX($A$11:$A$299) -> 72.000031 | B5: =MAX($B$11:$B$299) -> 72.000031 | C5: =MAX($C$11:$C$299) -> 72.000031 | D5: Max | E5: =MAX($E$11:$E$299) -> 322.39069 | F5: =MAX($F$11:$F$299) -> 25113.684 | G5: =MAX($G$11:$G$299) -> 41010.119
A6: =$A5-$A3 -> 72.000031 | B6: =$B5-$B3 -> 72.000031 | C6: =$C5-$C3 -> 72.000031 | D6: Delta | E6: =$E5-$E3 -> 336.2212 | F6: =$F5-$F3 -> 42979.151 | G6: =$G5-$G3 -> 47033.826
A7: h | B7: h | C7: h | E7: (M3/S) | F7: (M/S) | G7: (M/S)
A8: 0 | B8: 0 | C8: 0 | D8: Offset | E8: 0 | F8: 0 | G8: 0
A9: 1 | B9: 1 | C9: 1 | D9: Scale | E9: 1 | F9: 1 | G9: 1
A10: TIME1 | B10: TIME2 | C10: TIME3 | E10: =Legends!B2 -> Liquid at Outlet | F10: =Legends!B3 -> Liquid Velocity | G10: =Legends!B4 -> Gas Velocity
A11: =A$9 * (0 -A$8) -> 0 | B11: =B$9 * (0 -B$8) -> 0 | C11: =C$9 * (0 -C$8) -> 0 | E11: 68.364505 | F11: 25113.684 | G11: 35558.875
A12: =A$9 * (0.25001123547554 -A$8) -> 0.25001124 | B12: =B$9 * (0.25001123547554 -B$8) -> 0.25001124 | C12: =C$9 * (0.25001123547554 -C$8) -> 0.25001124 | E12: 47.710621 | F12: 15272.294 | G12: 25083.59
A13: =A$9 * (0.500121116638183 -A$8) -> 0.50012112 | B13: =B$9 * (0.500121116638183 -B$8) -> 0.50012112 | C13: =C$9 * (0.500121116638183 -C$8) -> 0.50012112 | E13: 33.244559 | F13: 10486.602 | G13: 20986.913
A14: =A$9 * (0.750061094760894 -A$8) -> 0.75006109 | B14: =B$9 * (0.750061094760894 -B$8) -> 0.75006109 | C14: =C$9 * (0.750061094760894 -C$8) -> 0.75006109 | E14: 18.107982 | F14: 4070.844 | G14: 12102.455
A15: =A$9 * (1.00013864040374 -A$8) -> 1.0001386 | B15: =B$9 * (1.00013864040374 -B$8) -> 1.0001386 | C15: =C$9 * (1.00013864040374 -C$8) -> 1.0001386 | E15: -4.0957453 | F15: -5484.2939 | G15: 3326.2063
A16: =A$9 * (1.25000834465026 -A$8) -> 1.2500083 | B16: =B$9 * (1.25000834465026 -B$8) -> 1.2500083 | C16: =C$9 * (1.25000834465026 -C$8) -> 1.2500083 | E16: -5.9376346 | F16: -2056.8355 | G16: -2363.7542
A17: =A$9 * (1.50006806850433 -A$8) -> 1.5000681 | B17: =B$9 * (1.50006806850433 -B$8) -> 1.5000681 | C17: =C$9 * (1.50006806850433 -C$8) -> 1.5000681 | E17: -0.42975539 | F17: -5318.8093 | G17: 2889.8729
A18: =A$9 * (1.75054419040679 -A$8) -> 1.7505442 | B18: =B$9 * (1.75054419040679 -B$8) -> 1.7505442 | C18: =C$9 * (1.75054419040679 -C$8) -> 1.7505442 | E18: -0.99574233 | F18: -2507.4541 | G18: 2406.5726
A19: =A$9 * (2.00004506111145 -A$8) -> 2.0000451 | B19: =B$9 * (2.00004506111145 -B$8) -> 2.0000451 | C19: =C$9 * (2.00004506111145 -C$8) -> 2.0000451 | E19: -2.8001386 | F19: -1156.7541 | G19: -635.70022
A20: =A$9 * (2.25067996978759 -A$8) -> 2.25068 | B20: =B$9 * (2.25067996978759 -B$8) -> 2.25068 | C20: =C$9 * (2.25067996978759 -C$8) -> 2.25068 | E20: 24.263244 | F20: 755.82826 | G20: 2021.6103
A21: =A$9 * (2.50043964385986 -A$8) -> 2.5004396 | B21: =B$9 * (2.50043964385986 -B$8) -> 2.5004396 | C21: =C$9 * (2.50043964385986 -C$8) -> 2.5004396 | E21: 19.765131 | F21: 12534.321 | G21: 38444.582
A22: =A$9 * (2.75004076957702 -A$8) -> 2.7500408 | B22: =B$9 * (2.75004076957702 -B$8) -> 2.7500408 | C22: =C$9 * (2.75004076957702 -C$8) -> 2.7500408 | E22: 110.15914 | F22: 11546.524 | G22: 12214.404
A23: =A$9 * (3.00018620491027 -A$8) -> 3.0001862 | B23: =B$9 * (3.00018620491027 -B$8) -> 3.0001862 | C23: =C$9 * (3.00018620491027 -C$8) -> 3.0001862 | E23: 52.675021 | F23: 16680.279 | G23: 25855.805
A24: =A$9 * (3.25007224082946 -A$8) -> 3.2500722 | B24: =B$9 * (3.25007224082946 -B$8) -> 3.2500722 | C24: =C$9 * (3.25007224082946 -C$8) -> 3.2500722 | E24: 33.57434 | F24: 12291.966 | G24: 24467.504
A25: =A$9 * (3.50036668777465 -A$8) -> 3.5003667 | B25: =B$9 * (3.50036668777465 -B$8) -> 3.5003667 | C25: =C$9 * (3.50036668777465 -C$8) -> 3.5003667 | E25: 52.085448 | F25: 9764.5 | G25: 14791.867
A26: =A$9 * (3.7503695487976 -A$8) -> 3.7503695 | B26: =B$9 * (3.7503695487976 -B$8) -> 3.7503695 | C26: =C$9 * (3.7503695487976 -C$8) -> 3.7503695 | E26: 26.534066 | F26: 10370.962 | G26: 24075.417
A27: =A$9 * (4.0003695487976 -A$8) -> 4.0003695 | B27: =B$9 * (4.0003695487976 -B$8) -> 4.0003695 | C27: =C$9 * (4.0003695487976 -C$8) -> 4.0003695 | E27: 16.122913 | F27: 4219.7113 | G27: 13723.113
A28: =A$9 * (4.25045824050903 -A$8) -> 4.2504582 | B28: =B$9 * (4.25045824050903 -B$8) -> 4.2504582 | C28: =C$9 * (4.25045824050903 -C$8) -> 4.2504582 | E28: -0.83366676 | F28: -4375.627 | G28: 2115.9226
A29: =A$9 * (4.50040578842163 -A$8) -> 4.5004058 | B29: =B$9 * (4.50040578842163 -B$8) -> 4.5004058 | C29: =C$9 * (4.50040578842163 -C$8) -> 4.5004058 | E29: -3.2607544 | F29: -2739.9003 | G29: -859.46292
A30: =A$9 * (4.75008058547973 -A$8) -> 4.7500806 | B30: =B$9 * (4.75008058547973 -B$8) -> 4.7500806 | C30: =C$9 * (4.75008058547973 -C$8) -> 4.7500806 | E30: 0.26781228 | F30: -4059.5006 | G30: 7152.2099
A31: =A$9 * (5.00038909912109 -A$8) -> 5.0003891 | B31: =B$9 * (5.00038909912109 -B$8) -> 5.0003891 | C31: =C$9 * (5.00038909912109 -C$8) -> 5.0003891 | E31: -6.4819223 | F31: -998.33761 | G31: -3103.2637
A32: =A$9 * (5.25025558471679 -A$8) -> 5.2502556 | B32: =B$9 * (5.25025558471679 -B$8) -> 5.2502556 | C32: =C$9 * (5.25025558471679 -C$8) -> 5.2502556 | E32: -2.1623749 | F32: -636.18516 | G32: -1097.2523
A33: =A$9 * (5.50069713592529 -A$8) -> 5.5006971 | B33: =B$9 * (5.50069713592529 -B$8) -> 5.5006971 | C33: =C$9 * (5.50069713592529 -C$8) -> 5.5006971 | E33: 41.334262 | F33: 1381.5371 | G33: 3151.4683
A34: =A$9 * (5.75034427642822 -A$8) -> 5.7503443 | B34: =B$9 * (5.75034427642822 -B$8) -> 5.7503443 | C34: =C$9 * (5.75034427642822 -C$8) -> 5.7503443 | E34: 2.5579836 | F34: 984.51941 | G34: 41010.119
A35: =A$9 * (6.00059986114502 -A$8) -> 6.0005999 | B35: =B$9 * (6.00059986114502 -B$8) -> 6.0005999 | C35: =C$9 * (6.00059986114502 -C$8) -> 6.0005999 | E35: 107.53895 | F35: 11939.857 | G35: 12795.959
A36: =A$9 * (6.25033330917358 -A$8) -> 6.2503333 | B36: =B$9 * (6.25033330917358 -B$8) -> 6.2503333 | C36: =C$9 * (6.25033330917358 -C$8) -> 6.2503333 | E36: 68.268422 | F36: 17401.252 | G36: 23706.644
A37: =A$9 * (6.50053310394287 -A$8) -> 6.5005331 | B37: =B$9 * (6.50053310394287 -B$8) -> 6.5005331 | C37: =C$9 * (6.50053310394287 -C$8) -> 6.5005331 | E37: 34.842991 | F37: 13471.128 | G37: 26501.346
A38: =A$9 * (6.75029182434082 -A$8) -> 6.7502918 | B38: =B$9 * (6.75029182434082 -B$8) -> 6.7502918 | C38: =C$9 * (6.75029182434082 -C$8) -> 6.7502918 | E38: 48.339793 | F38: 8371.5082 | G38: 13167.238
A39: =A$9 * (7.00004434585571 -A$8) -> 7.0000443 | B39: =B$9 * (7.00004434585571 -B$8) -> 7.0000443 | C39: =C$9 * (7.00004434585571 -C$8) -> 7.0000443 | E39: 33.858135 | F39: 11917.461 | G39: 23697.439
A40: =A$9 * (7.25014162063598 -A$8) -> 7.2501416 | B40: =B$9 * (7.25014162063598 -B$8) -> 7.2501416 | C40: =C$9 * (7.25014162063598 -C$8) -> 7.2501416 | E40: 19.690254 | F40: 6547.4065 | G40: 18555.869
...
