Workbook

Sheet Legends
A1: VARIABLE | B1: LEGEND
A2: TREND___QLT___(M3_S)___RISER_OUTLET | B2: VAR1
A3: TREND___UL___(M_S)___RISER_OUTLET | B3: VAR2
A4: TREND___UG___(M_S)___RISER_OUTLET | B4: VAR3
A5: TREND___VALVDP___(BAR)___CHOKE_OUTLET_SD2 | B5: VAR4

Sheet SIM1
A1: h | B1: h | C1: h | D1: h | F1: (M3/S) | G1: (M/S) | H1: (M/S) | I1: (BAR)
A2: TIME1 | B2: TIME2 | C2: TIME3 | D2: TIME4 | F2: ='Legends'!B2 -> 0 | G2: ='Legends'!B3 -> 0 | H2: ='Legends'!B4 -> 0 | I2: ='Legends'!B5 -> 0 | K2: Report-2031_Oil_4500bopd_Liquid_4789blpd_15MMSCFD_GL_TD_Only_OP1.genkey
A3: =MIN($A$11:$A$299) -> 0 | B3: =MIN($B$11:$B$299) -> 0 | C3: =MIN($C$11:$C$299) -> 0 | D3: =MIN($D$11:$D$299) -> 0 | E3: Min | F3: =MIN($F$11:$F$299) -> 0 | G3: =MIN($G$11:$G$299) -> 0 | H3: =MIN($H$11:$H$299) -> 0 | I3: =MIN($I$11:$I$299) -> 0
A4: =MEDIAN($A$11:$A$299) -> 0 | B4: =MEDIAN($B$11:$B$299) -> 0 | C4: =MEDIAN($C$11:$C$299) -> 0 | D4: =MEDIAN($D$11:$D$299) -> 0 | E4: P50 | F4: =MEDIAN($F$11:$F$299) -> 0 | G4: =MEDIAN($G$11:$G$299) -> 0 | H4: =MEDIAN($H$11:$H$299) -> 0 | I4: =MEDIAN($I$11:$I$299) -> 0
A5: =MAX($A$11:$A$299) -> 0 | B5: =MAX($B$11:$B$299) -> 0 | C5: =MAX($C$11:$C$299) -> 0 | D5: =MAX($D$11:$D$299) -> 0 | E5: Max | F5: =MAX($F$11:$F$299) -> 0 | G5: =MAX($G$11:$G$299) -> 0 | H5: =MAX($H$11:$H$299) -> 0 | I5: =MAX($I$11:$I$299) -> 0
A6: =$A5-$A3 -> 0 | B6: =$B5-$B3 -> 0 | C6: =$C5-$C3 -> 0 | D6: =$D5-$D3 -> 0 | E6: Delta | F6: =$F5-$F3 -> 0 | G6: =$G5-$G3 -> 0 | H6: =$H5-$H3 -> 0 | I6: =$I5-$I3 -> 0
A7: h | B7: h | C7: h | D7: h | F7: (M3/S) | G7: (M/S) | H7: (M/S) | I7: (BAR)
A8: 0 | B8: 0 | C8: 0 | D8: 0 | E8: Offset | F8: 0 | G8: 0 | H8: 0 | I8: 0
A9: 1 | B9: 1 | C9: 1 | D9: 1 | E9: Scale | F9: 1 | G9: 1 | H9: 1 | I9: 1
A10: TIME1 | B10: TIME2 | C10: TIME3 | D10: TIME4 | F10: ='Legends'!B2 -> 0 | G10: ='Legends'!B3 -> 0 | H10: ='Legends'!B4 -> 0 | I10: ='Legends'!B5 -> 0
A11: =A$9 * (0 -A$8) -> 0 | B11: =B$9 * (0 -B$8) -> 0 | C11: =C$9 * (0 -C$8) -> 0 | D11: =D$9 * (0 -D$8) -> 0 | F11: =F$9 * (0.01899014040827751 -F$8) -> 0 | G11: =G$9 * (6.976023197174072 -G$8) -> 0 | H11: =H$9 * (9.87746524810791 -H$8) -> 0 | I11: =I$9 * (0.04023474827408791 -I$8) -> 0
A12: =A$9 * (0.2503671646118164 -A$8) -> 0 | B12: =B$9 * (0.2503671646118164 -B$8) -> 0 | C12: =C$9 * (0.2503671646118164 -C$8) -> 0 | D12: =D$9 * (0.2503671646118164 -D$8) -> 0 | F12: =F$9 * (0.01097180973738432 -F$8) -> 0 | G12: =G$9 * (7.357691764831543 -G$8) -> 0 | H12: =H$9 * (15.4488697052002 -H$8) -> 0 | I12: =I$9 * (0.05202734097838402 -I$8) -> 0
A13: =A$9 * (0.5001519322395325 -A$8) -> 0 | B13: =B$9 * (0.5001519322395325 -B$8) -> 0 | C13: =C$9 * (0.5001519322395325 -C$8) -> 0 | D13: =D$9 * (0.5001519322395325 -D$8) -> 0 | F13: =F$9 * (0.007581710815429688 -F$8) -> 0 | G13: =G$9 * (5.557830810546875 -G$8) -> 0 | H13: =H$9 * (13.97049045562744 -H$8) -> 0 | I13: =I$9 * (0.03673849999904633 -I$8) -> 0
A14: =A$9 * (0.7503069639205933 -A$8) -> 0 | B14: =B$9 * (0.7503069639205933 -B$8) -> 0 | C14: =C$9 * (0.7503069639205933 -C$8) -> 0 | D14: =D$9 * (0.7503069639205933 -D$8) -> 0 | F14: =F$9 * (0.01136249955743551 -F$8) -> 0 | G14: =G$9 * (6.973039150238037 -G$8) -> 0 | H14: =H$9 * (13.3164701461792 -H$8) -> 0 | I14: =I$9 * (0.04264308884739876 -I$8) -> 0
A15: =A$9 * (1.000024199485779 -A$8) -> 0 | B15: =B$9 * (1.000024199485779 -B$8) -> 0 | C15: =C$9 * (1.000024199485779 -C$8) -> 0 | D15: =D$9 * (1.000024199485779 -D$8) -> 0 | F15: =F$9 * (0.008642112836241722 -F$8) -> 0 | G15: =G$9 * (5.96185302734375 -G$8) -> 0 | H15: =H$9 * (13.49567985534668 -H$8) -> 0 | I15: =I$9 * (0.03733047097921371 -I$8) -> 0
A16: =A$9 * (1.250035881996155 -A$8) -> 0 | B16: =B$9 * (1.250035881996155 -B$8) -> 0 | C16: =C$9 * (1.250035881996155 -C$8) -> 0 | D16: =D$9 * (1.250035881996155 -D$8) -> 0 | F16: =F$9 * (0.01067489013075829 -F$8) -> 0 | G16: =G$9 * (5.957446098327637 -G$8) -> 0 | H16: =H$9 * (11.59778022766113 -H$8) -> 0 | I16: =I$9 * (0.03343437984585762 -I$8) -> 0
A17: =A$9 * (1.500266671180725 -A$8) -> 0 | B17: =B$9 * (1.500266671180725 -B$8) -> 0 | C17: =C$9 * (1.500266671180725 -C$8) -> 0 | D17: =D$9 * (1.500266671180725 -D$8) -> 0 | F17: =F$9 * (0.008710009977221489 -F$8) -> 0 | G17: =G$9 * (5.728689193725586 -G$8) -> 0 | H17: =H$9 * (12.8129301071167 -H$8) -> 0 | I17: =I$9 * (0.03468288108706474 -I$8) -> 0
A18: =A$9 * (1.750089168548584 -A$8) -> 0 | B18: =B$9 * (1.750089168548584 -B$8) -> 0 | C18: =C$9 * (1.750089168548584 -C$8) -> 0 | D18: =D$9 * (1.750089168548584 -D$8) -> 0 | F18: =F$9 * (0.008181803859770298 -F$8) -> 0 | G18: =G$9 * (5.424334049224854 -G$8) -> 0 | H18: =H$9 * (12.61380958557129 -H$8) -> 0 | I18: =I$9 * (0.03280157968401909 -I$8) -> 0
A19: =A$9 * (2.000319719314575 -A$8) -> 0 | B19: =B$9 * (2.000319719314575 -B$8) -> 0 | C19: =C$9 * (2.000319719314575 -C$8) -> 0 | D19: =D$9 * (2.000319719314575 -D$8) -> 0 | F19: =F$9 * (0.01010151021182537 -F$8) -> 0 | G19: =G$9 * (6.053127765655518 -G$8) -> 0 | H19: =H$9 * (12.27962970733643 -H$8) -> 0 | I19: =I$9 * (0.0354129783809185 -I$8) -> 0
A20: =A$9 * (2.250142335891724 -A$8) -> 0 | B20: =B$9 * (2.250142335891724 -B$8) -> 0 | C20: =C$9 * (2.250142335891724 -C$8) -> 0 | D20: =D$9 * (2.250142335891724 -D$8) -> 0 | F20: =F$9 * (0.009255268611013889 -F$8) -> 0 | G20: =G$9 * (5.792596817016602 -G$8) -> 0 | H20: =H$9 * (12.43274974822998 -H$8) -> 0 | I20: =I$9 * (0.03438536077737808 -I$8) -> 0
A21: =A$9 * (2.500373125076294 -A$8) -> 0 | B21: =B$9 * (2.500373125076294 -B$8) -> 0 | C21: =C$9 * (2.500373125076294 -C$8) -> 0 | D21: =D$9 * (2.500373125076294 -D$8) -> 0 | F21: =F$9 * (0.009349054656922817 -F$8) -> 0 | G21: =G$9 * (5.740601062774658 -G$8) -> 0 | H21: =H$9 * (12.22107982635498 -H$8) -> 0 | I21: =I$9 * (0.03372646868228912 -I$8) -> 0
A22: =A$9 * (2.750195503234863 -A$8) -> 0 | B22: =B$9 * (2.750195503234863 -B$8) -> 0 | C22: =C$9 * (2.750195503234863 -C$8) -> 0 | D22: =D$9 * (2.750195503234863 -D$8) -> 0 | F22: =F$9 * (0.009816385805606842 -F$8) -> 0 | G22: =G$9 * (5.94547176361084 -G$8) -> 0 | H22: =H$9 * (12.29277992248535 -H$8) -> 0 | I22: =I$9 * (0.03502615168690681 -I$8) -> 0
A23: =A$9 * (3.000016689300537 -A$8) -> 0 | B23: =B$9 * (3.000016689300537 -B$8) -> 0 | C23: =C$9 * (3.000016689300537 -C$8) -> 0 | D23: =D$9 * (3.000016689300537 -D$8) -> 0 | F23: =F$9 * (0.009557683952152729 -F$8) -> 0 | G23: =G$9 * (5.83661413192749 -G$8) -> 0 | H23: =H$9 * (12.27081966400146 -H$8) -> 0 | I23: =I$9 * (0.03443736955523491 -I$8) -> 0
A24: =A$9 * (3.250250101089478 -A$8) -> 0 | B24: =B$9 * (3.250250101089478 -B$8) -> 0 | C24: =C$9 * (3.250250101089478 -C$8) -> 0 | D24: =D$9 * (3.250250101089478 -D$8) -> 0 | F24: =F$9 * (0.009805687703192234 -F$8) -> 0 | G24: =G$9 * (5.868650913238525 -G$8) -> 0 | H24: =H$9 * (12.12981986999512 -H$8) -> 0 | I24: =I$9 * (0.03436591103672981 -I$8) -> 0
A25: =A$9 * (3.500072240829468 -A$8) -> 0 | B25: =B$9 * (3.500072240829468 -B$8) -> 0 | C25: =C$9 * (3.500072240829468 -C$8) -> 0 | D25: =D$9 * (3.500072240829468 -D$8) -> 0 | F25: =F$9 * (0.01009378954768181 -F$8) -> 0 | G25: =G$9 * (5.998239994049072 -G$8) -> 0 | H25: =H$9 * (12.19044971466064 -H$8) -> 0 | I25: =I$9 * (0.03524487093091011 -I$8) -> 0
A26: =A$9 * (3.750302791595459 -A$8) -> 0 | B26: =B$9 * (3.750302791595459 -B$8) -> 0 | C26: =C$9 * (3.750302791595459 -C$8) -> 0 | D26: =D$9 * (3.750302791595459 -D$8) -> 0 | F26: =F$9 * (0.009907563216984272 -F$8) -> 0 | G26: =G$9 * (5.936785221099854 -G$8) -> 0 | H26: =H$9 * (12.22393035888672 -H$8) -> 0 | I26: =I$9 * (0.03509030118584633 -I$8) -> 0
A27: =A$9 * (4.000124931335449 -A$8) -> 0 | B27: =B$9 * (4.000124931335449 -B$8) -> 0 | C27: =C$9 * (4.000124931335449 -C$8) -> 0 | D27: =D$9 * (4.000124931335449 -D$8) -> 0 | F27: =F$9 * (0.009979641996324062 -F$8) -> 0 | G27: =G$9 * (5.918453216552734 -G$8) -> 0 | H27: =H$9 * (12.14278030395508 -H$8) -> 0 | I27: =I$9 * (0.03498442843556404 -I$8) -> 0
A28: =A$9 * (4.25035572052002 -A$8) -> 0 | B28: =B$9 * (4.25035572052002 -B$8) -> 0 | C28: =C$9 * (4.25035572052002 -C$8) -> 0 | D28: =D$9 * (4.25035572052002 -D$8) -> 0 | F28: =F$9 * (0.009894935414195061 -F$8) -> 0 | G28: =G$9 * (5.897223949432373 -G$8) -> 0 | H28: =H$9 * (12.17510986328125 -H$8) -> 0 | I28: =I$9 * (0.0349937416613102 -I$8) -> 0
A29: =A$9 * (4.50017786026001 -A$8) -> 0 | B29: =B$9 * (4.50017786026001 -B$8) -> 0 | C29: =C$9 * (4.50017786026001 -C$8) -> 0 | D29: =D$9 * (4.50017786026001 -D$8) -> 0 | F29: =F$9 * (0.009788823314011097 -F$8) -> 0 | G29: =G$9 * (5.843953132629395 -G$8) -> 0 | H29: =H$9 * (12.1471004486084 -H$8) -> 0 | I29: =I$9 * (0.03468092158436775 -I$8) -> 0
A30: =A$9 * (4.75 -A$8) -> 0 | B30: =B$9 * (4.75 -B$8) -> 0 | C30: =C$9 * (4.75 -C$8) -> 0 | D30: =D$9 * (4.75 -D$8) -> 0 | F30: =F$9 * (0.009871572256088257 -F$8) -> 0 | G30: =G$9 * (5.861738204956055 -G$8) -> 0 | H30: =H$9 * (12.11773014068604 -H$8) -> 0 | I30: =I$9 * (0.03473073989152908 -I$8) -> 0
A31: =A$9 * (5.00023078918457 -A$8) -> 0 | B31: =B$9 * (5.00023078918457 -B$8) -> 0 | C31: =C$9 * (5.00023078918457 -C$8) -> 0 | D31: =D$9 * (5.00023078918457 -D$8) -> 0 | F31: =F$9 * (0.00983258243650198 -F$8) -> 0 | G31: =G$9 * (5.850683212280273 -G$8) -> 0 | H31: =H$9 * (12.12627029418945 -H$8) -> 0 | I31: =I$9 * (0.03469723090529442 -I$8) -> 0
A32: =A$9 * (5.250052928924561 -A$8) -> 0 | B32: =B$9 * (5.250052928924561 -B$8) -> 0 | C32: =C$9 * (5.250052928924561 -C$8) -> 0 | D32: =D$9 * (5.250052928924561 -D$8) -> 0 | F32: =F$9 * (0.009826762601733208 -F$8) -> 0 | G32: =G$9 * (5.837368011474609 -G$8) -> 0 | H32: =H$9 * (12.10186004638672 -H$8) -> 0 | I32: =I$9 * (0.03459233045578003 -I$8) -> 0
A33: =A$9 * (5.500283241271973 -A$8) -> 0 | B33: =B$9 * (5.500283241271973 -B$8) -> 0 | C33: =C$9 * (5.500283241271973 -C$8) -> 0 | D33: =D$9 * (5.500283241271973 -D$8) -> 0 | F33: =F$9 * (0.009864252991974354 -F$8) -> 0 | G33: =G$9 * (5.846667766571045 -G$8) -> 0 | H33: =H$9 * (12.09193992614746 -H$8) -> 0 | I33: =I$9 * (0.03463288024067879 -I$8) -> 0
A34: =A$9 * (5.750105381011963 -A$8) -> 0 | B34: =B$9 * (5.750105381011963 -B$8) -> 0 | C34: =C$9 * (5.750105381011963 -C$8) -> 0 | D34: =D$9 * (5.750105381011963 -D$8) -> 0 | F34: =F$9 * (0.009843706153333187 -F$8) -> 0 | G34: =G$9 * (5.837972164154053 -G$8) -> 0 | H34: =H$9 * (12.09039974212646 -H$8) -> 0 | I34: =I$9 * (0.03459354862570763 -I$8) -> 0
A35: =A$9 * (6.000336170196533 -A$8) -> 0 | B35: =B$9 * (6.000336170196533 -B$8) -> 0 | C35: =C$9 * (6.000336170196533 -C$8) -> 0 | D35: =D$9 * (6.000336170196533 -D$8) -> 0 | F35: =F$9 * (0.009854025207459927 -F$8) -> 0 | G35: =G$9 * (5.834768772125244 -G$8) -> 0 | H35: =H$9 * (12.07526016235352 -H$8) -> 0 | I35: =I$9 * (0.03455797955393791 -I$8) -> 0
A36: =A$9 * (6.250158309936523 -A$8) -> 0 | B36: =B$9 * (6.250158309936523 -B$8) -> 0 | C36: =C$9 * (6.250158309936523 -C$8) -> 0 | D36: =D$9 * (6.250158309936523 -D$8) -> 0 | F36: =F$9 * (0.009865045547485352 -F$8) -> 0 | G36: =G$9 * (5.836542129516602 -G$8) -> 0 | H36: =H$9 * (12.07067012786865 -H$8) -> 0 | I36: =I$9 * (0.03456699103116989 -I$8) -> 0
A37: =A$9 * (6.500391483306885 -A$8) -> 0 | B37: =B$9 * (6.500391483306885 -B$8) -> 0 | C37: =C$9 * (6.500391483306885 -C$8) -> 0 | D37: =D$9 * (6.500391483306885 -D$8) -> 0 | F37: =F$9 * (0.009856316260993481 -F$8) -> 0 | G37: =G$9 * (5.830729007720947 -G$8) -> 0 | H37: =H$9 * (12.06556034088135 -H$8) -> 0 | I37: =I$9 * (0.03453446924686432 -I$8) -> 0
A38: =A$9 * (6.750214099884033 -A$8) -> 0 | B38: =B$9 * (6.750214099884033 -B$8) -> 0 | C38: =C$9 * (6.750214099884033 -C$8) -> 0 | D38: =D$9 * (6.750214099884033 -D$8) -> 0 | F38: =F$9 * (0.009865122847259045 -F$8) -> 0 | G38: =G$9 * (5.829803943634033 -G$8) -> 0 | H38: =H$9 * (12.05665016174316 -H$8) -> 0 | I38: =I$9 * (0.03452004864811897 -I$8) -> 0
A39: =A$9 * (7.000036239624023 -A$8) -> 0 | B39: =B$9 * (7.000036239624023 -B$8) -> 0 | C39: =C$9 * (7.000036239624023 -C$8) -> 0 | D39: =D$9 * (7.000036239624023 -D$8) -> 0 | F39: =F$9 * (0.009867358021438122 -F$8) -> 0 | G39: =G$9 * (5.828939914703369 -G$8) -> 0 | H39: =H$9 * (12.05333995819092 -H$8) -> 0 | I39: =I$9 * (0.03451545909047127 -I$8) -> 0
A40: =A$9 * (7.250266551971436 -A$8) -> 0 | B40: =B$9 * (7.250266551971436 -B$8) -> 0 | C40: =C$9 * (7.250266551971436 -C$8) -> 0 | D40: =D$9 * (7.250266551971436 -D$8) -> 0 | F40: =F$9 * (0.009864470921456814 -F$8) -> 0 | G40: =G$9 * (5.825331211090088 -G$8) -> 0 | H40: =H$9 * (12.04806995391846 -H$8) -> 0 | I40: =I$9 * (0.0344921313226223 -I$8) -> 0
...

Sheet SIM2
A1: h | B1: h | C1: h | D1: h | F1: (M3/S) | G1: (M/S) | H1: (M/S) | I1: (BAR)
A2: TIME1 | B2: TIME2 | C2: TIME3 | D2: TIME4 | F2: ='Legends'!B2 -> 0 | G2: ='Legends'!B3 -> 0 | H2: ='Legends'!B4 -> 0 | I2: ='Legends'!B5 -> 0 | K2: Report-2031_Oil_4500bopd_Liquid_4789blpd_5MMSCFD_GL_TD_Only_OP1.genkey
A3: =MIN($A$11:$A$299) -> 0 | B3: =MIN($B$11:$B$299) -> 0 | C3: =MIN($C$11:$C$299) -> 0 | D3: =MIN($D$11:$D$299) -> 0 | E3: Min | F3: =MIN($F$11:$F$299) -> 0 | G3: =MIN($G$11:$G$299) -> 0 | H3: =MIN($H$11:$H$299) -> 0 | I3: =MIN($I$11:$I$299) -> 0
A4: =MEDIAN($A$11:$A$299) -> 0 | B4: =MEDIAN($B$11:$B$299) -> 0 | C4: =MEDIAN($C$11:$C$299) -> 0 | D4: =MEDIAN($D$11:$D$299) -> 0 | E4: P50 | F4: =MEDIAN($F$11:$F$299) -> 0 | G4: =MEDIAN($G$11:$G$299) -> 0 | H4: =MEDIAN($H$11:$H$299) -> 0 | I4: =MEDIAN($I$11:$I$299) -> 0
A5: =MAX($A$11:$A$299) -> 0 | B5: =MAX($B$11:$B$299) -> 0 | C5: =MAX($C$11:$C$299) -> 0 | D5: =MAX($D$11:$D$299) -> 0 | E5: Max | F5: =MAX($F$11:$F$299) -> 0 | G5: =MAX($G$11:$G$299) -> 0 | H5: =MAX($H$11:$H$299) -> 0 | I5: =MAX($I$11:$I$299) -> 0
A6: =$A5-$A3 -> 0 | B6: =$B5-$B3 -> 0 | C6: =$C5-$C3 -> 0 | D6: =$D5-$D3 -> 0 | E6: Delta | F6: =$F5-$F3 -> 0 | G6: =$G5-$G3 -> 0 | H6: =$H5-$H3 -> 0 | I6: =$I5-$I3 -> 0
A7: h | B7: h | C7: h | D7: h | F7: (M3/S) | G7: (M/S) | H7: (M/S) | I7: (BAR)
A8: 0 | B8: 0 | C8: 0 | D8: 0 | E8: Offset | F8: 0 | G8: 0 | H8: 0 | I8: 0
A9: 1 | B9: 1 | C9: 1 | D9: 1 | E9: Scale | F9: 1 | G9: 1 | H9: 1 | I9: 1
A10: TIME1 | B10: TIME2 | C10: TIME3 | D10: TIME4 | F10: ='Legends'!B2 -> 0 | G10: ='Legends'!B3 -> 0 | H10: ='Legends'!B4 -> 0 | I10: ='Legends'!B5 -> 0
A11: =A$9 * (0 -A$8) -> 0 | B11: =B$9 * (0 -B$8) -> 0 | C11: =C$9 * (0 -C$8) -> 0 | D11: =D$9 * (0 -D$8) -> 0 | F11: =F$9 * (0.01899014040827751 -F$8) -> 0 | G11: =G$9 * (6.976023197174072 -G$8) -> 0 | H11: =H$9 * (9.87746524810791 -H$8) -> 0 | I11: =I$9 * (0.04023474827408791 -I$8) -> 0
A12: =A$9 * (0.2503923773765564 -A$8) -> 0 | B12: =B$9 * (0.2503923773765564 -B$8) -> 0 | C12: =C$9 * (0.2503923773765564 -C$8) -> 0 | D12: =D$9 * (0.2503923773765564 -D$8) -> 0 | F12: =F$9 * (0.0130656398832798 -F$8) -> 0 | G12: =G$9 * (6.005105018615723 -G$8) -> 0 | H12: =H$9 * (10.26500034332275 -H$8) -> 0 | I12: =I$9 * (0.03208952024579048 -I$8) -> 0
A13: =A$9 * (0.5000028014183044 -A$8) -> 0 | B13: =B$9 * (0.5000028014183044 -B$8) -> 0 | C13: =C$9 * (0.5000028014183044 -C$8) -> 0 | D13: =D$9 * (0.5000028014183044 -D$8) -> 0 | F13: =F$9 * (0.009224898181855679 -F$8) -> 0 | G13: =G$9 * (4.252870082855225 -G$8) -> 0 | H13: =H$9 * (8.758434295654297 -H$8) -> 0 | I13: =I$9 * (0.02026757970452309 -I$8) -> 0
A14: =A$9 * (0.7500805258750916 -A$8) -> 0 | B14: =B$9 * (0.7500805258750916 -B$8) -> 0 | C14: =C$9 * (0.7500805258750916 -C$8) -> 0 | D14: =D$9 * (0.7500805258750916 -D$8) -> 0 | F14: =F$9 * (0.01388760004192591 -F$8) -> 0 | G14: =G$9 * (4.405671119689941 -G$8) -> 0 | H14: =H$9 * (7.069362163543701 -H$8) -> 0 | I14: =I$9 * (0.02031189016997814 -I$8) -> 0
A15: =A$9 * (1.00001060962677 -A$8) -> 0 | B15: =B$9 * (1.00001060962677 -B$8) -> 0 | C15: =C$9 * (1.00001060962677 -C$8) -> 0 | D15: =D$9 * (1.00001060962677 -D$8) -> 0 | F15: =F$9 * (0.008046560920774937 -F$8) -> 0 | G15: =G$9 * (3.715637922286987 -G$8) -> 0 | H15: =H$9 * (8.319994926452637 -H$8) -> 0 | I15: =I$9 * (0.01728381961584091 -I$8) -> 0
A16: =A$9 * (1.250362277030945 -A$8) -> 0 | B16: =B$9 * (1.250362277030945 -B$8) -> 0 | C16: =C$9 * (1.250362277030945 -C$8) -> 0 | D16: =D$9 * (1.250362277030945 -D$8) -> 0 | F16: =F$9 * (0.006253426894545555 -F$8) -> 0 | G16: =G$9 * (2.63515305519104 -G$8) -> 0 | H16: =H$9 * (6.88732385635376 -H$8) -> 0 | I16: =I$9 * (0.0112347798421979 -I$8) -> 0
A17: =A$9 * (1.500348329544067 -A$8) -> 0 | B17: =B$9 * (1.500348329544067 -B$8) -> 0 | C17: =C$9 * (1.500348329544067 -C$8) -> 0 | D17: =D$9 * (1.500348329544067 -D$8) -> 0 | F17: =F$9 * (0.01099324971437454 -F$8) -> 0 | G17: =G$9 * (4.916737079620361 -G$8) -> 0 | H17: =H$9 * (9.149863243103027 -H$8) -> 0 | I17: =I$9 * (0.02428581938147545 -I$8) -> 0
A18: =A$9 * (1.750333905220032 -A$8) -> 0 | B18: =B$9 * (1.750333905220032 -B$8) -> 0 | C18: =C$9 * (1.750333905220032 -C$8) -> 0 | D18: =D$9 * (1.750333905220032 -D$8) -> 0 | F18: =F$9 * (0.007645462173968554 -F$8) -> 0 | G18: =G$9 * (3.215632915496826 -G$8) -> 0 | H18: =H$9 * (7.37236213684082 -H$8) -> 0 | I18: =I$9 * (0.0140394801273942 -I$8) -> 0
A19: =A$9 * (2.000319480895996 -A$8) -> 0 | B19: =B$9 * (2.000319480895996 -B$8) -> 0 | C19: =C$9 * (2.000319480895996 -C$8) -> 0 | D19: =D$9 * (2.000319480895996 -D$8) -> 0 | F19: =F$9 * (0.008920475840568542 -F$8) -> 0 | G19: =G$9 * (2.615137100219727 -G$8) -> 0 | H19: =H$9 * (5.323991775512695 -H$8) -> 0 | I19: =I$9 * (0.009964051656424999 -I$8) -> 0
A20: =A$9 * (2.250304937362671 -A$8) -> 0 | B20: =B$9 * (2.250304937362671 -B$8) -> 0 | C20: =C$9 * (2.250304937362671 -C$8) -> 0 | D20: =D$9 * (2.250304937362671 -D$8) -> 0 | F20: =F$9 * (0.008142299018800259 -F$8) -> 0 | G20: =G$9 * (3.766031980514526 -G$8) -> 0 | H20: =H$9 * (8.366021156311035 -H$8) -> 0 | I20: =I$9 * (0.0175566803663969 -I$8) -> 0
A21: =A$9 * (2.500290632247925 -A$8) -> 0 | B21: =B$9 * (2.500290632247925 -B$8) -> 0 | C21: =C$9 * (2.500290632247925 -C$8) -> 0 | D21: =D$9 * (2.500290632247925 -D$8) -> 0 | F21: =F$9 * (0.007999487221240997 -F$8) -> 0 | G21: =G$9 * (3.323729991912842 -G$8) -> 0 | H21: =H$9 * (7.393245220184326 -H$8) -> 0 | I21: =I$9 * (0.01456431020051241 -I$8) -> 0
A22: =A$9 * (2.7502760887146 -A$8) -> 0 | B22: =B$9 * (2.7502760887146 -B$8) -> 0 | C22: =C$9 * (2.7502760887146 -C$8) -> 0 | D22: =D$9 * (2.7502760887146 -D$8) -> 0 | F22: =F$9 * (0.01836380921304226 -F$8) -> 0 | G22: =G$9 * (5.241350173950195 -G$8) -> 0 | H22: =H$9 * (7.365799903869629 -H$8) -> 0 | I22: =I$9 * (0.02680592983961105 -I$8) -> 0
A23: =A$9 * (3.000097274780273 -A$8) -> 0 | B23: =B$9 * (3.000097274780273 -B$8) -> 0 | C23: =C$9 * (3.000097274780273 -C$8) -> 0 | D23: =D$9 * (3.000097274780273 -D$8) -> 0 | F23: =F$9 * (0.007615745067596436 -F$8) -> 0 | G23: =G$9 * (3.456604957580566 -G$8) -> 0 | H23: =H$9 * (8.01375675201416 -H$8) -> 0 | I23: =I$9 * (0.0158767607063055 -I$8) -> 0
A24: =A$9 * (3.25011944770813 -A$8) -> 0 | B24: =B$9 * (3.25011944770813 -B$8) -> 0 | C24: =C$9 * (3.25011944770813 -C$8) -> 0 | D24: =D$9 * (3.25011944770813 -D$8) -> 0 | F24: =F$9 * (0.005757988896220922 -F$8) -> 0 | G24: =G$9 * (1.466423988342285 -G$8) -> 0 | H24: =H$9 * (3.980041980743408 -H$8) -> 0 | I24: =I$9 * (2.264000045215653E-7 -I$8) -> 0
A25: =A$9 * (3.500241756439209 -A$8) -> 0 | B25: =B$9 * (3.500241756439209 -B$8) -> 0 | C25: =C$9 * (3.500241756439209 -C$8) -> 0 | D25: =D$9 * (3.500241756439209 -D$8) -> 0 | F25: =F$9 * (0.0128260999917984 -F$8) -> 0 | G25: =G$9 * (7.714497089385986 -G$8) -> 0 | H25: =H$9 * (13.99660968780518 -H$8) -> 0 | I25: =I$9 * (0.05035063996911049 -I$8) -> 0
A26: =A$9 * (3.750241756439209 -A$8) -> 0 | B26: =B$9 * (3.750241756439209 -B$8) -> 0 | C26: =C$9 * (3.750241756439209 -C$8) -> 0 | D26: =D$9 * (3.750241756439209 -D$8) -> 0 | F26: =F$9 * (0.009497069753706455 -F$8) -> 0 | G26: =G$9 * (3.955521106719971 -G$8) -> 0 | H26: =H$9 * (8.004570960998535 -H$8) -> 0 | I26: =I$9 * (0.0184132494032383 -I$8) -> 0
A27: =A$9 * (4.000097274780273 -A$8) -> 0 | B27: =B$9 * (4.000097274780273 -B$8) -> 0 | C27: =C$9 * (4.000097274780273 -C$8) -> 0 | D27: =D$9 * (4.000097274780273 -D$8) -> 0 | F27: =F$9 * (-0.0003748451999854296 -F$8) -> 0 | G27: =G$9 * (-0.9890316128730774 -G$8) -> 0 | H27: =H$9 * (0.6646957993507385 -H$8) -> 0 | I27: =I$9 * (1.314000002139437E-7 -I$8) -> 0
A28: =A$9 * (4.250372409820557 -A$8) -> 0 | B28: =B$9 * (4.250372409820557 -B$8) -> 0 | C28: =C$9 * (4.250372409820557 -C$8) -> 0 | D28: =D$9 * (4.250372409820557 -D$8) -> 0 | F28: =F$9 * (-0.001041476032696664 -F$8) -> 0 | G28: =G$9 * (-0.6794130206108093 -G$8) -> 0 | H28: =H$9 * (-0.05409051850438118 -H$8) -> 0 | I28: =I$9 * (0.002414763905107975 -I$8) -> 0
A29: =A$9 * (4.500458240509033 -A$8) -> 0 | B29: =B$9 * (4.500458240509033 -B$8) -> 0 | C29: =C$9 * (4.500458240509033 -C$8) -> 0 | D29: =D$9 * (4.500458240509033 -D$8) -> 0 | F29: =F$9 * (-0.0007887210813350976 -F$8) -> 0 | G29: =G$9 * (-1.047322988510132 -G$8) -> 0 | H29: =H$9 * (0.9475120902061462 -H$8) -> 0 | I29: =I$9 * (0.0002378169010626152 -I$8) -> 0
A30: =A$9 * (4.750261306762695 -A$8) -> 0 | B30: =B$9 * (4.750261306762695 -B$8) -> 0 | C30: =C$9 * (4.750261306762695 -C$8) -> 0 | D30: =D$9 * (4.750261306762695 -D$8) -> 0 | F30: =F$9 * (0.1061370968818665 -F$8) -> 0 | G30: =G$9 * (25.68881988525391 -G$8) -> 0 | H30: =H$9 * (27.84515953063965 -H$8) -> 0 | I30: =I$9 * (0.7688395977020264 -I$8) -> 0
A31: =A$9 * (5.000511169433594 -A$8) -> 0 | B31: =B$9 * (5.000511169433594 -B$8) -> 0 | C31: =C$9 * (5.000511169433594 -C$8) -> 0 | D31: =D$9 * (5.000511169433594 -D$8) -> 0 | F31: =F$9 * (0.003650814993306994 -F$8) -> 0 | G31: =G$9 * (0.474639505147934 -G$8) -> 0 | H31: =H$9 * (1.767848968505859 -H$8) -> 0 | I31: =I$9 * (1.720000000204891E-7 -I$8) -> 0
A32: =A$9 * (5.250458240509033 -A$8) -> 0 | B32: =B$9 * (5.250458240509033 -B$8) -> 0 | C32: =C$9 * (5.250458240509033 -C$8) -> 0 | D32: =D$9 * (5.250458240509033 -D$8) -> 0 | F32: =F$9 * (-0.0005991857033222914 -F$8) -> 0 | G32: =G$9 * (-1.005172967910767 -G$8) -> 0 | H32: =H$9 * (0.6231549978256226 -H$8) -> 0 | I32: =I$9 * (4.929999875002977E-8 -I$8) -> 0
A33: =A$9 * (5.500708103179932 -A$8) -> 0 | B33: =B$9 * (5.500708103179932 -B$8) -> 0 | C33: =C$9 * (5.500708103179932 -C$8) -> 0 | D33: =D$9 * (5.500708103179932 -D$8) -> 0 | F33: =F$9 * (-0.001275021000765264 -F$8) -> 0 | G33: =G$9 * (-1.732679009437561 -G$8) -> 0 | H33: =H$9 * (1.102659940719604 -H$8) -> 0 | I33: =I$9 * (1.96000002006258E-7 -I$8) -> 0
A34: =A$9 * (5.750102996826172 -A$8) -> 0 | B34: =B$9 * (5.750102996826172 -B$8) -> 0 | C34: =C$9 * (5.750102996826172 -C$8) -> 0 | D34: =D$9 * (5.750102996826172 -D$8) -> 0 | F34: =F$9 * (0.137664794921875 -F$8) -> 0 | G34: =G$9 * (10.02826976776123 -G$8) -> 0 | H34: =H$9 * (10.36571979522705 -H$8) -> 0 | I34: =I$9 * (0.2527644038200378 -I$8) -> 0
A35: =A$9 * (6.000141620635986 -A$8) -> 0 | B35: =B$9 * (6.000141620635986 -B$8) -> 0 | C35: =C$9 * (6.000141620635986 -C$8) -> 0 | D35: =D$9 * (6.000141620635986 -D$8) -> 0 | F35: =F$9 * (0.03853410854935646 -F$8) -> 0 | G35: =G$9 * (6.687821865081787 -G$8) -> 0 | H35: =H$9 * (7.165358066558838 -H$8) -> 0 | I35: =I$9 * (0.05159810930490494 -I$8) -> 0
A36: =A$9 * (6.250077724456787 -A$8) -> 0 | B36: =B$9 * (6.250077724456787 -B$8) -> 0 | C36: =C$9 * (6.250077724456787 -C$8) -> 0 | D36: =D$9 * (6.250077724456787 -D$8) -> 0 | F36: =F$9 * (0.01381864957511425 -F$8) -> 0 | G36: =G$9 * (8.080621719360352 -G$8) -> 0 | H36: =H$9 * (14.33267021179199 -H$8) -> 0 | I36: =I$9 * (0.05436401814222336 -I$8) -> 0
A37: =A$9 * (6.500152587890625 -A$8) -> 0 | B37: =B$9 * (6.500152587890625 -B$8) -> 0 | C37: =C$9 * (6.500152587890625 -C$8) -> 0 | D37: =D$9 * (6.500152587890625 -D$8) -> 0 | F37: =F$9 * (0.005012299865484238 -F$8) -> 0 | G37: =G$9 * (2.963341951370239 -G$8) -> 0 | H37: =H$9 * (9.477082252502441 -H$8) -> 0 | I37: =I$9 * (0.01652489043772221 -I$8) -> 0
A38: =A$9 * (6.750280380249023 -A$8) -> 0 | B38: =B$9 * (6.750280380249023 -B$8) -> 0 | C38: =C$9 * (6.750280380249023 -C$8) -> 0 | D38: =D$9 * (6.750280380249023 -D$8) -> 0 | F38: =F$9 * (0.006646659225225449 -F$8) -> 0 | G38: =G$9 * (3.028903007507324 -G$8) -> 0 | H38: =H$9 * (7.74265718460083 -H$8) -> 0 | I38: =I$9 * (0.01404414046555758 -I$8) -> 0
A39: =A$9 * (7.000197410583496 -A$8) -> 0 | B39: =B$9 * (7.000197410583496 -B$8) -> 0 | C39: =C$9 * (7.000197410583496 -C$8) -> 0 | D39: =D$9 * (7.000197410583496 -D$8) -> 0 | F39: =F$9 * (0.004747910890728235 -F$8) -> 0 | G39: =G$9 * (2.366934061050415 -G$8) -> 0 | H39: =H$9 * (7.745597839355469 -H$8) -> 0 | I39: =I$9 * (0.01167813967913389 -I$8) -> 0
A40: =A$9 * (7.250205516815186 -A$8) -> 0 | B40: =B$9 * (7.250205516815186 -B$8) -> 0 | C40: =C$9 * (7.250205516815186 -C$8) -> 0 | D40: =D$9 * (7.250205516815186 -D$8) -> 0 | F40: =F$9 * (0.004248705226927996 -F$8) -> 0 | G40: =G$9 * (1.919296026229858 -G$8) -> 0 | H40: =H$9 * (6.772552967071533 -H$8) -> 0 | I40: =I$9 * (3.965000132666319E-7 -I$8) -> 0
...

Sheet SIM3
A1: h | B1: h | C1: h | D1: h | F1: (M3/S) | G1: (M/S) | H1: (M/S) | I1: (BAR)
A2: TIME1 | B2: TIME2 | C2: TIME3 | D2: TIME4 | F2: ='Legends'!B2 -> 0 | G2: ='Legends'!B3 -> 0 | H2: ='Legends'!B4 -> 0 | I2: ='Legends'!B5 -> 0 | K2: Report-2031_Oil_4500bopd_Liquid_4789blpd_5MMSCFD_GL_TD_Only_OP1_TCV_10pc.genkey
A3: =MIN($A$11:$A$299) -> 0 | B3: =MIN($B$11:$B$299) -> 0 | C3: =MIN($C$11:$C$299) -> 0 | D3: =MIN($D$11:$D$299) -> 0 | E3: Min | F3: =MIN($F$11:$F$299) -> 0 | G3: =MIN($G$11:$G$299) -> 0 | H3: =MIN($H$11:$H$299) -> 0 | I3: =MIN($I$11:$I$299) -> 0
A4: =MEDIAN($A$11:$A$299) -> 0 | B4: =MEDIAN($B$11:$B$299) -> 0 | C4: =MEDIAN($C$11:$C$299) -> 0 | D4: =MEDIAN($D$11:$D$299) -> 0 | E4: P50 | F4: =MEDIAN($F$11:$F$299) -> 0 | G4: =MEDIAN($G$11:$G$299) -> 0 | H4: =MEDIAN($H$11:$H$299) -> 0 | I4: =MEDIAN($I$11:$I$299) -> 0
A5: =MAX($A$11:$A$299) -> 0 | B5: =MAX($B$11:$B$299) -> 0 | C5: =MAX($C$11:$C$299) -> 0 | D5: =MAX($D$11:$D$299) -> 0 | E5: Max | F5: =MAX($F$11:$F$299) -> 0 | G5: =MAX($G$11:$G$299) -> 0 | H5: =MAX($H$11:$H$299) -> 0 | I5: =MAX($I$11:$I$299) -> 0
A6: =$A5-$A3 -> 0 | B6: =$B5-$B3 -> 0 | C6: =$C5-$C3 -> 0 | D6: =$D5-$D3 -> 0 | E6: Delta | F6: =$F5-$F3 -> 0 | G6: =$G5-$G3 -> 0 | H6: =$H5-$H3 -> 0 | I6: =$I5-$I3 -> 0
A7: h | B7: h | C7: h | D7: h | F7: (M3/S) | G7: (M/S) | H7: (M/S) | I7: (BAR)
A8: 0 | B8: 0 | C8: 0 | D8: 0 | E8: Offset | F8: 0 | G8: 0 | H8: 0 | I8: 0
A9: 1 | B9: 1 | C9: 1 | D9: 1 | E9: Scale | F9: 1 | G9: 1 | H9: 1 | I9: 1
A10: TIME1 | B10: TIME2 | C10: TIME3 | D10: TIME4 | F10: ='Legends'!B2 -> 0 | G10: ='Legends'!B3 -> 0 | H10: ='Legends'!B4 -> 0 | I10: ='Legends'!B5 -> 0
A11: =A$9 * (0 -A$8) -> 0 | B11: =B$9 * (0 -B$8) -> 0 | C11: =C$9 * (0 -C$8) -> 0 | D11: =D$9 * (0 -D$8) -> 0 | F11: =F$9 * (0.01899014040827751 -F$8) -> 0 | G11: =G$9 * (6.976023197174072 -G$8) -> 0 | H11: =H$9 * (9.87746524810791 -H$8) -> 0 | I11: =I$9 * (0.04023474827408791 -I$8) -> 0
A12: =A$9 * (0.2503923773765564 -A$8) -> 0 | B12: =B$9 * (0.2503923773765564 -B$8) -> 0 | C12: =C$9 * (0.2503923773765564 -C$8) -> 0 | D12: =D$9 * (0.2503923773765564 -D$8) -> 0 | F12: =F$9 * (0.0130656398832798 -F$8) -> 0 | G12: =G$9 * (6.005105018615723 -G$8) -> 0 | H12: =H$9 * (10.26500034332275 -H$8) -> 0 | I12: =I$9 * (0.03208952024579048 -I$8) -> 0
A13: =A$9 * (0.5000028014183044 -A$8) -> 0 | B13: =B$9 * (0.5000028014183044 -B$8) -> 0 | C13: =C$9 * (0.5000028014183044 -C$8) -> 0 | D13: =D$9 * (0.5000028014183044 -D$8) -> 0 | F13: =F$9 * (0.009224898181855679 -F$8) -> 0 | G13: =G$9 * (4.252870082855225 -G$8) -> 0 | H13: =H$9 * (8.758434295654297 -H$8) -> 0 | I13: =I$9 * (0.02026757970452309 -I$8) -> 0
A14: =A$9 * (0.7500805258750916 -A$8) -> 0 | B14: =B$9 * (0.7500805258750916 -B$8) -> 0 | C14: =C$9 * (0.7500805258750916 -C$8) -> 0 | D14: =D$9 * (0.7500805258750916 -D$8) -> 0 | F14: =F$9 * (0.01388760004192591 -F$8) -> 0 | G14: =G$9 * (4.405671119689941 -G$8) -> 0 | H14: =H$9 * (7.069362163543701 -H$8) -> 0 | I14: =I$9 * (0.02031189016997814 -I$8) -> 0
A15: =A$9 * (1.00001060962677 -A$8) -> 0 | B15: =B$9 * (1.00001060962677 -B$8) -> 0 | C15: =C$9 * (1.00001060962677 -C$8) -> 0 | D15: =D$9 * (1.00001060962677 -D$8) -> 0 | F15: =F$9 * (0.0005696294829249382 -F$8) -> 0 | G15: =G$9 * (0.2561661005020142 -G$8) -> 0 | H15: =H$9 * (2.083694934844971 -H$8) -> 0 | I15: =I$9 * (2.971236944198608 -I$8) -> 0
A16: =A$9 * (1.250348329544067 -A$8) -> 0 | B16: =B$9 * (1.250348329544067 -B$8) -> 0 | C16: =C$9 * (1.250348329544067 -C$8) -> 0 | D16: =D$9 * (1.250348329544067 -D$8) -> 0 | F16: =F$9 * (0.007256591226905584 -F$8) -> 0 | G16: =G$9 * (2.369231939315796 -G$8) -> 0 | H16: =H$9 * (5.474161148071289 -H$8) -> 0 | I16: =I$9 * (3.75844407081604 -I$8) -> 0
A17: =A$9 * (1.50030505657196 -A$8) -> 0 | B17: =B$9 * (1.50030505657196 -B$8) -> 0 | C17: =C$9 * (1.50030505657196 -C$8) -> 0 | D17: =D$9 * (1.50030505657196 -D$8) -> 0 | F17: =F$9 * (0.00816324632614851 -F$8) -> 0 | G17: =G$9 * (2.651293992996216 -G$8) -> 0 | H17: =H$9 * (5.677178859710693 -H$8) -> 0 | I17: =I$9 * (4.475828170776367 -I$8) -> 0
A18: =A$9 * (1.750392556190491 -A$8) -> 0 | B18: =B$9 * (1.750392556190491 -B$8) -> 0 | C18: =C$9 * (1.750392556190491 -C$8) -> 0 | D18: =D$9 * (1.750392556190491 -D$8) -> 0 | F18: =F$9 * (0.006871405988931656 -F$8) -> 0 | G18: =G$9 * (2.744770050048828 -G$8) -> 0 | H18: =H$9 * (6.644062042236328 -H$8) -> 0 | I18: =I$9 * (5.350574016571045 -I$8) -> 0
A19: =A$9 * (2.000049829483032 -A$8) -> 0 | B19: =B$9 * (2.000049829483032 -B$8) -> 0 | C19: =C$9 * (2.000049829483032 -C$8) -> 0 | D19: =D$9 * (2.000049829483032 -D$8) -> 0 | F19: =F$9 * (0.008460048586130142 -F$8) -> 0 | G19: =G$9 * (2.363219022750854 -G$8) -> 0 | H19: =H$9 * (4.914949893951416 -H$8) -> 0 | I19: =I$9 * (3.542853116989136 -I$8) -> 0
A20: =A$9 * (2.250324249267578 -A$8) -> 0 | B20: =B$9 * (2.250324249267578 -B$8) -> 0 | C20: =C$9 * (2.250324249267578 -C$8) -> 0 | D20: =D$9 * (2.250324249267578 -D$8) -> 0 | F20: =F$9 * (0.01086783967912197 -F$8) -> 0 | G20: =G$9 * (3.11926007270813 -G$8) -> 0 | H20: =H$9 * (5.597668170928955 -H$8) -> 0 | I20: =I$9 * (5.754210948944092 -I$8) -> 0
A21: =A$9 * (2.500113248825073 -A$8) -> 0 | B21: =B$9 * (2.500113248825073 -B$8) -> 0 | C21: =C$9 * (2.500113248825073 -C$8) -> 0 | D21: =D$9 * (2.500113248825073 -D$8) -> 0 | F21: =F$9 * (0.008708593435585499 -F$8) -> 0 | G21: =G$9 * (3.018985033035278 -G$8) -> 0 | H21: =H$9 * (6.234920024871826 -H$8) -> 0 | I21: =I$9 * (5.779624938964844 -I$8) -> 0
A22: =A$9 * (2.750228643417358 -A$8) -> 0 | B22: =B$9 * (2.750228643417358 -B$8) -> 0 | C22: =C$9 * (2.750228643417358 -C$8) -> 0 | D22: =D$9 * (2.750228643417358 -D$8) -> 0 | F22: =F$9 * (0.008451846428215504 -F$8) -> 0 | G22: =G$9 * (2.745414018630981 -G$8) -> 0 | H22: =H$9 * (5.756985187530518 -H$8) -> 0 | I22: =I$9 * (4.763092994689941 -I$8) -> 0
A23: =A$9 * (3.000202894210815 -A$8) -> 0 | B23: =B$9 * (3.000202894210815 -B$8) -> 0 | C23: =C$9 * (3.000202894210815 -C$8) -> 0 | D23: =D$9 * (3.000202894210815 -D$8) -> 0 | F23: =F$9 * (0.01171903964132071 -F$8) -> 0 | G23: =G$9 * (3.035969972610474 -G$8) -> 0 | H23: =H$9 * (5.20297384262085 -H$8) -> 0 | I23: =I$9 * (5.401939868927002 -I$8) -> 0
A24: =A$9 * (3.25017786026001 -A$8) -> 0 | B24: =B$9 * (3.25017786026001 -B$8) -> 0 | C24: =C$9 * (3.25017786026001 -C$8) -> 0 | D24: =D$9 * (3.25017786026001 -D$8) -> 0 | F24: =F$9 * (0.008600321598351002 -F$8) -> 0 | G24: =G$9 * (3.099831104278564 -G$8) -> 0 | H24: =H$9 * (6.470314979553223 -H$8) -> 0 | I24: =I$9 * (6.212468147277832 -I$8) -> 0
A25: =A$9 * (3.500149965286255 -A$8) -> 0 | B25: =B$9 * (3.500149965286255 -B$8) -> 0 | C25: =C$9 * (3.500149965286255 -C$8) -> 0 | D25: =D$9 * (3.500149965286255 -D$8) -> 0 | F25: =F$9 * (0.008473405614495277 -F$8) -> 0 | G25: =G$9 * (2.83299708366394 -G$8) -> 0 | H25: =H$9 * (5.944900989532471 -H$8) -> 0 | I25: =I$9 * (5.101128101348877 -I$8) -> 0
A26: =A$9 * (3.750124931335449 -A$8) -> 0 | B26: =B$9 * (3.750124931335449 -B$8) -> 0 | C26: =C$9 * (3.750124931335449 -C$8) -> 0 | D26: =D$9 * (3.750124931335449 -D$8) -> 0 | F26: =F$9 * (0.01202922035008669 -F$8) -> 0 | G26: =G$9 * (2.94678807258606 -G$8) -> 0 | H26: =H$9 * (4.968132972717285 -H$8) -> 0 | I26: =I$9 * (5.099202156066895 -I$8) -> 0
A27: =A$9 * (4.000100135803223 -A$8) -> 0 | B27: =B$9 * (4.000100135803223 -B$8) -> 0 | C27: =C$9 * (4.000100135803223 -C$8) -> 0 | D27: =D$9 * (4.000100135803223 -D$8) -> 0 | F27: =F$9 * (0.009240892715752125 -F$8) -> 0 | G27: =G$9 * (3.230609893798828 -G$8) -> 0 | H27: =H$9 * (6.4491868019104 -H$8) -> 0 | I27: =I$9 * (6.631763935089111 -I$8) -> 0
A28: =A$9 * (4.250072002410889 -A$8) -> 0 | B28: =B$9 * (4.250072002410889 -B$8) -> 0 | C28: =C$9 * (4.250072002410889 -C$8) -> 0 | D28: =D$9 * (4.250072002410889 -D$8) -> 0 | F28: =F$9 * (0.007963317446410656 -F$8) -> 0 | G28: =G$9 * (2.854552984237671 -G$8) -> 0 | H28: =H$9 * (6.266407012939453 -H$8) -> 0 | I28: =I$9 * (5.404962062835693 -I$8) -> 0
A29: =A$9 * (4.500047206878662 -A$8) -> 0 | B29: =B$9 * (4.500047206878662 -B$8) -> 0 | C29: =C$9 * (4.500047206878662 -C$8) -> 0 | D29: =D$9 * (4.500047206878662 -D$8) -> 0 | F29: =F$9 * (0.01188206020742655 -F$8) -> 0 | G29: =G$9 * (2.75789999961853 -G$8) -> 0 | H29: =H$9 * (4.684443950653076 -H$8) -> 0 | I29: =I$9 * (4.563906192779541 -I$8) -> 0
A30: =A$9 * (4.750022411346436 -A$8) -> 0 | B30: =B$9 * (4.750022411346436 -B$8) -> 0 | C30: =C$9 * (4.750022411346436 -C$8) -> 0 | D30: =D$9 * (4.750022411346436 -D$8) -> 0 | F30: =F$9 * (0.009431002661585808 -F$8) -> 0 | G30: =G$9 * (3.270625114440918 -G$8) -> 0 | H30: =H$9 * (6.47621488571167 -H$8) -> 0 | I30: =I$9 * (6.899328231811523 -I$8) -> 0
A31: =A$9 * (5.000447273254395 -A$8) -> 0 | B31: =B$9 * (5.000447273254395 -B$8) -> 0 | C31: =C$9 * (5.000447273254395 -C$8) -> 0 | D31: =D$9 * (5.000447273254395 -D$8) -> 0 | F31: =F$9 * (0.007931373082101345 -F$8) -> 0 | G31: =G$9 * (2.901314973831177 -G$8) -> 0 | H31: =H$9 * (6.417575836181641 -H$8) -> 0 | I31: =I$9 * (5.70858097076416 -I$8) -> 0
A32: =A$9 * (5.25042200088501 -A$8) -> 0 | B32: =B$9 * (5.25042200088501 -B$8) -> 0 | C32: =C$9 * (5.25042200088501 -C$8) -> 0 | D32: =D$9 * (5.25042200088501 -D$8) -> 0 | F32: =F$9 * (0.01156772021204233 -F$8) -> 0 | G32: =G$9 * (2.57667088508606 -G$8) -> 0 | H32: =H$9 * (4.439963817596436 -H$8) -> 0 | I32: =I$9 * (4.061801910400391 -I$8) -> 0
A33: =A$9 * (5.500394344329834 -A$8) -> 0 | B33: =B$9 * (5.500394344329834 -B$8) -> 0 | C33: =C$9 * (5.500394344329834 -C$8) -> 0 | D33: =D$9 * (5.500394344329834 -D$8) -> 0 | F33: =F$9 * (0.009954288601875305 -F$8) -> 0 | G33: =G$9 * (3.355199098587036 -G$8) -> 0 | H33: =H$9 * (6.429596900939941 -H$8) -> 0 | I33: =I$9 * (7.186076164245605 -I$8) -> 0
A34: =A$9 * (5.750369548797607 -A$8) -> 0 | B34: =B$9 * (5.750369548797607 -B$8) -> 0 | C34: =C$9 * (5.750369548797607 -C$8) -> 0 | D34: =D$9 * (5.750369548797607 -D$8) -> 0 | F34: =F$9 * (0.008077426813542843 -F$8) -> 0 | G34: =G$9 * (2.932913064956665 -G$8) -> 0 | H34: =H$9 * (6.414557933807373 -H$8) -> 0 | I34: =I$9 * (5.805255889892578 -I$8) -> 0
A35: =A$9 * (6.000344276428223 -A$8) -> 0 | B35: =B$9 * (6.000344276428223 -B$8) -> 0 | C35: =C$9 * (6.000344276428223 -C$8) -> 0 | D35: =D$9 * (6.000344276428223 -D$8) -> 0 | F35: =F$9 * (0.01107819005846977 -F$8) -> 0 | G35: =G$9 * (2.435096979141235 -G$8) -> 0 | H35: =H$9 * (4.298439025878906 -H$8) -> 0 | I35: =I$9 * (3.687556028366089 -I$8) -> 0
A36: =A$9 * (6.250316619873047 -A$8) -> 0 | B36: =B$9 * (6.250316619873047 -B$8) -> 0 | C36: =C$9 * (6.250316619873047 -C$8) -> 0 | D36: =D$9 * (6.250316619873047 -D$8) -> 0 | F36: =F$9 * (0.0106697203591466 -F$8) -> 0 | G36: =G$9 * (3.413289070129395 -G$8) -> 0 | H36: =H$9 * (6.267036914825439 -H$8) -> 0 | I36: =I$9 * (7.291137218475342 -I$8) -> 0
A37: =A$9 * (6.50029182434082 -A$8) -> 0 | B37: =B$9 * (6.50029182434082 -B$8) -> 0 | C37: =C$9 * (6.50029182434082 -C$8) -> 0 | D37: =D$9 * (6.50029182434082 -D$8) -> 0 | F37: =F$9 * (0.008055947721004486 -F$8) -> 0 | G37: =G$9 * (2.941173076629639 -G$8) -> 0 | H37: =H$9 * (6.448339939117432 -H$8) -> 0 | I37: =I$9 * (5.863420963287354 -I$8) -> 0
A38: =A$9 * (6.750258445739746 -A$8) -> 0 | B38: =B$9 * (6.750258445739746 -B$8) -> 0 | C38: =C$9 * (6.750258445739746 -C$8) -> 0 | D38: =D$9 * (6.750258445739746 -D$8) -> 0 | F38: =F$9 * (0.01034715957939625 -F$8) -> 0 | G38: =G$9 * (2.275924921035767 -G$8) -> 0 | H38: =H$9 * (4.181074142456055 -H$8) -> 0 | I38: =I$9 * (3.299815893173218 -I$8) -> 0
A39: =A$9 * (7.000214099884033 -A$8) -> 0 | B39: =B$9 * (7.000214099884033 -B$8) -> 0 | C39: =C$9 * (7.000214099884033 -C$8) -> 0 | D39: =D$9 * (7.000214099884033 -D$8) -> 0 | F39: =F$9 * (0.01157317962497473 -F$8) -> 0 | G39: =G$9 * (3.447168111801147 -G$8) -> 0 | H39: =H$9 * (6.025957107543945 -H$8) -> 0 | I39: =I$9 * (7.290769100189209 -I$8) -> 0
A40: =A$9 * (7.250169277191162 -A$8) -> 0 | B40: =B$9 * (7.250169277191162 -B$8) -> 0 | C40: =C$9 * (7.250169277191162 -C$8) -> 0 | D40: =D$9 * (7.250169277191162 -D$8) -> 0 | F40: =F$9 * (0.008010442368686199 -F$8) -> 0 | G40: =G$9 * (2.945575952529907 -G$8) -> 0 | H40: =H$9 * (6.488649845123291 -H$8) -> 0 | I40: =I$9 * (5.922506809234619 -I$8) -> 0
...

Sheet SIM4
A1: h | B1: h | C1: h | D1: h | F1: (M3/S) | G1: (M/S) | H1: (M/S) | I1: (BAR)
A2: TIME1 | B2: TIME2 | C2: TIME3 | D2: TIME4 | F2: ='Legends'!B2 -> 0 | G2: ='Legends'!B3 -> 0 | H2: ='Legends'!B4 -> 0 | I2: ='Legends'!B5 -> 0 | K2: Report-2031_Oil_4500bopd_Liquid_4789blpd_5MMSCFD_GL_TD_Only_OP1_TCV_5pc.genkey
A3: =MIN($A$11:$A$299) -> 0 | B3: =MIN($B$11:$B$299) -> 0 | C3: =MIN($C$11:$C$299) -> 0 | D3: =MIN($D$11:$D$299) -> 0 | E3: Min | F3: =MIN($F$11:$F$299) -> 0 | G3: =MIN($G$11:$G$299) -> 0 | H3: =MIN($H$11:$H$299) -> 0 | I3: =MIN($I$11:$I$299) -> 0
A4: =MEDIAN($A$11:$A$299) -> 0 | B4: =MEDIAN($B$11:$B$299) -> 0 | C4: =MEDIAN($C$11:$C$299) -> 0 | D4: =MEDIAN($D$11:$D$299) -> 0 | E4: P50 | F4: =MEDIAN($F$11:$F$299) -> 0 | G4: =MEDIAN($G$11:$G$299) -> 0 | H4: =MEDIAN($H$11:$H$299) -> 0 | I4: =MEDIAN($I$11:$I$299) -> 0
A5: =MAX($A$11:$A$299) -> 0 | B5: =MAX($B$11:$B$299) -> 0 | C5: =MAX($C$11:$C$299) -> 0 | D5: =MAX($D$11:$D$299) -> 0 | E5: Max | F5: =MAX($F$11:$F$299) -> 0 | G5: =MAX($G$11:$G$299) -> 0 | H5: =MAX($H$11:$H$299) -> 0 | I5: =MAX($I$11:$I$299) -> 0
A6: =$A5-$A3 -> 0 | B6: =$B5-$B3 -> 0 | C6: =$C5-$C3 -> 0 | D6: =$D5-$D3 -> 0 | E6: Delta | F6: =$F5-$F3 -> 0 | G6: =$G5-$G3 -> 0 | H6: =$H5-$H3 -> 0 | I6: =$I5-$I3 -> 0
A7: h | B7: h | C7: h | D7: h | F7: (M3/S) | G7: (M/S) | H7: (M/S) | I7: (BAR)
A8: 0 | B8: 0 | C8: 0 | D8: 0 | E8: Offset | F8: 0 | G8: 0 | H8: 0 | I8: 0
A9: 1 | B9: 1 | C9: 1 | D9: 1 | E9: Scale | F9: 1 | G9: 1 | H9: 1 | I9: 1
A10: TIME1 | B10: TIME2 | C10: TIME3 | D10: TIME4 | F10: ='Legends'!B2 -> 0 | G10: ='Legends'!B3 -> 0 | H10: ='Legends'!B4 -> 0 | I10: ='Legends'!B5 -> 0
A11: =A$9 * (0 -A$8) -> 0 | B11: =B$9 * (0 -B$8) -> 0 | C11: =C$9 * (0 -C$8) -> 0 | D11: =D$9 * (0 -D$8) -> 0 | F11: =F$9 * (0.01899014040827751 -F$8) -> 0 | G11: =G$9 * (6.976023197174072 -G$8) -> 0 | H11: =H$9 * (9.87746524810791 -H$8) -> 0 | I11: =I$9 * (0.04023474827408791 -I$8) -> 0
A12: =A$9 * (0.2503923773765564 -A$8) -> 0 | B12: =B$9 * (0.2503923773765564 -B$8) -> 0 | C12: =C$9 * (0.2503923773765564 -C$8) -> 0 | D12: =D$9 * (0.2503923773765564 -D$8) -> 0 | F12: =F$9 * (0.0130656398832798 -F$8) -> 0 | G12: =G$9 * (6.005105018615723 -G$8) -> 0 | H12: =H$9 * (10.26500034332275 -H$8) -> 0 | I12: =I$9 * (0.03208952024579048 -I$8) -> 0
A13: =A$9 * (0.5000028014183044 -A$8) -> 0 | B13: =B$9 * (0.5000028014183044 -B$8) -> 0 | C13: =C$9 * (0.5000028014183044 -C$8) -> 0 | D13: =D$9 * (0.5000028014183044 -D$8) -> 0 | F13: =F$9 * (0.009224898181855679 -F$8) -> 0 | G13: =G$9 * (4.252870082855225 -G$8) -> 0 | H13: =H$9 * (8.758434295654297 -H$8) -> 0 | I13: =I$9 * (0.02026757970452309 -I$8) -> 0
A14: =A$9 * (0.7500805258750916 -A$8) -> 0 | B14: =B$9 * (0.7500805258750916 -B$8) -> 0 | C14: =C$9 * (0.7500805258750916 -C$8) -> 0 | D14: =D$9 * (0.7500805258750916 -D$8) -> 0 | F14: =F$9 * (0.01388760004192591 -F$8) -> 0 | G14: =G$9 * (4.405671119689941 -G$8) -> 0 | H14: =H$9 * (7.069362163543701 -H$8) -> 0 | I14: =I$9 * (0.02031189016997814 -I$8) -> 0
A15: =A$9 * (1.00001060962677 -A$8) -> 0 | B15: =B$9 * (1.00001060962677 -B$8) -> 0 | C15: =C$9 * (1.00001060962677 -C$8) -> 0 | D15: =D$9 * (1.00001060962677 -D$8) -> 0 | F15: =F$9 * (-0.003372678067535162 -F$8) -> 0 | G15: =G$9 * (-1.612897992134094 -G$8) -> 0 | H15: =H$9 * (-2.599679946899414 -H$8) -> 0 | I15: =I$9 * (9.708891868591309 -I$8) -> 0
A16: =A$9 * (1.250212550163269 -A$8) -> 0 | B16: =B$9 * (1.250212550163269 -B$8) -> 0 | C16: =C$9 * (1.250212550163269 -C$8) -> 0 | D16: =D$9 * (1.250212550163269 -D$8) -> 0 | F16: =F$9 * (-0.0003163136134389788 -F$8) -> 0 | G16: =G$9 * (-2.18445611000061 -G$8) -> 0 | H16: =H$9 * (1.790732979774475 -H$8) -> 0 | I16: =I$9 * (4.851388931274414 -I$8) -> 0
A17: =A$9 * (1.50015115737915 -A$8) -> 0 | B17: =B$9 * (1.50015115737915 -B$8) -> 0 | C17: =C$9 * (1.50015115737915 -C$8) -> 0 | D17: =D$9 * (1.50015115737915 -D$8) -> 0 | F17: =F$9 * (0.001392820966430008 -F$8) -> 0 | G17: =G$9 * (-1.745538949966431 -G$8) -> 0 | H17: =H$9 * (1.393306970596313 -H$8) -> 0 | I17: =I$9 * (5.958818912506104 -I$8) -> 0
A18: =A$9 * (1.750082492828369 -A$8) -> 0 | B18: =B$9 * (1.750082492828369 -B$8) -> 0 | C18: =C$9 * (1.750082492828369 -C$8) -> 0 | D18: =D$9 * (1.750082492828369 -D$8) -> 0 | F18: =F$9 * (0.002279487904161215 -F$8) -> 0 | G18: =G$9 * (-2.245676040649414 -G$8) -> 0 | H18: =H$9 * (1.384389042854309 -H$8) -> 0 | I18: =I$9 * (14.52054977416992 -I$8) -> 0
A19: =A$9 * (2.000370740890503 -A$8) -> 0 | B19: =B$9 * (2.000370740890503 -B$8) -> 0 | C19: =C$9 * (2.000370740890503 -C$8) -> 0 | D19: =D$9 * (2.000370740890503 -D$8) -> 0 | F19: =F$9 * (0.008723045699298382 -F$8) -> 0 | G19: =G$9 * (2.091460943222046 -G$8) -> 0 | H19: =H$9 * (4.062270164489746 -H$8) -> 0 | I19: =I$9 * (25.39755058288574 -I$8) -> 0
A20: =A$9 * (2.250343084335327 -A$8) -> 0 | B20: =B$9 * (2.250343084335327 -B$8) -> 0 | C20: =C$9 * (2.250343084335327 -C$8) -> 0 | D20: =D$9 * (2.250343084335327 -D$8) -> 0 | F20: =F$9 * (0.006273952778428793 -F$8) -> 0 | G20: =G$9 * (2.104238986968994 -G$8) -> 0 | H20: =H$9 * (5.047359943389893 -H$8) -> 0 | I20: =I$9 * (7.09949779510498 -I$8) -> 0
A21: =A$9 * (2.500083684921265 -A$8) -> 0 | B21: =B$9 * (2.500083684921265 -B$8) -> 0 | C21: =C$9 * (2.500083684921265 -C$8) -> 0 | D21: =D$9 * (2.500083684921265 -D$8) -> 0 | F21: =F$9 * (0.01268788985908031 -F$8) -> 0 | G21: =G$9 * (1.368736028671265 -G$8) -> 0 | H21: =H$9 * (2.092298984527588 -H$8) -> 0 | I21: =I$9 * (8.266169548034668 -I$8) -> 0
A22: =A$9 * (2.750252246856689 -A$8) -> 0 | B22: =B$9 * (2.750252246856689 -B$8) -> 0 | C22: =C$9 * (2.750252246856689 -C$8) -> 0 | D22: =D$9 * (2.750252246856689 -D$8) -> 0 | F22: =F$9 * (0.01907997019588947 -F$8) -> 0 | G22: =G$9 * (2.017231941223145 -G$8) -> 0 | H22: =H$9 * (2.524672985076904 -H$8) -> 0 | I22: =I$9 * (22.5219898223877 -I$8) -> 0
A23: =A$9 * (3.000216722488403 -A$8) -> 0 | B23: =B$9 * (3.000216722488403 -B$8) -> 0 | C23: =C$9 * (3.000216722488403 -C$8) -> 0 | D23: =D$9 * (3.000216722488403 -D$8) -> 0 | F23: =F$9 * (0.006877514068037271 -F$8) -> 0 | G23: =G$9 * (1.981701016426086 -G$8) -> 0 | H23: =H$9 * (4.34011697769165 -H$8) -> 0 | I23: =I$9 * (24.76015090942383 -I$8) -> 0
A24: =A$9 * (3.250436067581177 -A$8) -> 0 | B24: =B$9 * (3.250436067581177 -B$8) -> 0 | C24: =C$9 * (3.250436067581177 -C$8) -> 0 | D24: =D$9 * (3.250436067581177 -D$8) -> 0 | F24: =F$9 * (0.007994884625077248 -F$8) -> 0 | G24: =G$9 * (1.930199027061462 -G$8) -> 0 | H24: =H$9 * (4.004549026489258 -H$8) -> 0 | I24: =I$9 * (22.60177993774414 -I$8) -> 0
A25: =A$9 * (3.50005841255188 -A$8) -> 0 | B25: =B$9 * (3.50005841255188 -B$8) -> 0 | C25: =C$9 * (3.50005841255188 -C$8) -> 0 | D25: =D$9 * (3.50005841255188 -D$8) -> 0 | F25: =F$9 * (0.01312362961471081 -F$8) -> 0 | G25: =G$9 * (1.885370016098022 -G$8) -> 0 | H25: =H$9 * (2.879342079162598 -H$8) -> 0 | I25: =I$9 * (17.9199104309082 -I$8) -> 0
A26: =A$9 * (3.750363826751709 -A$8) -> 0 | B26: =B$9 * (3.750363826751709 -B$8) -> 0 | C26: =C$9 * (3.750363826751709 -C$8) -> 0 | D26: =D$9 * (3.750363826751709 -D$8) -> 0 | F26: =F$9 * (0.01291069015860558 -F$8) -> 0 | G26: =G$9 * (2.039254903793335 -G$8) -> 0 | H26: =H$9 * (3.220103025436401 -H$8) -> 0 | I26: =I$9 * (22.36252021789551 -I$8) -> 0
A27: =A$9 * (4.000669479370117 -A$8) -> 0 | B27: =B$9 * (4.000669479370117 -B$8) -> 0 | C27: =C$9 * (4.000669479370117 -C$8) -> 0 | D27: =D$9 * (4.000669479370117 -D$8) -> 0 | F27: =F$9 * (0.007821237668395042 -F$8) -> 0 | G27: =G$9 * (1.940299034118652 -G$8) -> 0 | H27: =H$9 * (4.056522846221924 -H$8) -> 0 | I27: =I$9 * (22.96622085571289 -I$8) -> 0
A28: =A$9 * (4.250608444213867 -A$8) -> 0 | B28: =B$9 * (4.250608444213867 -B$8) -> 0 | C28: =C$9 * (4.250608444213867 -C$8) -> 0 | D28: =D$9 * (4.250608444213867 -D$8) -> 0 | F28: =F$9 * (0.007098529953509569 -F$8) -> 0 | G28: =G$9 * (1.81311297416687 -G$8) -> 0 | H28: =H$9 * (4.054679870605469 -H$8) -> 0 | I28: =I$9 * (21.10944938659668 -I$8) -> 0
A29: =A$9 * (4.500080585479736 -A$8) -> 0 | B29: =B$9 * (4.500080585479736 -B$8) -> 0 | C29: =C$9 * (4.500080585479736 -C$8) -> 0 | D29: =D$9 * (4.500080585479736 -D$8) -> 0 | F29: =F$9 * (0.01275001000612974 -F$8) -> 0 | G29: =G$9 * (1.881240963935852 -G$8) -> 0 | H29: =H$9 * (2.928603887557983 -H$8) -> 0 | I29: =I$9 * (18.06533050537109 -I$8) -> 0
A30: =A$9 * (4.750102996826172 -A$8) -> 0 | B30: =B$9 * (4.750102996826172 -B$8) -> 0 | C30: =C$9 * (4.750102996826172 -C$8) -> 0 | D30: =D$9 * (4.750102996826172 -D$8) -> 0 | F30: =F$9 * (0.01124729961156845 -F$8) -> 0 | G30: =G$9 * (1.988312005996704 -G$8) -> 0 | H30: =H$9 * (3.413183927536011 -H$8) -> 0 | I30: =I$9 * (21.98818969726562 -I$8) -> 0
A31: =A$9 * (5.000124931335449 -A$8) -> 0 | B31: =B$9 * (5.000124931335449 -B$8) -> 0 | C31: =C$9 * (5.000124931335449 -C$8) -> 0 | D31: =D$9 * (5.000124931335449 -D$8) -> 0 | F31: =F$9 * (0.00835808739066124 -F$8) -> 0 | G31: =G$9 * (1.903880953788757 -G$8) -> 0 | H31: =H$9 * (3.89182710647583 -H$8) -> 0 | I31: =I$9 * (22.12310981750488 -I$8) -> 0
A32: =A$9 * (5.250147342681885 -A$8) -> 0 | B32: =B$9 * (5.250147342681885 -B$8) -> 0 | C32: =C$9 * (5.250147342681885 -C$8) -> 0 | D32: =D$9 * (5.250147342681885 -D$8) -> 0 | F32: =F$9 * (0.007808811031281948 -F$8) -> 0 | G32: =G$9 * (1.794935941696167 -G$8) -> 0 | H32: =H$9 * (3.858082056045532 -H$8) -> 0 | I32: =I$9 * (20.45653915405273 -I$8) -> 0
A33: =A$9 * (5.500169277191162 -A$8) -> 0 | B33: =B$9 * (5.500169277191162 -B$8) -> 0 | C33: =C$9 * (5.500169277191162 -C$8) -> 0 | D33: =D$9 * (5.500169277191162 -D$8) -> 0 | F33: =F$9 * (0.01244520023465157 -F$8) -> 0 | G33: =G$9 * (1.897909045219421 -G$8) -> 0 | H33: =H$9 * (3.009910106658936 -H$8) -> 0 | I33: =I$9 * (18.94076919555664 -I$8) -> 0
A34: =A$9 * (5.750191688537598 -A$8) -> 0 | B34: =B$9 * (5.750191688537598 -B$8) -> 0 | C34: =C$9 * (5.750191688537598 -C$8) -> 0 | D34: =D$9 * (5.750191688537598 -D$8) -> 0 | F34: =F$9 * (0.01060689985752106 -F$8) -> 0 | G34: =G$9 * (1.957725048065186 -G$8) -> 0 | H34: =H$9 * (3.489475011825562 -H$8) -> 0 | I34: =I$9 * (21.85592079162598 -I$8) -> 0
A35: =A$9 * (6.000214099884033 -A$8) -> 0 | B35: =B$9 * (6.000214099884033 -B$8) -> 0 | C35: =C$9 * (6.000214099884033 -C$8) -> 0 | D35: =D$9 * (6.000214099884033 -D$8) -> 0 | F35: =F$9 * (0.008626800030469894 -F$8) -> 0 | G35: =G$9 * (1.893583059310913 -G$8) -> 0 | H35: =H$9 * (3.823539972305298 -H$8) -> 0 | I35: =I$9 * (21.90521049499512 -I$8) -> 0
A36: =A$9 * (6.250236034393311 -A$8) -> 0 | B36: =B$9 * (6.250236034393311 -B$8) -> 0 | C36: =C$9 * (6.250236034393311 -C$8) -> 0 | D36: =D$9 * (6.250236034393311 -D$8) -> 0 | F36: =F$9 * (0.008631167933344841 -F$8) -> 0 | G36: =G$9 * (1.808351039886475 -G$8) -> 0 | H36: =H$9 * (3.68880295753479 -H$8) -> 0 | I36: =I$9 * (20.22295951843262 -I$8) -> 0
A37: =A$9 * (6.500255584716797 -A$8) -> 0 | B37: =B$9 * (6.500255584716797 -B$8) -> 0 | C37: =C$9 * (6.500255584716797 -C$8) -> 0 | D37: =D$9 * (6.500255584716797 -D$8) -> 0 | F37: =F$9 * (0.01227410044521093 -F$8) -> 0 | G37: =G$9 * (1.890519022941589 -G$8) -> 0 | H37: =H$9 * (3.081933975219727 -H$8) -> 0 | I37: =I$9 * (20.03248977661133 -I$8) -> 0
A38: =A$9 * (6.750277996063232 -A$8) -> 0 | B38: =B$9 * (6.750277996063232 -B$8) -> 0 | C38: =C$9 * (6.750277996063232 -C$8) -> 0 | D38: =D$9 * (6.750277996063232 -D$8) -> 0 | F38: =F$9 * (0.01033032033592463 -F$8) -> 0 | G38: =G$9 * (1.950119972229004 -G$8) -> 0 | H38: =H$9 * (3.53302788734436 -H$8) -> 0 | I38: =I$9 * (21.8056697845459 -I$8) -> 0
A39: =A$9 * (7.00029993057251 -A$8) -> 0 | B39: =B$9 * (7.00029993057251 -B$8) -> 0 | C39: =C$9 * (7.00029993057251 -C$8) -> 0 | D39: =D$9 * (7.00029993057251 -D$8) -> 0 | F39: =F$9 * (0.009070499800145626 -F$8) -> 0 | G39: =G$9 * (1.897393941879272 -G$8) -> 0 | H39: =H$9 * (3.733963012695312 -H$8) -> 0 | I39: =I$9 * (21.66011047363281 -I$8) -> 0
A40: =A$9 * (7.250322341918945 -A$8) -> 0 | B40: =B$9 * (7.250322341918945 -B$8) -> 0 | C40: =C$9 * (7.250322341918945 -C$8) -> 0 | D40: =D$9 * (7.250322341918945 -D$8) -> 0 | F40: =F$9 * (0.00943301897495985 -F$8) -> 0 | G40: =G$9 * (1.865110993385315 -G$8) -> 0 | H40: =H$9 * (3.583715915679932 -H$8) -> 0 | I40: =I$9 * (20.62030029296875 -I$8) -> 0
...

Sheet SIM5
A1: h | B1: h | C1: h | D1: h | F1: (M3/S) | G1: (M/S) | H1: (M/S) | I1: (BAR)
A2: TIME1 | B2: TIME2 | C2: TIME3 | D2: TIME4 | F2: ='Legends'!B2 -> 0 | G2: ='Legends'!B3 -> 0 | H2: ='Legends'!B4 -> 0 | I2: ='Legends'!B5 -> 0 | K2: Report-2031_Oil_4500bopd_Liquid_4789blpd_No_GL_TD_Only_OP1.genkey
A3: =MIN($A$11:$A$299) -> 0 | B3: =MIN($B$11:$B$299) -> 0 | C3: =MIN($C$11:$C$299) -> 0 | D3: =MIN($D$11:$D$299) -> 0 | E3: Min | F3: =MIN($F$11:$F$299) -> 0 | G3: =MIN($G$11:$G$299) -> 0 | H3: =MIN($H$11:$H$299) -> 0 | I3: =MIN($I$11:$I$299) -> 0
A4: =MEDIAN($A$11:$A$299) -> 0 | B4: =MEDIAN($B$11:$B$299) -> 0 | C4: =MEDIAN($C$11:$C$299) -> 0 | D4: =MEDIAN($D$11:$D$299) -> 0 | E4: P50 | F4: =MEDIAN($F$11:$F$299) -> 0 | G4: =MEDIAN($G$11:$G$299) -> 0 | H4: =MEDIAN($H$11:$H$299) -> 0 | I4: =MEDIAN($I$11:$I$299) -> 0
A5: =MAX($A$11:$A$299) -> 0 | B5: =MAX($B$11:$B$299) -> 0 | C5: =MAX($C$11:$C$299) -> 0 | D5: =MAX($D$11:$D$299) -> 0 | E5: Max | F5: =MAX($F$11:$F$299) -> 0 | G5: =MAX($G$11:$G$299) -> 0 | H5: =MAX($H$11:$H$299) -> 0 | I5: =MAX($I$11:$I$299) -> 0
A6: =$A5-$A3 -> 0 | B6: =$B5-$B3 -> 0 | C6: =$C5-$C3 -> 0 | D6: =$D5-$D3 -> 0 | E6: Delta | F6: =$F5-$F3 -> 0 | G6: =$G5-$G3 -> 0 | H6: =$H5-$H3 -> 0 | I6: =$I5-$I3 -> 0
A7: h | B7: h | C7: h | D7: h | F7: (M3/S) | G7: (M/S) | H7: (M/S) | I7: (BAR)
A8: 0 | B8: 0 | C8: 0 | D8: 0 | E8: Offset | F8: 0 | G8: 0 | H8: 0 | I8: 0
A9: 1 | B9: 1 | C9: 1 | D9: 1 | E9: Scale | F9: 1 | G9: 1 | H9: 1 | I9: 1
A10: TIME1 | B10: TIME2 | C10: TIME3 | D10: TIME4 | F10: ='Legends'!B2 -> 0 | G10: ='Legends'!B3 -> 0 | H10: ='Legends'!B4 -> 0 | I10: ='Legends'!B5 -> 0
A11: =A$9 * (0 -A$8) -> 0 | B11: =B$9 * (0 -B$8) -> 0 | C11: =C$9 * (0 -C$8) -> 0 | D11: =D$9 * (0 -D$8) -> 0 | F11: =F$9 * (0.01899014040827751 -F$8) -> 0 | G11: =G$9 * (6.976023197174072 -G$8) -> 0 | H11: =H$9 * (9.87746524810791 -H$8) -> 0 | I11: =I$9 * (0.04023474827408791 -I$8) -> 0
A12: =A$9 * (0.2503698766231537 -A$8) -> 0 | B12: =B$9 * (0.2503698766231537 -B$8) -> 0 | C12: =C$9 * (0.2503698766231537 -C$8) -> 0 | D12: =D$9 * (0.2503698766231537 -D$8) -> 0 | F12: =F$9 * (0.0127095403149724 -F$8) -> 0 | G12: =G$9 * (4.013641834259033 -G$8) -> 0 | H12: =H$9 * (6.724209785461426 -H$8) -> 0 | I12: =I$9 * (0.01786009036004543 -I$8) -> 0
A13: =A$9 * (0.5003474950790405 -A$8) -> 0 | B13: =B$9 * (0.5003474950790405 -B$8) -> 0 | C13: =C$9 * (0.5003474950790405 -C$8) -> 0 | D13: =D$9 * (0.5003474950790405 -D$8) -> 0 | F13: =F$9 * (0.009269413538277149 -F$8) -> 0 | G13: =G$9 * (2.928809881210327 -G$8) -> 0 | H13: =H$9 * (5.848559856414795 -H$8) -> 0 | I13: =I$9 * (0.01166731957346201 -I$8) -> 0
A14: =A$9 * (0.7503663897514343 -A$8) -> 0 | B14: =B$9 * (0.7503663897514343 -B$8) -> 0 | C14: =C$9 * (0.7503663897514343 -C$8) -> 0 | D14: =D$9 * (0.7503663897514343 -D$8) -> 0 | F14: =F$9 * (0.002632620977237821 -F$8) -> 0 | G14: =G$9 * (0.5996202230453491 -G$8) -> 0 | H14: =H$9 * (2.995414018630981 -H$8) -> 0 | I14: =I$9 * (2.48699990379464E-7 -I$8) -> 0
A15: =A$9 * (1.000272274017334 -A$8) -> 0 | B15: =B$9 * (1.000272274017334 -B$8) -> 0 | C15: =C$9 * (1.000272274017334 -C$8) -> 0 | D15: =D$9 * (1.000272274017334 -D$8) -> 0 | F15: =F$9 * (-0.00185360899195075 -F$8) -> 0 | G15: =G$9 * (-1.749161005020142 -G$8) -> 0 | H15: =H$9 * (0.3458889126777649 -H$8) -> 0 | I15: =I$9 * (3.508999952828162E-7 -I$8) -> 0
A16: =A$9 * (1.250338554382324 -A$8) -> 0 | B16: =B$9 * (1.250338554382324 -B$8) -> 0 | C16: =C$9 * (1.250338554382324 -C$8) -> 0 | D16: =D$9 * (1.250338554382324 -D$8) -> 0 | F16: =F$9 * (-0.001179191982373595 -F$8) -> 0 | G16: =G$9 * (-1.43955397605896 -G$8) -> 0 | H16: =H$9 * (0.3663032054901123 -H$8) -> 0 | I16: =I$9 * (2.1760000379345E-7 -I$8) -> 0
A17: =A$9 * (1.500310778617859 -A$8) -> 0 | B17: =B$9 * (1.500310778617859 -B$8) -> 0 | C17: =C$9 * (1.500310778617859 -C$8) -> 0 | D17: =D$9 * (1.500310778617859 -D$8) -> 0 | F17: =F$9 * (-0.002168271923437715 -F$8) -> 0 | G17: =G$9 * (-1.193088054656982 -G$8) -> 0 | H17: =H$9 * (-0.8842821717262268 -H$8) -> 0 | I17: =I$9 * (1.592179978615604E-5 -I$8) -> 0
A18: =A$9 * (1.750393390655518 -A$8) -> 0 | B18: =B$9 * (1.750393390655518 -B$8) -> 0 | C18: =C$9 * (1.750393390655518 -C$8) -> 0 | D18: =D$9 * (1.750393390655518 -D$8) -> 0 | F18: =F$9 * (-0.002610733965411782 -F$8) -> 0 | G18: =G$9 * (-1.002915024757385 -G$8) -> 0 | H18: =H$9 * (-1.964154958724976 -H$8) -> 0 | I18: =I$9 * (0.0007428731769323349 -I$8) -> 0
A19: =A$9 * (2.000298500061035 -A$8) -> 0 | B19: =B$9 * (2.000298500061035 -B$8) -> 0 | C19: =C$9 * (2.000298500061035 -C$8) -> 0 | D19: =D$9 * (2.000298500061035 -D$8) -> 0 | F19: =F$9 * (-0.000678984506521374 -F$8) -> 0 | G19: =G$9 * (-0.5985733866691589 -G$8) -> 0 | H19: =H$9 * (0.2452626973390579 -H$8) -> 0 | I19: =I$9 * (3.551259942469187E-5 -I$8) -> 0
A20: =A$9 * (2.250226020812988 -A$8) -> 0 | B20: =B$9 * (2.250226020812988 -B$8) -> 0 | C20: =C$9 * (2.250226020812988 -C$8) -> 0 | D20: =D$9 * (2.250226020812988 -D$8) -> 0 | F20: =F$9 * (4.167799852439202E-5 -F$8) -> 0 | G20: =G$9 * (-3.886600017547607 -G$8) -> 0 | H20: =H$9 * (0.7135136127471924 -H$8) -> 0 | I20: =I$9 * (4.799999828719592E-7 -I$8) -> 0
A21: =A$9 * (2.500319957733154 -A$8) -> 0 | B21: =B$9 * (2.500319957733154 -B$8) -> 0 | C21: =C$9 * (2.500319957733154 -C$8) -> 0 | D21: =D$9 * (2.500319957733154 -D$8) -> 0 | F21: =F$9 * (0.01630106009542942 -F$8) -> 0 | G21: =G$9 * (7.639770030975342 -G$8) -> 0 | H21: =H$9 * (12.07009029388428 -H$8) -> 0 | I21: =I$9 * (0.04675766825675964 -I$8) -> 0
A22: =A$9 * (2.750267744064331 -A$8) -> 0 | B22: =B$9 * (2.750267744064331 -B$8) -> 0 | C22: =C$9 * (2.750267744064331 -C$8) -> 0 | D22: =D$9 * (2.750267744064331 -D$8) -> 0 | F22: =F$9 * (0.06876353174448013 -F$8) -> 0 | G22: =G$9 * (9.15025806427002 -G$8) -> 0 | H22: =H$9 * (9.636834144592285 -H$8) -> 0 | I22: =I$9 * (0.1209719032049179 -I$8) -> 0
A23: =A$9 * (3.000191688537598 -A$8) -> 0 | B23: =B$9 * (3.000191688537598 -B$8) -> 0 | C23: =C$9 * (3.000191688537598 -C$8) -> 0 | D23: =D$9 * (3.000191688537598 -D$8) -> 0 | F23: =F$9 * (0.01289913989603519 -F$8) -> 0 | G23: =G$9 * (7.092512130737305 -G$8) -> 0 | H23: =H$9 * (12.53713989257812 -H$8) -> 0 | I23: =I$9 * (0.0426502488553524 -I$8) -> 0
A24: =A$9 * (3.250283241271973 -A$8) -> 0 | B24: =B$9 * (3.250283241271973 -B$8) -> 0 | C24: =C$9 * (3.250283241271973 -C$8) -> 0 | D24: =D$9 * (3.250283241271973 -D$8) -> 0 | F24: =F$9 * (0.003646072000265121 -F$8) -> 0 | G24: =G$9 * (1.124827980995178 -G$8) -> 0 | H24: =H$9 * (4.389116764068604 -H$8) -> 0 | I24: =I$9 * (6.766999831597786E-7 -I$8) -> 0
A25: =A$9 * (3.500147104263306 -A$8) -> 0 | B25: =B$9 * (3.500147104263306 -B$8) -> 0 | C25: =C$9 * (3.500147104263306 -C$8) -> 0 | D25: =D$9 * (3.500147104263306 -D$8) -> 0 | F25: =F$9 * (-0.0003267576976213604 -F$8) -> 0 | G25: =G$9 * (-1.365815043449402 -G$8) -> 0 | H25: =H$9 * (2.290347099304199 -H$8) -> 0 | I25: =I$9 * (6.47899980776856E-7 -I$8) -> 0
A26: =A$9 * (3.750288963317871 -A$8) -> 0 | B26: =B$9 * (3.750288963317871 -B$8) -> 0 | C26: =C$9 * (3.750288963317871 -C$8) -> 0 | D26: =D$9 * (3.750288963317871 -D$8) -> 0 | F26: =F$9 * (0.0008398304926231503 -F$8) -> 0 | G26: =G$9 * (-1.263849020004272 -G$8) -> 0 | H26: =H$9 * (3.711467981338501 -H$8) -> 0 | I26: =I$9 * (4.297000089081848E-7 -I$8) -> 0
A27: =A$9 * (4.000313758850098 -A$8) -> 0 | B27: =B$9 * (4.000313758850098 -B$8) -> 0 | C27: =C$9 * (4.000313758850098 -C$8) -> 0 | D27: =D$9 * (4.000313758850098 -D$8) -> 0 | F27: =F$9 * (-0.001906004035845399 -F$8) -> 0 | G27: =G$9 * (-2.087815046310425 -G$8) -> 0 | H27: =H$9 * (2.845895051956177 -H$8) -> 0 | I27: =I$9 * (6.520419992739335E-5 -I$8) -> 0
A28: =A$9 * (4.250041484832764 -A$8) -> 0 | B28: =B$9 * (4.250041484832764 -B$8) -> 0 | C28: =C$9 * (4.250041484832764 -C$8) -> 0 | D28: =D$9 * (4.250041484832764 -D$8) -> 0 | F28: =F$9 * (-0.001272641005925834 -F$8) -> 0 | G28: =G$9 * (-1.399719953536987 -G$8) -> 0 | H28: =H$9 * (0.1025459989905357 -H$8) -> 0 | I28: =I$9 * (1.76699998633012E-7 -I$8) -> 0
A29: =A$9 * (4.50066089630127 -A$8) -> 0 | B29: =B$9 * (4.50066089630127 -B$8) -> 0 | C29: =C$9 * (4.50066089630127 -C$8) -> 0 | D29: =D$9 * (4.50066089630127 -D$8) -> 0 | F29: =F$9 * (0.007637470960617065 -F$8) -> 0 | G29: =G$9 * (0.241156205534935 -G$8) -> 0 | H29: =H$9 * (4.869906902313232 -H$8) -> 0 | I29: =I$9 * (1.844099983827618E-6 -I$8) -> 0
A30: =A$9 * (4.750247001647949 -A$8) -> 0 | B30: =B$9 * (4.750247001647949 -B$8) -> 0 | C30: =C$9 * (4.750247001647949 -C$8) -> 0 | D30: =D$9 * (4.750247001647949 -D$8) -> 0 | F30: =F$9 * (0.01535611040890217 -F$8) -> 0 | G30: =G$9 * (2.772372961044312 -G$8) -> 0 | H30: =H$9 * (4.107535839080811 -H$8) -> 0 | I30: =I$9 * (8.513999887327373E-7 -I$8) -> 0
A31: =A$9 * (5.000277996063232 -A$8) -> 0 | B31: =B$9 * (5.000277996063232 -B$8) -> 0 | C31: =C$9 * (5.000277996063232 -C$8) -> 0 | D31: =D$9 * (5.000277996063232 -D$8) -> 0 | F31: =F$9 * (-0.0003207437985111028 -F$8) -> 0 | G31: =G$9 * (-0.9150152206420898 -G$8) -> 0 | H31: =H$9 * (0.7113612294197083 -H$8) -> 0 | I31: =I$9 * (1.149999988570016E-7 -I$8) -> 0
A32: =A$9 * (5.250236034393311 -A$8) -> 0 | B32: =B$9 * (5.250236034393311 -B$8) -> 0 | C32: =C$9 * (5.250236034393311 -C$8) -> 0 | D32: =D$9 * (5.250236034393311 -D$8) -> 0 | F32: =F$9 * (-0.0003606494865380228 -F$8) -> 0 | G32: =G$9 * (-0.5302770733833313 -G$8) -> 0 | H32: =H$9 * (0.2800131142139435 -H$8) -> 0 | I32: =I$9 * (8.469999812632523E-8 -I$8) -> 0
A33: =A$9 * (5.500516891479492 -A$8) -> 0 | B33: =B$9 * (5.500516891479492 -B$8) -> 0 | C33: =C$9 * (5.500516891479492 -C$8) -> 0 | D33: =D$9 * (5.500516891479492 -D$8) -> 0 | F33: =F$9 * (-0.0003102883056271821 -F$8) -> 0 | G33: =G$9 * (-0.4376001060009003 -G$8) -> 0 | H33: =H$9 * (0.09468682110309601 -H$8) -> 0 | I33: =I$9 * (2.280000011012362E-8 -I$8) -> 0
A34: =A$9 * (5.750086307525635 -A$8) -> 0 | B34: =B$9 * (5.750086307525635 -B$8) -> 0 | C34: =C$9 * (5.750086307525635 -C$8) -> 0 | D34: =D$9 * (5.750086307525635 -D$8) -> 0 | F34: =F$9 * (-0.0004048458940815181 -F$8) -> 0 | G34: =G$9 * (-2.798572063446045 -G$8) -> 0 | H34: =H$9 * (0.3517780900001526 -H$8) -> 0 | I34: =I$9 * (2.105000049823502E-7 -I$8) -> 0
A35: =A$9 * (6.000389099121094 -A$8) -> 0 | B35: =B$9 * (6.000389099121094 -B$8) -> 0 | C35: =C$9 * (6.000389099121094 -C$8) -> 0 | D35: =D$9 * (6.000389099121094 -D$8) -> 0 | F35: =F$9 * (0.1491090059280396 -F$8) -> 0 | G35: =G$9 * (11.21032047271729 -G$8) -> 0 | H35: =H$9 * (11.59012031555176 -H$8) -> 0 | I35: =I$9 * (0.3122856914997101 -I$8) -> 0
A36: =A$9 * (6.250469207763672 -A$8) -> 0 | B36: =B$9 * (6.250469207763672 -B$8) -> 0 | C36: =C$9 * (6.250469207763672 -C$8) -> 0 | D36: =D$9 * (6.250469207763672 -D$8) -> 0 | F36: =F$9 * (0.02490348927676678 -F$8) -> 0 | G36: =G$9 * (2.896580934524536 -G$8) -> 0 | H36: =H$9 * (3.321458101272583 -H$8) -> 0 | I36: =I$9 * (1.331099952039949E-6 -I$8) -> 0
