Workbook

Sheet Legends
A1: VARIABLE | B1: LEGEND
A2: TREND___QLT___(M3_S)___RISER_OUTLET | B2: VAR1
A3: TREND___UL___(M_S)___RISER_OUTLET | B3: VAR2
A4: TREND___UG___(M_S)___RISER_OUTLET | B4: VAR3

Sheet SIM1
A1: h | B1: h | C1: h | E1: (M3/S) | F1: (M/S) | G1: (M/S)
A2: TIME1 | B2: TIME2 | C2: TIME3 | E2: ='Legends'!B2 -> 0 | F2: ='Legends'!B3 -> 0 | G2: ='Legends'!B4 -> 0 | I2: Report-2031_Oil_4500bopd_Liquid_4773blpd_10MMSCFD_GL_TD_Only_OP2.genkey
A3: =MIN($A$11:$A$299) -> 0 | B3: =MIN($B$11:$B$299) -> 0 | C3: =MIN($C$11:$C$299) -> 0 | D3: Min | E3: =MIN($E$11:$E$299) -> 0 | F3: =MIN($F$11:$F$299) -> 0 | G3: =MIN($G$11:$G$299) -> 0
A4: =MEDIAN($A$11:$A$299) -> 0 | B4: =MEDIAN($B$11:$B$299) -> 0 | C4: =MEDIAN($C$11:$C$299) -> 0 | D4: P50 | E4: =MEDIAN($E$11:$E$299) -> 0 | F4: =MEDIAN($F$11:$F$299) -> 0 | G4: =MEDIAN($G$11:$G$299) -> 0
A5: =MAX($A$11:$A$299) -> 0 | B5: =MAX($B$11:$B$299) -> 0 | C5: =MAX($C$11:$C$299) -> 0 | D5: Max | E5: =MAX($E$11:$E$299) -> 0 | F5: =MAX($F$11:$F$299) -> 0 | G5: =MAX($G$11:$G$299) -> 0
A6: =$A5-$A3 -> 0 | B6: =$B5-$B3 -> 0 | C6: =$C5-$C3 -> 0 | D6: Delta | E6: =$E5-$E3 -> 0 | F6: =$F5-$F3 -> 0 | G6: =$G5-$G3 -> 0
A7: h | B7: h | C7: h | E7: (M3/S) | F7: (M/S) | G7: (M/S)
A8: 0 | B8: 0 | C8: 0 | D8: Offset | E8: 0 | F8: 0 | G8: 0
A9: 1 | B9: 1 | C9: 1 | D9: Scale | E9: 1 | F9: 1 | G9: 1
A10: TIME1 | B10: TIME2 | C10: TIME3 | E10: ='Legends'!B2 -> 0 | F10: ='Legends'!B3 -> 0 | G10: ='Legends'!B4 -> 0
A11: =A$9 * (0 -A$8) -> 0 | B11: =B$9 * (0 -B$8) -> 0 | C11: =C$9 * (0 -C$8) -> 0 | E11: =E$9 * (0.01899014040827751 -E$8) -> 0 | F11: =F$9 * (6.976023197174072 -F$8) -> 0 | G11: =G$9 * (9.87746524810791 -G$8) -> 0
A12: =A$9 * (0.2504511773586273 -A$8) -> 0 | B12: =B$9 * (0.2504511773586273 -B$8) -> 0 | C12: =C$9 * (0.2504511773586273 -C$8) -> 0 | E12: =E$9 * (0.01235297974199057 -E$8) -> 0 | F12: =F$9 * (7.181337833404541 -F$8) -> 0 | G12: =G$9 * (13.02390003204346 -G$8) -> 0
A13: =A$9 * (0.5003725290298462 -A$8) -> 0 | B13: =B$9 * (0.5003725290298462 -B$8) -> 0 | C13: =C$9 * (0.5003725290298462 -C$8) -> 0 | E13: =E$9 * (0.008767951279878616 -E$8) -> 0 | F13: =F$9 * (5.209248065948486 -F$8) -> 0 | G13: =G$9 * (11.39206981658936 -G$8) -> 0
A14: =A$9 * (0.7502644658088684 -A$8) -> 0 | B14: =B$9 * (0.7502644658088684 -B$8) -> 0 | C14: =C$9 * (0.7502644658088684 -C$8) -> 0 | E14: =E$9 * (0.01135827973484993 -E$8) -> 0 | F14: =F$9 * (5.983951091766357 -F$8) -> 0 | G14: =G$9 * (11.16973972320557 -G$8) -> 0
A15: =A$9 * (1.000229716300964 -A$8) -> 0 | B15: =B$9 * (1.000229716300964 -B$8) -> 0 | C15: =C$9 * (1.000229716300964 -C$8) -> 0 | E15: =E$9 * (0.009398536756634712 -E$8) -> 0 | F15: =F$9 * (5.278471946716309 -F$8) -> 0 | G15: =G$9 * (11.01521968841553 -G$8) -> 0
A16: =A$9 * (1.250013113021851 -A$8) -> 0 | B16: =B$9 * (1.250013113021851 -B$8) -> 0 | C16: =C$9 * (1.250013113021851 -C$8) -> 0 | E16: =E$9 * (0.01062831003218889 -E$8) -> 0 | F16: =F$9 * (5.146395206451416 -F$8) -> 0 | G16: =G$9 * (9.851216316223145 -G$8) -> 0
A17: =A$9 * (1.500121116638184 -A$8) -> 0 | B17: =B$9 * (1.500121116638184 -B$8) -> 0 | C17: =C$9 * (1.500121116638184 -C$8) -> 0 | E17: =E$9 * (0.00895081739872694 -E$8) -> 0 | F17: =F$9 * (5.006810188293457 -F$8) -> 0 | G17: =G$9 * (10.74590015411377 -G$8) -> 0
A18: =A$9 * (1.750328660011292 -A$8) -> 0 | B18: =B$9 * (1.750328660011292 -B$8) -> 0 | C18: =C$9 * (1.750328660011292 -C$8) -> 0 | E18: =E$9 * (0.008839445188641548 -E$8) -> 0 | F18: =F$9 * (4.737603187561035 -F$8) -> 0 | G18: =G$9 * (10.18994998931885 -G$8) -> 0
A19: =A$9 * (2.000328540802002 -A$8) -> 0 | B19: =B$9 * (2.000328540802002 -B$8) -> 0 | C19: =C$9 * (2.000328540802002 -C$8) -> 0 | E19: =E$9 * (0.01007585041224957 -E$8) -> 0 | F19: =F$9 * (5.198352813720703 -F$8) -> 0 | G19: =G$9 * (10.32841014862061 -G$8) -> 0
A20: =A$9 * (2.2502760887146 -A$8) -> 0 | B20: =B$9 * (2.2502760887146 -B$8) -> 0 | C20: =C$9 * (2.2502760887146 -C$8) -> 0 | E20: =E$9 * (0.008484907448291779 -E$8) -> 0 | F20: =F$9 * (4.683227062225342 -F$8) -> 0 | G20: =G$9 * (10.36596012115479 -G$8) -> 0
A21: =A$9 * (2.500304222106934 -A$8) -> 0 | B21: =B$9 * (2.500304222106934 -B$8) -> 0 | C21: =C$9 * (2.500304222106934 -C$8) -> 0 | E21: =E$9 * (0.01016569044440985 -E$8) -> 0 | F21: =F$9 * (5.070384979248047 -F$8) -> 0 | G21: =G$9 * (9.994375228881836 -G$8) -> 0
A22: =A$9 * (2.750331878662109 -A$8) -> 0 | B22: =B$9 * (2.750331878662109 -B$8) -> 0 | C22: =C$9 * (2.750331878662109 -C$8) -> 0 | E22: =E$9 * (0.009207810275256634 -E$8) -> 0 | F22: =F$9 * (4.888185024261475 -F$8) -> 0 | G22: =G$9 * (10.27120971679688 -G$8) -> 0
A23: =A$9 * (3.000361204147339 -A$8) -> 0 | B23: =B$9 * (3.000361204147339 -B$8) -> 0 | C23: =C$9 * (3.000361204147339 -C$8) -> 0 | E23: =E$9 * (0.009293840266764164 -E$8) -> 0 | F23: =F$9 * (4.81830883026123 -F$8) -> 0 | G23: =G$9 * (10.04555988311768 -G$8) -> 0
A24: =A$9 * (3.250388860702515 -A$8) -> 0 | B24: =B$9 * (3.250388860702515 -B$8) -> 0 | C24: =C$9 * (3.250388860702515 -C$8) -> 0 | E24: =E$9 * (0.009793265722692013 -E$8) -> 0 | F24: =F$9 * (5.030058860778809 -F$8) -> 0 | G24: =G$9 * (10.16969013214111 -G$8) -> 0
A25: =A$9 * (3.500027894973755 -A$8) -> 0 | B25: =B$9 * (3.500027894973755 -B$8) -> 0 | C25: =C$9 * (3.500027894973755 -C$8) -> 0 | E25: =E$9 * (0.009593348950147629 -E$8) -> 0 | F25: =F$9 * (4.945787906646729 -F$8) -> 0 | G25: =G$9 * (10.12565040588379 -G$8) -> 0
A26: =A$9 * (3.750055551528931 -A$8) -> 0 | B26: =B$9 * (3.750055551528931 -B$8) -> 0 | C26: =C$9 * (3.750055551528931 -C$8) -> 0 | E26: =E$9 * (0.009927818551659584 -E$8) -> 0 | F26: =F$9 * (4.995786190032959 -F$8) -> 0 | G26: =G$9 * (10.00938034057617 -G$8) -> 0
A27: =A$9 * (4.000083446502686 -A$8) -> 0 | B27: =B$9 * (4.000083446502686 -B$8) -> 0 | C27: =C$9 * (4.000083446502686 -C$8) -> 0 | E27: =E$9 * (0.009745977818965912 -E$8) -> 0 | F27: =F$9 * (4.987526893615723 -F$8) -> 0 | G27: =G$9 * (10.13465976715088 -G$8) -> 0
A28: =A$9 * (4.250111103057861 -A$8) -> 0 | B28: =B$9 * (4.250111103057861 -B$8) -> 0 | C28: =C$9 * (4.250111103057861 -C$8) -> 0 | E28: =E$9 * (0.009619700722396374 -E$8) -> 0 | F28: =F$9 * (4.898069858551025 -F$8) -> 0 | G28: =G$9 * (10.03995990753174 -G$8) -> 0
A29: =A$9 * (4.500138759613037 -A$8) -> 0 | B29: =B$9 * (4.500138759613037 -B$8) -> 0 | C29: =C$9 * (4.500138759613037 -C$8) -> 0 | E29: =E$9 * (0.009813901968300343 -E$8) -> 0 | F29: =F$9 * (4.945738792419434 -F$8) -> 0 | G29: =G$9 * (10.01618957519531 -G$8) -> 0
A30: =A$9 * (4.750166893005371 -A$8) -> 0 | B30: =B$9 * (4.750166893005371 -B$8) -> 0 | C30: =C$9 * (4.750166893005371 -C$8) -> 0 | E30: =E$9 * (0.009633160196244717 -E$8) -> 0 | F30: =F$9 * (4.908864974975586 -F$8) -> 0 | G30: =G$9 * (10.06272029876709 -G$8) -> 0
A31: =A$9 * (5.000194549560547 -A$8) -> 0 | B31: =B$9 * (5.000194549560547 -B$8) -> 0 | C31: =C$9 * (5.000194549560547 -C$8) -> 0 | E31: =E$9 * (0.009712209925055504 -E$8) -> 0 | F31: =F$9 * (4.896020889282227 -F$8) -> 0 | G31: =G$9 * (9.980698585510254 -G$8) -> 0
A32: =A$9 * (5.250222206115723 -A$8) -> 0 | B32: =B$9 * (5.250222206115723 -B$8) -> 0 | C32: =C$9 * (5.250222206115723 -C$8) -> 0 | E32: =E$9 * (0.009768794290721416 -E$8) -> 0 | F32: =F$9 * (4.924986839294434 -F$8) -> 0 | G32: =G$9 * (10.0071496963501 -G$8) -> 0
A33: =A$9 * (5.500249862670898 -A$8) -> 0 | B33: =B$9 * (5.500249862670898 -B$8) -> 0 | C33: =C$9 * (5.500249862670898 -C$8) -> 0 | E33: =E$9 * (0.009662165306508541 -E$8) -> 0 | F33: =F$9 * (4.885807037353516 -F$8) -> 0 | G33: =G$9 * (9.995956420898438 -G$8) -> 0
A34: =A$9 * (5.750277996063232 -A$8) -> 0 | B34: =B$9 * (5.750277996063232 -B$8) -> 0 | C34: =C$9 * (5.750277996063232 -C$8) -> 0 | E34: =E$9 * (0.009771605953574181 -E$8) -> 0 | F34: =F$9 * (4.89839506149292 -F$8) -> 0 | G34: =G$9 * (9.949575424194336 -G$8) -> 0
A35: =A$9 * (6.000305652618408 -A$8) -> 0 | B35: =B$9 * (6.000305652618408 -B$8) -> 0 | C35: =C$9 * (6.000305652618408 -C$8) -> 0 | E35: =E$9 * (0.009737667627632618 -E$8) -> 0 | F35: =F$9 * (4.898931980133057 -F$8) -> 0 | G35: =G$9 * (9.97559642791748 -G$8) -> 0
A36: =A$9 * (6.250333309173584 -A$8) -> 0 | B36: =B$9 * (6.250333309173584 -B$8) -> 0 | C36: =C$9 * (6.250333309173584 -C$8) -> 0 | E36: =E$9 * (0.009715227410197258 -E$8) -> 0 | F36: =F$9 * (4.875664234161377 -F$8) -> 0 | G36: =G$9 * (9.941168785095215 -G$8) -> 0
A37: =A$9 * (6.50036096572876 -A$8) -> 0 | B37: =B$9 * (6.50036096572876 -B$8) -> 0 | C37: =C$9 * (6.50036096572876 -C$8) -> 0 | E37: =E$9 * (0.00978646706789732 -E$8) -> 0 | F37: =F$9 * (4.891172885894775 -F$8) -> 0 | G37: =G$9 * (9.92794132232666 -G$8) -> 0
A38: =A$9 * (6.75 -A$8) -> 0 | B38: =B$9 * (6.75 -B$8) -> 0 | C38: =C$9 * (6.75 -C$8) -> 0 | E38: =E$9 * (0.009734553284943104 -E$8) -> 0 | F38: =F$9 * (4.877693176269531 -F$8) -> 0 | G38: =G$9 * (9.935090065002441 -G$8) -> 0
A39: =A$9 * (7.000027656555176 -A$8) -> 0 | B39: =B$9 * (7.000027656555176 -B$8) -> 0 | C39: =C$9 * (7.000027656555176 -C$8) -> 0 | E39: =E$9 * (0.009760910645127296 -E$8) -> 0 | F39: =F$9 * (4.870511054992676 -F$8) -> 0 | G39: =G$9 * (9.902462959289551 -G$8) -> 0
A40: =A$9 * (7.25005578994751 -A$8) -> 0 | B40: =B$9 * (7.25005578994751 -B$8) -> 0 | C40: =C$9 * (7.25005578994751 -C$8) -> 0 | E40: =E$9 * (0.009783023037016392 -E$8) -> 0 | F40: =F$9 * (4.877882957458496 -F$8) -> 0 | G40: =G$9 * (9.904850959777832 -G$8) -> 0
...

Sheet SIM2
A1: h | B1: h | C1: h | E1: (M3/S) | F1: (M/S) | G1: (M/S)
A2: TIME1 | B2: TIME2 | C2: TIME3 | E2: ='Legends'!B2 -> 0 | F2: ='Legends'!B3 -> 0 | G2: ='Legends'!B4 -> 0 | I2: Report-2031_Oil_4500bopd_Liquid_4773blpd_5MMSCFD_GL_TD_Only_OP2.genkey
A3: =MIN($A$11:$A$299) -> 0 | B3: =MIN($B$11:$B$299) -> 0 | C3: =MIN($C$11:$C$299) -> 0 | D3: Min | E3: =MIN($E$11:$E$299) -> 0 | F3: =MIN($F$11:$F$299) -> 0 | G3: =MIN($G$11:$G$299) -> 0
A4: =MEDIAN($A$11:$A$299) -> 0 | B4: =MEDIAN($B$11:$B$299) -> 0 | C4: =MEDIAN($C$11:$C$299) -> 0 | D4: P50 | E4: =MEDIAN($E$11:$E$299) -> 0 | F4: =MEDIAN($F$11:$F$299) -> 0 | G4: =MEDIAN($G$11:$G$299) -> 0
A5: =MAX($A$11:$A$299) -> 0 | B5: =MAX($B$11:$B$299) -> 0 | C5: =MAX($C$11:$C$299) -> 0 | D5: Max | E5: =MAX($E$11:$E$299) -> 0 | F5: =MAX($F$11:$F$299) -> 0 | G5: =MAX($G$11:$G$299) -> 0
A6: =$A5-$A3 -> 0 | B6: =$B5-$B3 -> 0 | C6: =$C5-$C3 -> 0 | D6: Delta | E6: =$E5-$E3 -> 0 | F6: =$F5-$F3 -> 0 | G6: =$G5-$G3 -> 0
A7: h | B7: h | C7: h | E7: (M3/S) | F7: (M/S) | G7: (M/S)
A8: 0 | B8: 0 | C8: 0 | D8: Offset | E8: 0 | F8: 0 | G8: 0
A9: 1 | B9: 1 | C9: 1 | D9: Scale | E9: 1 | F9: 1 | G9: 1
A10: TIME1 | B10: TIME2 | C10: TIME3 | E10: ='Legends'!B2 -> 0 | F10: ='Legends'!B3 -> 0 | G10: ='Legends'!B4 -> 0
A11: =A$9 * (0 -A$8) -> 0 | B11: =B$9 * (0 -B$8) -> 0 | C11: =C$9 * (0 -C$8) -> 0 | E11: =E$9 * (0.01899014040827751 -E$8) -> 0 | F11: =F$9 * (6.976023197174072 -F$8) -> 0 | G11: =G$9 * (9.87746524810791 -G$8) -> 0
A12: =A$9 * (0.2502377033233643 -A$8) -> 0 | B12: =B$9 * (0.2502377033233643 -B$8) -> 0 | C12: =C$9 * (0.2502377033233643 -C$8) -> 0 | E12: =E$9 * (0.01325710956007242 -E$8) -> 0 | F12: =F$9 * (6.133063793182373 -F$8) -> 0 | G12: =G$9 * (10.41926002502441 -G$8) -> 0
A13: =A$9 * (0.5001344680786133 -A$8) -> 0 | B13: =B$9 * (0.5001344680786133 -B$8) -> 0 | C13: =C$9 * (0.5001344680786133 -C$8) -> 0 | E13: =E$9 * (0.009549681097269058 -E$8) -> 0 | F13: =F$9 * (4.365466117858887 -F$8) -> 0 | G13: =G$9 * (8.80455207824707 -G$8) -> 0
A14: =A$9 * (0.7502166628837585 -A$8) -> 0 | B14: =B$9 * (0.7502166628837585 -B$8) -> 0 | C14: =C$9 * (0.7502166628837585 -C$8) -> 0 | E14: =E$9 * (0.01315690018236637 -E$8) -> 0 | F14: =F$9 * (5.038919925689697 -F$8) -> 0 | G14: =G$9 * (8.427870750427246 -G$8) -> 0
A15: =A$9 * (1.000296950340271 -A$8) -> 0 | B15: =B$9 * (1.000296950340271 -B$8) -> 0 | C15: =C$9 * (1.000296950340271 -C$8) -> 0 | E15: =E$9 * (0.009365567937493324 -E$8) -> 0 | F15: =F$9 * (4.040027141571045 -F$8) -> 0 | G15: =G$9 * (8.207898139953613 -G$8) -> 0
A16: =A$9 * (1.250070571899414 -A$8) -> 0 | B16: =B$9 * (1.250070571899414 -B$8) -> 0 | C16: =C$9 * (1.250070571899414 -C$8) -> 0 | E16: =E$9 * (0.008319569751620293 -E$8) -> 0 | F16: =F$9 * (3.141571044921875 -F$8) -> 0 | G16: =G$9 * (6.773316860198975 -G$8) -> 0
A17: =A$9 * (1.500028848648071 -A$8) -> 0 | B17: =B$9 * (1.500028848648071 -B$8) -> 0 | C17: =C$9 * (1.500028848648071 -C$8) -> 0 | E17: =E$9 * (0.009252616204321384 -E$8) -> 0 | F17: =F$9 * (4.243772983551025 -F$8) -> 0 | G17: =G$9 * (8.722887992858887 -G$8) -> 0
A18: =A$9 * (1.750007748603821 -A$8) -> 0 | B18: =B$9 * (1.750007748603821 -B$8) -> 0 | C18: =C$9 * (1.750007748603821 -C$8) -> 0 | E18: =E$9 * (0.008697706274688244 -E$8) -> 0 | F18: =F$9 * (3.681416034698486 -F$8) -> 0 | G18: =G$9 * (7.795071125030518 -G$8) -> 0
A19: =A$9 * (2.00033164024353 -A$8) -> 0 | B19: =B$9 * (2.00033164024353 -B$8) -> 0 | C19: =C$9 * (2.00033164024353 -C$8) -> 0 | E19: =E$9 * (0.01156174018979073 -E$8) -> 0 | F19: =F$9 * (3.947942018508911 -F$8) -> 0 | G19: =G$9 * (6.994433879852295 -G$8) -> 0
A20: =A$9 * (2.250254154205322 -A$8) -> 0 | B20: =B$9 * (2.250254154205322 -B$8) -> 0 | C20: =C$9 * (2.250254154205322 -C$8) -> 0 | E20: =E$9 * (0.008207106031477451 -E$8) -> 0 | F20: =F$9 * (3.780515909194946 -F$8) -> 0 | G20: =G$9 * (8.353146553039551 -G$8) -> 0
A21: =A$9 * (2.500176668167114 -A$8) -> 0 | B21: =B$9 * (2.500176668167114 -B$8) -> 0 | C21: =C$9 * (2.500176668167114 -C$8) -> 0 | E21: =E$9 * (0.008492790162563324 -E$8) -> 0 | F21: =F$9 * (3.242907047271729 -F$8) -> 0 | G21: =G$9 * (6.910186767578125 -G$8) -> 0
A22: =A$9 * (2.750099182128906 -A$8) -> 0 | B22: =B$9 * (2.750099182128906 -B$8) -> 0 | C22: =C$9 * (2.750099182128906 -C$8) -> 0 | E22: =E$9 * (0.01046258956193924 -E$8) -> 0 | F22: =F$9 * (4.545087814331055 -F$8) -> 0 | G22: =G$9 * (8.672121047973633 -G$8) -> 0
A23: =A$9 * (3.000022172927856 -A$8) -> 0 | B23: =B$9 * (3.000022172927856 -B$8) -> 0 | C23: =C$9 * (3.000022172927856 -C$8) -> 0 | E23: =E$9 * (0.008392437361180782 -E$8) -> 0 | F23: =F$9 * (3.621102094650269 -F$8) -> 0 | G23: =G$9 * (7.860945224761963 -G$8) -> 0
A24: =A$9 * (3.250344514846802 -A$8) -> 0 | B24: =B$9 * (3.250344514846802 -B$8) -> 0 | C24: =C$9 * (3.250344514846802 -C$8) -> 0 | E24: =E$9 * (0.01151208020746708 -E$8) -> 0 | F24: =F$9 * (3.504371881484985 -F$8) -> 0 | G24: =G$9 * (6.193033218383789 -G$8) -> 0
A25: =A$9 * (3.500269412994385 -A$8) -> 0 | B25: =B$9 * (3.500269412994385 -B$8) -> 0 | C25: =C$9 * (3.500269412994385 -C$8) -> 0 | E25: =E$9 * (0.008474365808069706 -E$8) -> 0 | F25: =F$9 * (3.883497953414917 -F$8) -> 0 | G25: =G$9 * (8.45409107208252 -G$8) -> 0
A26: =A$9 * (3.750191688537598 -A$8) -> 0 | B26: =B$9 * (3.750191688537598 -B$8) -> 0 | C26: =C$9 * (3.750191688537598 -C$8) -> 0 | E26: =E$9 * (0.007510873954743147 -E$8) -> 0 | F26: =F$9 * (2.901604890823364 -F$8) -> 0 | G26: =G$9 * (6.720756053924561 -G$8) -> 0
A27: =A$9 * (4.000113964080811 -A$8) -> 0 | B27: =B$9 * (4.000113964080811 -B$8) -> 0 | C27: =C$9 * (4.000113964080811 -C$8) -> 0 | E27: =E$9 * (0.01170090958476067 -E$8) -> 0 | F27: =F$9 * (5.222056865692139 -F$8) -> 0 | G27: =G$9 * (9.449234008789062 -G$8) -> 0
A28: =A$9 * (4.250036239624023 -A$8) -> 0 | B28: =B$9 * (4.250036239624023 -B$8) -> 0 | C28: =C$9 * (4.250036239624023 -C$8) -> 0 | E28: =E$9 * (0.008261324837803841 -E$8) -> 0 | F28: =F$9 * (3.666079998016357 -F$8) -> 0 | G28: =G$9 * (8.094941139221191 -G$8) -> 0
A29: =A$9 * (4.500358104705811 -A$8) -> 0 | B29: =B$9 * (4.500358104705811 -B$8) -> 0 | C29: =C$9 * (4.500358104705811 -C$8) -> 0 | E29: =E$9 * (0.009489740245044231 -E$8) -> 0 | F29: =F$9 * (2.195451021194458 -F$8) -> 0 | G29: =G$9 * (4.283183097839355 -G$8) -> 0
A30: =A$9 * (4.750305652618408 -A$8) -> 0 | B30: =B$9 * (4.750305652618408 -B$8) -> 0 | C30: =C$9 * (4.750305652618408 -C$8) -> 0 | E30: =E$9 * (0.007197902072221041 -E$8) -> 0 | F30: =F$9 * (3.686717987060547 -F$8) -> 0 | G30: =G$9 * (9.038081169128418 -G$8) -> 0
A31: =A$9 * (5.00006103515625 -A$8) -> 0 | B31: =B$9 * (5.00006103515625 -B$8) -> 0 | C31: =C$9 * (5.00006103515625 -C$8) -> 0 | E31: =E$9 * (0.00537472777068615 -E$8) -> 0 | F31: =F$9 * (1.766379952430725 -F$8) -> 0 | G31: =G$9 * (5.10724401473999 -G$8) -> 0
A32: =A$9 * (5.250485897064209 -A$8) -> 0 | B32: =B$9 * (5.250485897064209 -B$8) -> 0 | C32: =C$9 * (5.250485897064209 -C$8) -> 0 | E32: =E$9 * (-0.002428255975246429 -E$8) -> 0 | F32: =F$9 * (-2.114963054656982 -F$8) -> 0 | G32: =G$9 * (0.5123434066772461 -G$8) -> 0
A33: =A$9 * (5.500458240509033 -A$8) -> 0 | B33: =B$9 * (5.500458240509033 -B$8) -> 0 | C33: =C$9 * (5.500458240509033 -C$8) -> 0 | E33: =E$9 * (0.002065117936581373 -E$8) -> 0 | F33: =F$9 * (-0.3621223866939545 -F$8) -> 0 | G33: =G$9 * (2.059521913528442 -G$8) -> 0
A34: =A$9 * (5.750716686248779 -A$8) -> 0 | B34: =B$9 * (5.750716686248779 -B$8) -> 0 | C34: =C$9 * (5.750716686248779 -C$8) -> 0 | E34: =E$9 * (0.002236966043710709 -E$8) -> 0 | F34: =F$9 * (-2.568073034286499 -F$8) -> 0 | G34: =G$9 * (1.244606018066406 -G$8) -> 0
A35: =A$9 * (6.000564098358154 -A$8) -> 0 | B35: =B$9 * (6.000564098358154 -B$8) -> 0 | C35: =C$9 * (6.000564098358154 -C$8) -> 0 | E35: =E$9 * (0.003278614021837711 -E$8) -> 0 | F35: =F$9 * (-0.08032719045877457 -F$8) -> 0 | G35: =G$9 * (7.30388879776001 -G$8) -> 0
A36: =A$9 * (6.250602722167969 -A$8) -> 0 | B36: =B$9 * (6.250602722167969 -B$8) -> 0 | C36: =C$9 * (6.250602722167969 -C$8) -> 0 | E36: =E$9 * (0.02540455013513565 -E$8) -> 0 | F36: =F$9 * (2.690529108047485 -F$8) -> 0 | G36: =G$9 * (3.070297002792358 -G$8) -> 0
A37: =A$9 * (6.500152587890625 -A$8) -> 0 | B37: =B$9 * (6.500152587890625 -B$8) -> 0 | C37: =C$9 * (6.500152587890625 -C$8) -> 0 | E37: =E$9 * (0.01043733954429626 -E$8) -> 0 | F37: =F$9 * (5.537818908691406 -F$8) -> 0 | G37: =G$9 * (10.95543003082275 -G$8) -> 0
A38: =A$9 * (6.750202655792236 -A$8) -> 0 | B38: =B$9 * (6.750202655792236 -B$8) -> 0 | C38: =C$9 * (6.750202655792236 -C$8) -> 0 | E38: =E$9 * (0.01910514943301678 -E$8) -> 0 | F38: =F$9 * (7.105545043945312 -F$8) -> 0 | G38: =G$9 * (10.11063957214355 -G$8) -> 0
A39: =A$9 * (7.000389099121094 -A$8) -> 0 | B39: =B$9 * (7.000389099121094 -B$8) -> 0 | C39: =C$9 * (7.000389099121094 -C$8) -> 0 | E39: =E$9 * (0.007040968164801598 -E$8) -> 0 | F39: =F$9 * (3.701052904129028 -F$8) -> 0 | G39: =G$9 * (9.260794639587402 -G$8) -> 0
A40: =A$9 * (7.25005578994751 -A$8) -> 0 | B40: =B$9 * (7.25005578994751 -B$8) -> 0 | C40: =C$9 * (7.25005578994751 -C$8) -> 0 | E40: =E$9 * (0.004246283788233995 -E$8) -> 0 | F40: =F$9 * (1.365893006324768 -F$8) -> 0 | G40: =G$9 * (4.740287780761719 -G$8) -> 0
...

Sheet SIM3
A1: h | B1: h | C1: h | E1: (M3/S) | F1: (M/S) | G1: (M/S)
A2: TIME1 | B2: TIME2 | C2: TIME3 | E2: ='Legends'!B2 -> 0 | F2: ='Legends'!B3 -> 0 | G2: ='Legends'!B4 -> 0 | I2: Report-2031_Oil_4500bopd_Liquid_4773blpd_No_GL_TD_Only_OP2.genkey
A3: =MIN($A$11:$A$299) -> 0 | B3: =MIN($B$11:$B$299) -> 0 | C3: =MIN($C$11:$C$299) -> 0 | D3: Min | E3: =MIN($E$11:$E$299) -> 0 | F3: =MIN($F$11:$F$299) -> 0 | G3: =MIN($G$11:$G$299) -> 0
A4: =MEDIAN($A$11:$A$299) -> 0 | B4: =MEDIAN($B$11:$B$299) -> 0 | C4: =MEDIAN($C$11:$C$299) -> 0 | D4: P50 | E4: =MEDIAN($E$11:$E$299) -> 0 | F4: =MEDIAN($F$11:$F$299) -> 0 | G4: =MEDIAN($G$11:$G$299) -> 0
A5: =MAX($A$11:$A$299) -> 0 | B5: =MAX($B$11:$B$299) -> 0 | C5: =MAX($C$11:$C$299) -> 0 | D5: Max | E5: =MAX($E$11:$E$299) -> 0 | F5: =MAX($F$11:$F$299) -> 0 | G5: =MAX($G$11:$G$299) -> 0
A6: =$A5-$A3 -> 0 | B6: =$B5-$B3 -> 0 | C6: =$C5-$C3 -> 0 | D6: Delta | E6: =$E5-$E3 -> 0 | F6: =$F5-$F3 -> 0 | G6: =$G5-$G3 -> 0
A7: h | B7: h | C7: h | E7: (M3/S) | F7: (M/S) | G7: (M/S)
A8: 0 | B8: 0 | C8: 0 | D8: Offset | E8: 0 | F8: 0 | G8: 0
A9: 1 | B9: 1 | C9: 1 | D9: Scale | E9: 1 | F9: 1 | G9: 1
A10: TIME1 | B10: TIME2 | C10: TIME3 | E10: ='Legends'!B2 -> 0 | F10: ='Legends'!B3 -> 0 | G10: ='Legends'!B4 -> 0
A11: =A$9 * (0 -A$8) -> 0 | B11: =B$9 * (0 -B$8) -> 0 | C11: =C$9 * (0 -C$8) -> 0 | E11: =E$9 * (0.01899014040827751 -E$8) -> 0 | F11: =F$9 * (6.976023197174072 -F$8) -> 0 | G11: =G$9 * (9.87746524810791 -G$8) -> 0
A12: =A$9 * (0.2500112354755402 -A$8) -> 0 | B12: =B$9 * (0.2500112354755402 -B$8) -> 0 | C12: =C$9 * (0.2500112354755402 -C$8) -> 0 | E12: =E$9 * (0.01325295027345419 -E$8) -> 0 | F12: =F$9 * (4.242303848266602 -F$8) -> 0 | G12: =G$9 * (6.967663764953613 -G$8) -> 0
A13: =A$9 * (0.5001211166381836 -A$8) -> 0 | B13: =B$9 * (0.5001211166381836 -B$8) -> 0 | C13: =C$9 * (0.5001211166381836 -C$8) -> 0 | E13: =E$9 * (0.009234599769115448 -E$8) -> 0 | F13: =F$9 * (2.912945032119751 -F$8) -> 0 | G13: =G$9 * (5.829698085784912 -G$8) -> 0
A14: =A$9 * (0.7500610947608948 -A$8) -> 0 | B14: =B$9 * (0.7500610947608948 -B$8) -> 0 | C14: =C$9 * (0.7500610947608948 -C$8) -> 0 | E14: =E$9 * (0.005029994994401932 -E$8) -> 0 | F14: =F$9 * (1.130789995193481 -F$8) -> 0 | G14: =G$9 * (3.361793041229248 -G$8) -> 0
A15: =A$9 * (1.000138640403748 -A$8) -> 0 | B15: =B$9 * (1.000138640403748 -B$8) -> 0 | C15: =C$9 * (1.000138640403748 -C$8) -> 0 | E15: =E$9 * (-0.001605786033906043 -E$8) -> 0 | F15: =F$9 * (-1.595832943916321 -F$8) -> 0 | G15: =G$9 * (0.28751140832901 -G$8) -> 0
A16: =A$9 * (1.25046443939209 -A$8) -> 0 | B16: =B$9 * (1.25046443939209 -B$8) -> 0 | C16: =C$9 * (1.25046443939209 -C$8) -> 0 | E16: =E$9 * (-0.0006059535080567002 -E$8) -> 0 | F16: =F$9 * (-0.6819136142730713 -F$8) -> 0 | G16: =G$9 * (0.2123174965381622 -G$8) -> 0
A17: =A$9 * (1.500494718551636 -A$8) -> 0 | B17: =B$9 * (1.500494718551636 -B$8) -> 0 | C17: =C$9 * (1.500494718551636 -C$8) -> 0 | E17: =E$9 * (-0.001401726040057838 -E$8) -> 0 | F17: =F$9 * (-1.419749021530151 -F$8) -> 0 | G17: =G$9 * (0.1466632932424545 -G$8) -> 0
A18: =A$9 * (1.750004172325134 -A$8) -> 0 | B18: =B$9 * (1.750004172325134 -B$8) -> 0 | C18: =C$9 * (1.750004172325134 -C$8) -> 0 | E18: =E$9 * (-0.0001914673048304394 -E$8) -> 0 | F18: =F$9 * (-0.7674710154533386 -F$8) -> 0 | G18: =G$9 * (0.6117944717407227 -G$8) -> 0
A19: =A$9 * (2.000420570373535 -A$8) -> 0 | B19: =B$9 * (2.000420570373535 -B$8) -> 0 | C19: =C$9 * (2.000420570373535 -C$8) -> 0 | E19: =E$9 * (-0.0008314211736433208 -E$8) -> 0 | F19: =F$9 * (-0.9107096195220947 -F$8) -> 0 | G19: =G$9 * (-0.1550046056509018 -G$8) -> 0
A20: =A$9 * (2.250224113464355 -A$8) -> 0 | B20: =B$9 * (2.250224113464355 -B$8) -> 0 | C20: =C$9 * (2.250224113464355 -C$8) -> 0 | E20: =E$9 * (0.0009498466970399022 -E$8) -> 0 | F20: =F$9 * (-0.8200296759605408 -F$8) -> 0 | G20: =G$9 * (0.3807440102100372 -G$8) -> 0
A21: =A$9 * (2.500369071960449 -A$8) -> 0 | B21: =B$9 * (2.500369071960449 -B$8) -> 0 | C21: =C$9 * (2.500369071960449 -C$8) -> 0 | E21: =E$9 * (0.03375799953937531 -E$8) -> 0 | F21: =F$9 * (11.16559982299805 -F$8) -> 0 | G21: =G$9 * (13.01156997680664 -G$8) -> 0
A22: =A$9 * (2.750024080276489 -A$8) -> 0 | B22: =B$9 * (2.750024080276489 -B$8) -> 0 | C22: =C$9 * (2.750024080276489 -C$8) -> 0 | E22: =E$9 * (0.03092280030250549 -E$8) -> 0 | F22: =F$9 * (12.60305023193359 -F$8) -> 0 | G22: =G$9 * (16.15007972717285 -G$8) -> 0
A23: =A$9 * (3.000208377838135 -A$8) -> 0 | B23: =B$9 * (3.000208377838135 -B$8) -> 0 | C23: =C$9 * (3.000208377838135 -C$8) -> 0 | E23: =E$9 * (0.007981591857969761 -E$8) -> 0 | F23: =F$9 * (4.464561939239502 -F$8) -> 0 | G23: =G$9 * (10.29673004150391 -G$8) -> 0
A24: =A$9 * (3.250113964080811 -A$8) -> 0 | B24: =B$9 * (3.250113964080811 -B$8) -> 0 | C24: =C$9 * (3.250113964080811 -C$8) -> 0 | E24: =E$9 * (-0.002657023025676608 -E$8) -> 0 | F24: =F$9 * (-0.6809154152870178 -F$8) -> 0 | G24: =G$9 * (1.283489942550659 -G$8) -> 0
A25: =A$9 * (3.500452756881714 -A$8) -> 0 | B25: =B$9 * (3.500452756881714 -B$8) -> 0 | C25: =C$9 * (3.500452756881714 -C$8) -> 0 | E25: =E$9 * (-0.003872086061164737 -E$8) -> 0 | F25: =F$9 * (-1.171179056167603 -F$8) -> 0 | G25: =G$9 * (-3.11378002166748 -G$8) -> 0
A26: =A$9 * (3.750383377075195 -A$8) -> 0 | B26: =B$9 * (3.750383377075195 -B$8) -> 0 | C26: =C$9 * (3.750383377075195 -C$8) -> 0 | E26: =E$9 * (-0.0005111981881782413 -E$8) -> 0 | F26: =F$9 * (-0.7079771161079407 -F$8) -> 0 | G26: =G$9 * (0.5570847988128662 -G$8) -> 0
A27: =A$9 * (4.000344276428223 -A$8) -> 0 | B27: =B$9 * (4.000344276428223 -B$8) -> 0 | C27: =C$9 * (4.000344276428223 -C$8) -> 0 | E27: =E$9 * (0.0002108947956003249 -E$8) -> 0 | F27: =F$9 * (-1.096295952796936 -F$8) -> 0 | G27: =G$9 * (2.51476001739502 -G$8) -> 0
A28: =A$9 * (4.250494480133057 -A$8) -> 0 | B28: =B$9 * (4.250494480133057 -B$8) -> 0 | C28: =C$9 * (4.250494480133057 -C$8) -> 0 | E28: =E$9 * (-0.0009959570597857237 -E$8) -> 0 | F28: =F$9 * (-0.9517791271209717 -F$8) -> 0 | G28: =G$9 * (-0.2452594935894012 -G$8) -> 0
A29: =A$9 * (4.500461101531982 -A$8) -> 0 | B29: =B$9 * (4.500461101531982 -B$8) -> 0 | C29: =C$9 * (4.500461101531982 -C$8) -> 0 | E29: =E$9 * (-0.0002507099998183548 -E$8) -> 0 | F29: =F$9 * (-1.097759008407593 -F$8) -> 0 | G29: =G$9 * (0.398908406496048 -G$8) -> 0
A30: =A$9 * (4.750263690948486 -A$8) -> 0 | B30: =B$9 * (4.750263690948486 -B$8) -> 0 | C30: =C$9 * (4.750263690948486 -C$8) -> 0 | E30: =E$9 * (0.002192992949858308 -E$8) -> 0 | F30: =F$9 * (0.05927617847919464 -F$8) -> 0 | G30: =G$9 * (9.970287322998047 -G$8) -> 0
A31: =A$9 * (5.00053071975708 -A$8) -> 0 | B31: =B$9 * (5.00053071975708 -B$8) -> 0 | C31: =C$9 * (5.00053071975708 -C$8) -> 0 | E31: =E$9 * (0.03571724891662598 -E$8) -> 0 | F31: =F$9 * (13.40221977233887 -F$8) -> 0 | G31: =G$9 * (16.29467010498047 -G$8) -> 0
A32: =A$9 * (5.250083446502686 -A$8) -> 0 | B32: =B$9 * (5.250083446502686 -B$8) -> 0 | C32: =C$9 * (5.250083446502686 -C$8) -> 0 | E32: =E$9 * (0.009636894799768925 -E$8) -> 0 | F32: =F$9 * (4.985125064849854 -F$8) -> 0 | G32: =G$9 * (10.19309043884277 -G$8) -> 0
A33: =A$9 * (5.500141620635986 -A$8) -> 0 | B33: =B$9 * (5.500141620635986 -B$8) -> 0 | C33: =C$9 * (5.500141620635986 -C$8) -> 0 | E33: =E$9 * (-0.0001963086979230866 -E$8) -> 0 | F33: =F$9 * (-1.031733989715576 -F$8) -> 0 | G33: =G$9 * (1.143684029579163 -G$8) -> 0
A34: =A$9 * (5.750216484069824 -A$8) -> 0 | B34: =B$9 * (5.750216484069824 -B$8) -> 0 | C34: =C$9 * (5.750216484069824 -C$8) -> 0 | E34: =E$9 * (-0.002130030887201428 -E$8) -> 0 | F34: =F$9 * (-1.032536029815674 -F$8) -> 0 | G34: =G$9 * (-0.8067687749862671 -G$8) -> 0
A35: =A$9 * (6.000549793243408 -A$8) -> 0 | B35: =B$9 * (6.000549793243408 -B$8) -> 0 | C35: =C$9 * (6.000549793243408 -C$8) -> 0 | E35: =E$9 * (-0.004873230122029781 -E$8) -> 0 | F35: =F$9 * (-0.2461369931697845 -F$8) -> 0 | G35: =G$9 * (-3.361999034881592 -G$8) -> 0
A36: =A$9 * (6.250091552734375 -A$8) -> 0 | B36: =B$9 * (6.250091552734375 -B$8) -> 0 | C36: =C$9 * (6.250091552734375 -C$8) -> 0 | E36: =E$9 * (-0.00118114601355046 -E$8) -> 0 | F36: =F$9 * (-1.076241970062256 -F$8) -> 0 | G36: =G$9 * (-0.3041419088840485 -G$8) -> 0
A37: =A$9 * (6.500341892242432 -A$8) -> 0 | B37: =B$9 * (6.500341892242432 -B$8) -> 0 | C37: =C$9 * (6.500341892242432 -C$8) -> 0 | E37: =E$9 * (-0.000840449589304626 -E$8) -> 0 | F37: =F$9 * (-0.8284202814102173 -F$8) -> 0 | G37: =G$9 * (0.301072895526886 -G$8) -> 0
A38: =A$9 * (6.75011682510376 -A$8) -> 0 | B38: =B$9 * (6.75011682510376 -B$8) -> 0 | C38: =C$9 * (6.75011682510376 -C$8) -> 0 | E38: =E$9 * (-0.0008777469047345221 -E$8) -> 0 | F38: =F$9 * (-0.3064115941524506 -F$8) -> 0 | G38: =G$9 * (-0.2956759035587311 -G$8) -> 0
A39: =A$9 * (7.000205516815186 -A$8) -> 0 | B39: =B$9 * (7.000205516815186 -B$8) -> 0 | C39: =C$9 * (7.000205516815186 -C$8) -> 0 | E39: =E$9 * (0.1952133029699326 -E$8) -> 0 | F39: =F$9 * (13.67689037322998 -F$8) -> 0 | G39: =G$9 * (14.08092021942139 -G$8) -> 0
A40: =A$9 * (7.250244617462158 -A$8) -> 0 | B40: =B$9 * (7.250244617462158 -B$8) -> 0 | C40: =C$9 * (7.250244617462158 -C$8) -> 0 | E40: =E$9 * (0.04559443891048431 -E$8) -> 0 | F40: =F$9 * (6.837777137756348 -F$8) -> 0 | G40: =G$9 * (7.262814044952393 -G$8) -> 0
...

Sheet SIM4
A1: h | B1: h | C1: h | E1: (M3/S) | F1: (M/S) | G1: (M/S)
A2: TIME1 | B2: TIME2 | C2: TIME3 | E2: ='Legends'!B2 -> 0 | F2: ='Legends'!B3 -> 0 | G2: ='Legends'!B4 -> 0 | I2: Report-2031_Oil_4500bopd_Liquid_4773blpd_No_GL_TD_Only_OP2_TCV_10pc.genkey
A3: =MIN($A$11:$A$299) -> 0 | B3: =MIN($B$11:$B$299) -> 0 | C3: =MIN($C$11:$C$299) -> 0 | D3: Min | E3: =MIN($E$11:$E$299) -> 0 | F3: =MIN($F$11:$F$299) -> 0 | G3: =MIN($G$11:$G$299) -> 0
A4: =MEDIAN($A$11:$A$299) -> 0 | B4: =MEDIAN($B$11:$B$299) -> 0 | C4: =MEDIAN($C$11:$C$299) -> 0 | D4: P50 | E4: =MEDIAN($E$11:$E$299) -> 0 | F4: =MEDIAN($F$11:$F$299) -> 0 | G4: =MEDIAN($G$11:$G$299) -> 0
A5: =MAX($A$11:$A$299) -> 0 | B5: =MAX($B$11:$B$299) -> 0 | C5: =MAX($C$11:$C$299) -> 0 | D5: Max | E5: =MAX($E$11:$E$299) -> 0 | F5: =MAX($F$11:$F$299) -> 0 | G5: =MAX($G$11:$G$299) -> 0
A6: =$A5-$A3 -> 0 | B6: =$B5-$B3 -> 0 | C6: =$C5-$C3 -> 0 | D6: Delta | E6: =$E5-$E3 -> 0 | F6: =$F5-$F3 -> 0 | G6: =$G5-$G3 -> 0
A7: h | B7: h | C7: h | E7: (M3/S) | F7: (M/S) | G7: (M/S)
A8: 0 | B8: 0 | C8: 0 | D8: Offset | E8: 0 | F8: 0 | G8: 0
A9: 1 | B9: 1 | C9: 1 | D9: Scale | E9: 1 | F9: 1 | G9: 1
A10: TIME1 | B10: TIME2 | C10: TIME3 | E10: ='Legends'!B2 -> 0 | F10: ='Legends'!B3 -> 0 | G10: ='Legends'!B4 -> 0
A11: =A$9 * (0 -A$8) -> 0 | B11: =B$9 * (0 -B$8) -> 0 | C11: =C$9 * (0 -C$8) -> 0 | E11: =E$9 * (0.01899014040827751 -E$8) -> 0 | F11: =F$9 * (6.976023197174072 -F$8) -> 0 | G11: =G$9 * (9.87746524810791 -G$8) -> 0
A12: =A$9 * (0.2500112354755402 -A$8) -> 0 | B12: =B$9 * (0.2500112354755402 -B$8) -> 0 | C12: =C$9 * (0.2500112354755402 -C$8) -> 0 | E12: =E$9 * (0.01325295027345419 -E$8) -> 0 | F12: =F$9 * (4.242303848266602 -F$8) -> 0 | G12: =G$9 * (6.967663764953613 -G$8) -> 0
A13: =A$9 * (0.5001211166381836 -A$8) -> 0 | B13: =B$9 * (0.5001211166381836 -B$8) -> 0 | C13: =C$9 * (0.5001211166381836 -C$8) -> 0 | E13: =E$9 * (0.009234599769115448 -E$8) -> 0 | F13: =F$9 * (2.912945032119751 -F$8) -> 0 | G13: =G$9 * (5.829698085784912 -G$8) -> 0
A14: =A$9 * (0.7500610947608948 -A$8) -> 0 | B14: =B$9 * (0.7500610947608948 -B$8) -> 0 | C14: =C$9 * (0.7500610947608948 -C$8) -> 0 | E14: =E$9 * (0.005029994994401932 -E$8) -> 0 | F14: =F$9 * (1.130789995193481 -F$8) -> 0 | G14: =G$9 * (3.361793041229248 -G$8) -> 0
A15: =A$9 * (1.000138640403748 -A$8) -> 0 | B15: =B$9 * (1.000138640403748 -B$8) -> 0 | C15: =C$9 * (1.000138640403748 -C$8) -> 0 | E15: =E$9 * (-0.001137707033194602 -E$8) -> 0 | F15: =F$9 * (-1.523414969444275 -F$8) -> 0 | G15: =G$9 * (0.9239462018013 -G$8) -> 0
A16: =A$9 * (1.250008344650269 -A$8) -> 0 | B16: =B$9 * (1.250008344650269 -B$8) -> 0 | C16: =C$9 * (1.250008344650269 -C$8) -> 0 | E16: =E$9 * (-0.001649342942982912 -E$8) -> 0 | F16: =F$9 * (-0.5713431835174561 -F$8) -> 0 | G16: =G$9 * (-0.6565983891487122 -G$8) -> 0
A17: =A$9 * (1.500068068504333 -A$8) -> 0 | B17: =B$9 * (1.500068068504333 -B$8) -> 0 | C17: =C$9 * (1.500068068504333 -C$8) -> 0 | E17: =E$9 * (-0.0001193764983327128 -E$8) -> 0 | F17: =F$9 * (-1.477447032928467 -F$8) -> 0 | G17: =G$9 * (0.8027424812316895 -G$8) -> 0
A18: =A$9 * (1.750544190406799 -A$8) -> 0 | B18: =B$9 * (1.750544190406799 -B$8) -> 0 | C18: =C$9 * (1.750544190406799 -C$8) -> 0 | E18: =E$9 * (-0.0002765950921457261 -E$8) -> 0 | F18: =F$9 * (-0.6965150237083435 -F$8) -> 0 | G18: =G$9 * (0.6684923768043518 -G$8) -> 0
A19: =A$9 * (2.00004506111145 -A$8) -> 0 | B19: =B$9 * (2.00004506111145 -B$8) -> 0 | C19: =C$9 * (2.00004506111145 -C$8) -> 0 | E19: =E$9 * (-0.0007778162835165858 -E$8) -> 0 | F19: =F$9 * (-0.3213205933570862 -F$8) -> 0 | G19: =G$9 * (-0.176583394408226 -G$8) -> 0
A20: =A$9 * (2.250679969787598 -A$8) -> 0 | B20: =B$9 * (2.250679969787598 -B$8) -> 0 | C20: =C$9 * (2.250679969787598 -C$8) -> 0 | E20: =E$9 * (0.006739790085703135 -E$8) -> 0 | F20: =F$9 * (0.2099522948265076 -F$8) -> 0 | G20: =G$9 * (0.5615584254264832 -G$8) -> 0
A21: =A$9 * (2.500439643859863 -A$8) -> 0 | B21: =B$9 * (2.500439643859863 -B$8) -> 0 | C21: =C$9 * (2.500439643859863 -C$8) -> 0 | E21: =E$9 * (0.005490314215421677 -E$8) -> 0 | F21: =F$9 * (3.481755971908569 -F$8) -> 0 | G21: =G$9 * (10.67905044555664 -G$8) -> 0
A22: =A$9 * (2.750040769577026 -A$8) -> 0 | B22: =B$9 * (2.750040769577026 -B$8) -> 0 | C22: =C$9 * (2.750040769577026 -C$8) -> 0 | E22: =E$9 * (0.03059975989162922 -E$8) -> 0 | F22: =F$9 * (3.207367897033691 -F$8) -> 0 | G22: =G$9 * (3.392889976501465 -G$8) -> 0
A23: =A$9 * (3.000186204910278 -A$8) -> 0 | B23: =B$9 * (3.000186204910278 -B$8) -> 0 | C23: =C$9 * (3.000186204910278 -C$8) -> 0 | E23: =E$9 * (0.01463195029646158 -E$8) -> 0 | F23: =F$9 * (4.633410930633545 -F$8) -> 0 | G23: =G$9 * (7.182168006896973 -G$8) -> 0
A24: =A$9 * (3.250072240829468 -A$8) -> 0 | B24: =B$9 * (3.250072240829468 -B$8) -> 0 | C24: =C$9 * (3.250072240829468 -C$8) -> 0 | E24: =E$9 * (0.009326205588877201 -E$8) -> 0 | F24: =F$9 * (3.414434909820557 -F$8) -> 0 | G24: =G$9 * (6.796528816223145 -G$8) -> 0
A25: =A$9 * (3.500366687774658 -A$8) -> 0 | B25: =B$9 * (3.500366687774658 -B$8) -> 0 | C25: =C$9 * (3.500366687774658 -C$8) -> 0 | E25: =E$9 * (0.01446818001568317 -E$8) -> 0 | F25: =F$9 * (2.712361097335815 -F$8) -> 0 | G25: =G$9 * (4.108851909637451 -G$8) -> 0
A26: =A$9 * (3.750369548797607 -A$8) -> 0 | B26: =B$9 * (3.750369548797607 -B$8) -> 0 | C26: =C$9 * (3.750369548797607 -C$8) -> 0 | E26: =E$9 * (0.007370573934167624 -E$8) -> 0 | F26: =F$9 * (2.880822896957397 -F$8) -> 0 | G26: =G$9 * (6.687615871429443 -G$8) -> 0
A27: =A$9 * (4.000369548797607 -A$8) -> 0 | B27: =B$9 * (4.000369548797607 -B$8) -> 0 | C27: =C$9 * (4.000369548797607 -C$8) -> 0 | E27: =E$9 * (0.004478586837649345 -E$8) -> 0 | F27: =F$9 * (1.172142028808594 -F$8) -> 0 | G27: =G$9 * (3.811975955963135 -G$8) -> 0
A28: =A$9 * (4.250458240509033 -A$8) -> 0 | B28: =B$9 * (4.250458240509033 -B$8) -> 0 | C28: =C$9 * (4.250458240509033 -C$8) -> 0 | E28: =E$9 * (-0.0002315741003258154 -E$8) -> 0 | F28: =F$9 * (-1.215451955795288 -F$8) -> 0 | G28: =G$9 * (0.5877562761306763 -G$8) -> 0
A29: =A$9 * (4.500405788421631 -A$8) -> 0 | B29: =B$9 * (4.500405788421631 -B$8) -> 0 | C29: =C$9 * (4.500405788421631 -C$8) -> 0 | E29: =E$9 * (-0.0009057651041075587 -E$8) -> 0 | F29: =F$9 * (-0.7610834240913391 -F$8) -> 0 | G29: =G$9 * (-0.2387396991252899 -G$8) -> 0
A30: =A$9 * (4.750080585479736 -A$8) -> 0 | B30: =B$9 * (4.750080585479736 -B$8) -> 0 | C30: =C$9 * (4.750080585479736 -C$8) -> 0 | E30: =E$9 * (7.439230103045702E-5 -E$8) -> 0 | F30: =F$9 * (-1.127639055252075 -F$8) -> 0 | G30: =G$9 * (1.986724972724915 -G$8) -> 0
A31: =A$9 * (5.000389099121094 -A$8) -> 0 | B31: =B$9 * (5.000389099121094 -B$8) -> 0 | C31: =C$9 * (5.000389099121094 -C$8) -> 0 | E31: =E$9 * (-0.001800533966161311 -E$8) -> 0 | F31: =F$9 * (-0.2773160040378571 -F$8) -> 0 | G31: =G$9 * (-0.8620176911354065 -G$8) -> 0
A32: =A$9 * (5.250255584716797 -A$8) -> 0 | B32: =B$9 * (5.250255584716797 -B$8) -> 0 | C32: =C$9 * (5.250255584716797 -C$8) -> 0 | E32: =E$9 * (-0.0006006596959196031 -E$8) -> 0 | F32: =F$9 * (-0.1767181009054184 -F$8) -> 0 | G32: =G$9 * (-0.3047923147678375 -G$8) -> 0
A33: =A$9 * (5.500697135925293 -A$8) -> 0 | B33: =B$9 * (5.500697135925293 -B$8) -> 0 | C33: =C$9 * (5.500697135925293 -C$8) -> 0 | E33: =E$9 * (0.01148173958063126 -E$8) -> 0 | F33: =F$9 * (0.3837603032588959 -F$8) -> 0 | G33: =G$9 * (0.875407874584198 -G$8) -> 0
A34: =A$9 * (5.750344276428223 -A$8) -> 0 | B34: =B$9 * (5.750344276428223 -B$8) -> 0 | C34: =C$9 * (5.750344276428223 -C$8) -> 0 | E34: =E$9 * (0.0007105509866960347 -E$8) -> 0 | F34: =F$9 * (0.2734776139259338 -F$8) -> 0 | G34: =G$9 * (11.39169979095459 -G$8) -> 0
A35: =A$9 * (6.00059986114502 -A$8) -> 0 | B35: =B$9 * (6.00059986114502 -B$8) -> 0 | C35: =C$9 * (6.00059986114502 -C$8) -> 0 | E35: =E$9 * (0.02987192943692207 -E$8) -> 0 | F35: =F$9 * (3.316627025604248 -F$8) -> 0 | G35: =G$9 * (3.554433107376099 -G$8) -> 0
A36: =A$9 * (6.250333309173584 -A$8) -> 0 | B36: =B$9 * (6.250333309173584 -B$8) -> 0 | C36: =C$9 * (6.250333309173584 -C$8) -> 0 | E36: =E$9 * (0.01896345056593418 -E$8) -> 0 | F36: =F$9 * (4.833681106567383 -F$8) -> 0 | G36: =G$9 * (6.585178852081299 -G$8) -> 0
A37: =A$9 * (6.500533103942871 -A$8) -> 0 | B37: =B$9 * (6.500533103942871 -B$8) -> 0 | C37: =C$9 * (6.500533103942871 -C$8) -> 0 | E37: =E$9 * (0.009678608737885952 -E$8) -> 0 | F37: =F$9 * (3.741980075836182 -F$8) -> 0 | G37: =G$9 * (7.361485004425049 -G$8) -> 0
A38: =A$9 * (6.75029182434082 -A$8) -> 0 | B38: =B$9 * (6.75029182434082 -B$8) -> 0 | C38: =C$9 * (6.75029182434082 -C$8) -> 0 | E38: =E$9 * (0.01342772040516138 -E$8) -> 0 | F38: =F$9 * (2.325418949127197 -F$8) -> 0 | G38: =G$9 * (3.657566070556641 -G$8) -> 0
A39: =A$9 * (7.000044345855713 -A$8) -> 0 | B39: =B$9 * (7.000044345855713 -B$8) -> 0 | C39: =C$9 * (7.000044345855713 -C$8) -> 0 | E39: =E$9 * (0.009405037388205528 -E$8) -> 0 | F39: =F$9 * (3.310405969619751 -F$8) -> 0 | G39: =G$9 * (6.582622051239014 -G$8) -> 0
A40: =A$9 * (7.250141620635986 -A$8) -> 0 | B40: =B$9 * (7.250141620635986 -B$8) -> 0 | C40: =C$9 * (7.250141620635986 -C$8) -> 0 | E40: =E$9 * (0.005469514988362789 -E$8) -> 0 | F40: =F$9 * (1.818724036216736 -F$8) -> 0 | G40: =G$9 * (5.154407978057861 -G$8) -> 0
...
