Workbook

Sheet Legends
A1: VARIABLE | B1: LEGEND
A2: TREND___PT___(BARA)___OP1-US_CHOKE | B2: Pressure upstream choke
A3: TREND___PT___(BARA)___OP1-DS_CHOKE | B3: Pressure downstream choke

Sheet SIM1
A1: h | B1: h | D1: (BARA) | E1: (BARA)
A2: TIME1 | B2: TIME2 | D2: =Legends!B2 -> Pressure upstream choke | E2: =Legends!B3 -> Pressure downstream choke | G2: Report-2031_Oil_4500bopd_Liquid_4789blpd_5MMSCFD_GL_TD_Only_OP1_TCV_5pc.genkey
A3: =MIN($A$11:$A$299) -> 0 | B3: =MIN($B$11:$B$299) -> 0 | C3: Min | D3: =MIN($D$11:$D$299) -> 156.7196 | E3: =MIN($E$11:$E$299) -> 36.276642
A4: =MEDIAN($A$11:$A$299) -> 36.000221 | B4: =MEDIAN($B$11:$B$299) -> 36.000221 | C4: P50 | D4: =MEDIAN($D$11:$D$299) -> 156.79449 | E4: =MEDIAN($E$11:$E$299) -> 63.600632
A5: =MAX($A$11:$A$299) -> 72.000084 | B5: =MAX($B$11:$B$299) -> 72.000084 | C5: Max | D5: =MAX($D$11:$D$299) -> 156.80051 | E5: =MAX($E$11:$E$299) -> 71.296692
A6: =$A5-$A3 -> 72.000084 | B6: =$B5-$B3 -> 72.000084 | C6: Delta | D6: =$D5-$D3 -> 0.0809021 | E6: =$E5-$E3 -> 35.02005
A7: h | B7: h | D7: (BARA) | E7: (BARA)
A8: 0 | B8: 0 | C8: Offset | D8: 0 | E8: 0
A9: 1 | B9: 1 | C9: Scale | D9: 1 | E9: 1
A10: TIME1 | B10: TIME2 | D10: =Legends!B2 -> Pressure upstream choke | E10: =Legends!B3 -> Pressure downstream choke
A11: =A$9 * (0 -A$8) -> 0 | B11: =B$9 * (0 -B$8) -> 0 | D11: =D$9 * (156.740097045898 -D$8) -> 156.7401 | E11: =E$9 * (49.8292388916015 -E$8) -> 49.829239
A12: =A$9 * (0.250392377376556 -A$8) -> 0.25039238 | B12: =B$9 * (0.250392377376556 -B$8) -> 0.25039238 | D12: =D$9 * (156.719604492187 -D$8) -> 156.7196 | E12: =E$9 * (40.9013290405273 -E$8) -> 40.901329
A13: =A$9 * (0.500002801418304 -A$8) -> 0.5000028 | B13: =B$9 * (0.500002801418304 -B$8) -> 0.5000028 | D13: =D$9 * (156.800506591796 -D$8) -> 156.80051 | E13: =E$9 * (37.0190811157226 -E$8) -> 37.019081
A14: =A$9 * (0.750080525875091 -A$8) -> 0.75008053 | B14: =B$9 * (0.750080525875091 -B$8) -> 0.75008053 | D14: =D$9 * (156.794998168945 -D$8) -> 156.795 | E14: =E$9 * (37.3563613891601 -E$8) -> 37.356361
A15: =A$9 * (1.00001060962677 -A$8) -> 1.0000106 | B15: =B$9 * (1.00001060962677 -B$8) -> 1.0000106 | D15: =D$9 * (156.793701171875 -D$8) -> 156.7937 | E15: =E$9 * (36.2766418457031 -E$8) -> 36.276642
A16: =A$9 * (1.25021255016326 -A$8) -> 1.2502126 | B16: =B$9 * (1.25021255016326 -B$8) -> 1.2502126 | D16: =D$9 * (156.793395996093 -D$8) -> 156.7934 | E16: =E$9 * (42.7963981628418 -E$8) -> 42.796398
A17: =A$9 * (1.50015115737915 -A$8) -> 1.5001512 | B17: =B$9 * (1.50015115737915 -B$8) -> 1.5001512 | D17: =D$9 * (156.796295166015 -D$8) -> 156.7963 | E17: =E$9 * (53.8725891113281 -E$8) -> 53.872589
A18: =A$9 * (1.75008249282836 -A$8) -> 1.7500825 | B18: =B$9 * (1.75008249282836 -B$8) -> 1.7500825 | D18: =D$9 * (156.794494628906 -D$8) -> 156.79449 | E18: =E$9 * (64.9466705322265 -E$8) -> 64.946671
A19: =A$9 * (2.0003707408905 -A$8) -> 2.0003707 | B19: =B$9 * (2.0003707408905 -B$8) -> 2.0003707 | D19: =D$9 * (156.794494628906 -D$8) -> 156.79449 | E19: =E$9 * (69.5347137451171 -E$8) -> 69.534714
A20: =A$9 * (2.25034308433532 -A$8) -> 2.2503431 | B20: =B$9 * (2.25034308433532 -B$8) -> 2.2503431 | D20: =D$9 * (156.793502807617 -D$8) -> 156.7935 | E20: =E$9 * (62.0207595825195 -E$8) -> 62.02076
A21: =A$9 * (2.50008368492126 -A$8) -> 2.5000837 | B21: =B$9 * (2.50008368492126 -B$8) -> 2.5000837 | D21: =D$9 * (156.793792724609 -D$8) -> 156.79379 | E21: =E$9 * (64.1846618652343 -E$8) -> 64.184662
A22: =A$9 * (2.75025224685668 -A$8) -> 2.7502522 | B22: =B$9 * (2.75025224685668 -B$8) -> 2.7502522 | D22: =D$9 * (156.742294311523 -D$8) -> 156.74229 | E22: =E$9 * (71.2966918945312 -E$8) -> 71.296692
A23: =A$9 * (3.0002167224884 -A$8) -> 3.0002167 | B23: =B$9 * (3.0002167224884 -B$8) -> 3.0002167 | D23: =D$9 * (156.797698974609 -D$8) -> 156.7977 | E23: =E$9 * (68.5374221801757 -E$8) -> 68.537422
A24: =A$9 * (3.25043606758117 -A$8) -> 3.2504361 | B24: =B$9 * (3.25043606758117 -B$8) -> 3.2504361 | D24: =D$9 * (156.794601440429 -D$8) -> 156.7946 | E24: =E$9 * (64.1005477905273 -E$8) -> 64.100548
A25: =A$9 * (3.50005841255188 -A$8) -> 3.5000584 | B25: =B$9 * (3.50005841255188 -B$8) -> 3.5000584 | D25: =D$9 * (156.794204711914 -D$8) -> 156.7942 | E25: =E$9 * (64.2530364990234 -E$8) -> 64.253036
A26: =A$9 * (3.7503638267517 -A$8) -> 3.7503638 | B26: =B$9 * (3.7503638267517 -B$8) -> 3.7503638 | D26: =D$9 * (156.794601440429 -D$8) -> 156.7946 | E26: =E$9 * (67.1315536499023 -E$8) -> 67.131554
A27: =A$9 * (4.00066947937011 -A$8) -> 4.0006695 | B27: =B$9 * (4.00066947937011 -B$8) -> 4.0006695 | D27: =D$9 * (156.794296264648 -D$8) -> 156.7943 | E27: =E$9 * (65.0619201660156 -E$8) -> 65.06192
A28: =A$9 * (4.25060844421386 -A$8) -> 4.2506084 | B28: =B$9 * (4.25060844421386 -B$8) -> 4.2506084 | D28: =D$9 * (156.794799804687 -D$8) -> 156.7948 | E28: =E$9 * (61.8584899902343 -E$8) -> 61.85849
A29: =A$9 * (4.50008058547973 -A$8) -> 4.5000806 | B29: =B$9 * (4.50008058547973 -B$8) -> 4.5000806 | D29: =D$9 * (156.794799804687 -D$8) -> 156.7948 | E29: =E$9 * (63.3673706054687 -E$8) -> 63.367371
A30: =A$9 * (4.75010299682617 -A$8) -> 4.750103 | B30: =B$9 * (4.75010299682617 -B$8) -> 4.750103 | D30: =D$9 * (156.79490661621 -D$8) -> 156.79491 | E30: =E$9 * (65.3970870971679 -E$8) -> 65.397087
A31: =A$9 * (5.00012493133544 -A$8) -> 5.0001249 | B31: =B$9 * (5.00012493133544 -B$8) -> 5.0001249 | D31: =D$9 * (156.79490661621 -D$8) -> 156.79491 | E31: =E$9 * (63.8035812377929 -E$8) -> 63.803581
A32: =A$9 * (5.25014734268188 -A$8) -> 5.2501473 | B32: =B$9 * (5.25014734268188 -B$8) -> 5.2501473 | D32: =D$9 * (156.794799804687 -D$8) -> 156.7948 | E32: =E$9 * (61.6486892700195 -E$8) -> 61.648689
A33: =A$9 * (5.50016927719116 -A$8) -> 5.5001693 | B33: =B$9 * (5.50016927719116 -B$8) -> 5.5001693 | D33: =D$9 * (156.794692993164 -D$8) -> 156.79469 | E33: =E$9 * (63.4968185424804 -E$8) -> 63.496819
A34: =A$9 * (5.75019168853759 -A$8) -> 5.7501917 | B34: =B$9 * (5.75019168853759 -B$8) -> 5.7501917 | D34: =D$9 * (156.794494628906 -D$8) -> 156.79449 | E34: =E$9 * (64.9329071044921 -E$8) -> 64.932907
A35: =A$9 * (6.00021409988403 -A$8) -> 6.0002141 | B35: =B$9 * (6.00021409988403 -B$8) -> 6.0002141 | D35: =D$9 * (156.794296264648 -D$8) -> 156.7943 | E35: =E$9 * (63.5789413452148 -E$8) -> 63.578941
A36: =A$9 * (6.25023603439331 -A$8) -> 6.250236 | B36: =B$9 * (6.25023603439331 -B$8) -> 6.250236 | D36: =D$9 * (156.79409790039 -D$8) -> 156.7941 | E36: =E$9 * (61.8893890380859 -E$8) -> 61.889389
A37: =A$9 * (6.50025558471679 -A$8) -> 6.5002556 | B37: =B$9 * (6.50025558471679 -B$8) -> 6.5002556 | D37: =D$9 * (156.794006347656 -D$8) -> 156.79401 | E37: =E$9 * (63.6680908203125 -E$8) -> 63.668091
A38: =A$9 * (6.75027799606323 -A$8) -> 6.750278 | B38: =B$9 * (6.75027799606323 -B$8) -> 6.750278 | D38: =D$9 * (156.794006347656 -D$8) -> 156.79401 | E38: =E$9 * (64.6754989624023 -E$8) -> 64.675499
A39: =A$9 * (7.00029993057251 -A$8) -> 7.0002999 | B39: =B$9 * (7.00029993057251 -B$8) -> 7.0002999 | D39: =D$9 * (156.79409790039 -D$8) -> 156.7941 | E39: =E$9 * (63.5291290283203 -E$8) -> 63.529129
A40: =A$9 * (7.25032234191894 -A$8) -> 7.2503223 | B40: =B$9 * (7.25032234191894 -B$8) -> 7.2503223 | D40: =D$9 * (156.794204711914 -D$8) -> 156.7942 | E40: =E$9 * (62.587791442871 -E$8) -> 62.587791
...

Sheet SIM2
A1: h | B1: h | D1: (BARA) | E1: (BARA)
A2: TIME1 | B2: TIME2 | D2: =Legends!B2 -> Pressure upstream choke | E2: =Legends!B3 -> Pressure downstream choke | G2: Report-2031_Oil_4500bopd_Liquid_4789blpd_No_GL_TD_Only_OP1.genkey
A3: =MIN($A$11:$A$299) -> 0 | B3: =MIN($B$11:$B$299) -> 0 | C3: Min | D3: =MIN($D$11:$D$299) -> 156.28329 | E3: =MIN($E$11:$E$299) -> 34.045521
A4: =MEDIAN($A$11:$A$299) -> 36.000195 | B4: =MEDIAN($B$11:$B$299) -> 36.000195 | C4: P50 | D4: =MEDIAN($D$11:$D$299) -> 156.75841 | E4: =MEDIAN($E$11:$E$299) -> 66.431633
A5: =MAX($A$11:$A$299) -> 72.000168 | B5: =MAX($B$11:$B$299) -> 72.000168 | C5: Max | D5: =MAX($D$11:$D$299) -> 157.0332 | E5: =MAX($E$11:$E$299) -> 95.978729
A6: =$A5-$A3 -> 72.000168 | B6: =$B5-$B3 -> 72.000168 | C6: Delta | D6: =$D5-$D3 -> 0.74990845 | E6: =$E5-$E3 -> 61.933208
A7: h | B7: h | D7: (BARA) | E7: (BARA)
A8: 0 | B8: 0 | C8: Offset | D8: 0 | E8: 0
A9: 1 | B9: 1 | C9: Scale | D9: 1 | E9: 1
A10: TIME1 | B10: TIME2 | D10: =Legends!B2 -> Pressure upstream choke | E10: =Legends!B3 -> Pressure downstream choke
A11: =A$9 * (0 -A$8) -> 0 | B11: =B$9 * (0 -B$8) -> 0 | D11: =D$9 * (156.740097045898 -D$8) -> 156.7401 | E11: =E$9 * (49.8292388916015 -E$8) -> 49.829239
A12: =A$9 * (0.250369876623153 -A$8) -> 0.25036988 | B12: =B$9 * (0.250369876623153 -B$8) -> 0.25036988 | D12: =D$9 * (156.720596313476 -D$8) -> 156.7206 | E12: =E$9 * (39.7745704650878 -E$8) -> 39.77457
A13: =A$9 * (0.50034749507904 -A$8) -> 0.5003475 | B13: =B$9 * (0.50034749507904 -B$8) -> 0.5003475 | D13: =D$9 * (156.797897338867 -D$8) -> 156.7979 | E13: =E$9 * (36.9728889465332 -E$8) -> 36.972889
A14: =A$9 * (0.750366389751434 -A$8) -> 0.75036639 | B14: =B$9 * (0.750366389751434 -B$8) -> 0.75036639 | D14: =D$9 * (156.79490661621 -D$8) -> 156.79491 | E14: =E$9 * (36.6915702819824 -E$8) -> 36.69157
A15: =A$9 * (1.00027227401733 -A$8) -> 1.0002723 | B15: =B$9 * (1.00027227401733 -B$8) -> 1.0002723 | D15: =D$9 * (156.793701171875 -D$8) -> 156.7937 | E15: =E$9 * (44.4730911254882 -E$8) -> 44.473091
A16: =A$9 * (1.25033855438232 -A$8) -> 1.2503386 | B16: =B$9 * (1.25033855438232 -B$8) -> 1.2503386 | D16: =D$9 * (156.793792724609 -D$8) -> 156.79379 | E16: =E$9 * (53.8846206665039 -E$8) -> 53.884621
A17: =A$9 * (1.50031077861785 -A$8) -> 1.5003108 | B17: =B$9 * (1.50031077861785 -B$8) -> 1.5003108 | D17: =D$9 * (156.793502807617 -D$8) -> 156.7935 | E17: =E$9 * (63.2030296325683 -E$8) -> 63.20303
A18: =A$9 * (1.75039339065551 -A$8) -> 1.7503934 | B18: =B$9 * (1.75039339065551 -B$8) -> 1.7503934 | D18: =D$9 * (156.767105102539 -D$8) -> 156.76711 | E18: =E$9 * (72.660057067871 -E$8) -> 72.660057
A19: =A$9 * (2.00029850006103 -A$8) -> 2.0002985 | B19: =B$9 * (2.00029850006103 -B$8) -> 2.0002985 | D19: =D$9 * (157.033203125 -D$8) -> 157.0332 | E19: =E$9 * (81.8025207519531 -E$8) -> 81.802521
A20: =A$9 * (2.25022602081298 -A$8) -> 2.250226 | B20: =B$9 * (2.25022602081298 -B$8) -> 2.250226 | D20: =D$9 * (156.943496704101 -D$8) -> 156.9435 | E20: =E$9 * (91.3377990722656 -E$8) -> 91.337799
A21: =A$9 * (2.50031995773315 -A$8) -> 2.50032 | B21: =B$9 * (2.50031995773315 -B$8) -> 2.50032 | D21: =D$9 * (156.318695068359 -D$8) -> 156.3187 | E21: =E$9 * (84.2213287353515 -E$8) -> 84.221329
A22: =A$9 * (2.75026774406433 -A$8) -> 2.7502677 | B22: =B$9 * (2.75026774406433 -B$8) -> 2.7502677 | D22: =D$9 * (156.678497314453 -D$8) -> 156.6785 | E22: =E$9 * (60.6998481750488 -E$8) -> 60.699848
A23: =A$9 * (3.00019168853759 -A$8) -> 3.0001917 | B23: =B$9 * (3.00019168853759 -B$8) -> 3.0001917 | D23: =D$9 * (156.682907104492 -D$8) -> 156.68291 | E23: =E$9 * (43.4461708068847 -E$8) -> 43.446171
A24: =A$9 * (3.25028324127197 -A$8) -> 3.2502832 | B24: =B$9 * (3.25028324127197 -B$8) -> 3.2502832 | D24: =D$9 * (156.662506103515 -D$8) -> 156.66251 | E24: =E$9 * (34.7001609802246 -E$8) -> 34.700161
A25: =A$9 * (3.5001471042633 -A$8) -> 3.5001471 | B25: =B$9 * (3.5001471042633 -B$8) -> 3.5001471 | D25: =D$9 * (156.66160583496 -D$8) -> 156.66161 | E25: =E$9 * (39.3535003662109 -E$8) -> 39.3535
A26: =A$9 * (3.75028896331787 -A$8) -> 3.750289 | B26: =B$9 * (3.75028896331787 -B$8) -> 3.750289 | D26: =D$9 * (156.661193847656 -D$8) -> 156.66119 | E26: =E$9 * (48.3858604431152 -E$8) -> 48.38586
A27: =A$9 * (4.00031375885009 -A$8) -> 4.0003138 | B27: =B$9 * (4.00031375885009 -B$8) -> 4.0003138 | D27: =D$9 * (156.663101196289 -D$8) -> 156.6631 | E27: =E$9 * (57.0205497741699 -E$8) -> 57.02055
A28: =A$9 * (4.25004148483276 -A$8) -> 4.2500415 | B28: =B$9 * (4.25004148483276 -B$8) -> 4.2500415 | D28: =D$9 * (156.662506103515 -D$8) -> 156.66251 | E28: =E$9 * (65.6055526733398 -E$8) -> 65.605553
A29: =A$9 * (4.50066089630127 -A$8) -> 4.5006609 | B29: =B$9 * (4.50066089630127 -B$8) -> 4.5006609 | D29: =D$9 * (156.707000732421 -D$8) -> 156.707 | E29: =E$9 * (73.1279602050781 -E$8) -> 73.12796
A30: =A$9 * (4.75024700164794 -A$8) -> 4.750247 | B30: =B$9 * (4.75024700164794 -B$8) -> 4.750247 | D30: =D$9 * (156.668502807617 -D$8) -> 156.6685 | E30: =E$9 * (54.5939407348632 -E$8) -> 54.593941
A31: =A$9 * (5.00027799606323 -A$8) -> 5.000278 | B31: =B$9 * (5.00027799606323 -B$8) -> 5.000278 | D31: =D$9 * (156.662002563476 -D$8) -> 156.662 | E31: =E$9 * (59.9819908142089 -E$8) -> 59.981991
A32: =A$9 * (5.25023603439331 -A$8) -> 5.250236 | B32: =B$9 * (5.25023603439331 -B$8) -> 5.250236 | D32: =D$9 * (156.662200927734 -D$8) -> 156.6622 | E32: =E$9 * (69.4759826660156 -E$8) -> 69.475983
A33: =A$9 * (5.50051689147949 -A$8) -> 5.5005169 | B33: =B$9 * (5.50051689147949 -B$8) -> 5.5005169 | D33: =D$9 * (156.837203979492 -D$8) -> 156.8372 | E33: =E$9 * (79.1821365356445 -E$8) -> 79.182137
A34: =A$9 * (5.75008630752563 -A$8) -> 5.7500863 | B34: =B$9 * (5.75008630752563 -B$8) -> 5.7500863 | D34: =D$9 * (156.753997802734 -D$8) -> 156.754 | E34: =E$9 * (88.816421508789 -E$8) -> 88.816422
A35: =A$9 * (6.00038909912109 -A$8) -> 6.0003891 | B35: =B$9 * (6.00038909912109 -B$8) -> 6.0003891 | D35: =D$9 * (156.543792724609 -D$8) -> 156.54379 | E35: =E$9 * (92.8428192138671 -E$8) -> 92.842819
A36: =A$9 * (6.25046920776367 -A$8) -> 6.2504692 | B36: =B$9 * (6.25046920776367 -B$8) -> 6.2504692 | D36: =D$9 * (156.626403808593 -D$8) -> 156.6264 | E36: =E$9 * (61.8475685119628 -E$8) -> 61.847569
A37: =A$9 * (6.50005292892456 -A$8) -> 6.5000529 | B37: =B$9 * (6.50005292892456 -B$8) -> 6.5000529 | D37: =D$9 * (156.690002441406 -D$8) -> 156.69 | E37: =E$9 * (69.6109008789062 -E$8) -> 69.610901
A38: =A$9 * (6.75055265426635 -A$8) -> 6.7505527 | B38: =B$9 * (6.75055265426635 -B$8) -> 6.7505527 | D38: =D$9 * (156.824401855468 -D$8) -> 156.8244 | E38: =E$9 * (78.7387619018554 -E$8) -> 78.738762
A39: =A$9 * (7.00069999694824 -A$8) -> 7.0007 | B39: =B$9 * (7.00069999694824 -B$8) -> 7.0007 | D39: =D$9 * (156.74560546875 -D$8) -> 156.74561 | E39: =E$9 * (88.0147018432617 -E$8) -> 88.014702
A40: =A$9 * (7.25026130676269 -A$8) -> 7.2502613 | B40: =B$9 * (7.25026130676269 -B$8) -> 7.2502613 | D40: =D$9 * (156.437606811523 -D$8) -> 156.43761 | E40: =E$9 * (92.4313278198242 -E$8) -> 92.431328
...
